Workbook

Sheet MFP(sample)
A1: LQFP64(7*7) | B1: ULQFP64(7*7) | C1: LQFP128(14*14) | D1: ULQFP128(14*14) | E1: PAD Name | F1: Pin Name | G1: MFP1 | H1: MFP2 | I1: MFP3 | J1: MFP4 | K1: MFP5 | L1: MFP6 | M1: MFP7 | N1: MFP8(LQFP64) | O1: MFP8(LQFP128) | P1: MFP8(ULQFP128) | Q1: MFP31 | S1: MFP1 | T1: ADC | U1: ACMP0 | V1: ACMP1 | X1: Bit3 | Y1: Bit2 | Z1: Bit1 | AA1: Bit0
C2: 1 | D2: 1 | E2: GPB[5] | F2: PB.5 | G2: Analog0 | H2: EBI_ADR0 | I2: SD0_DAT3 | J2: EMAC_RMII_REFCLK | P2: LCD_SEG33 | S2: Analog0 | T2: EADC0_CH5 | V2: ACMP1_N | X2: MFPA[3] | Y2: MFPA[2] | Z2: MFPA[1] | AA2: MFPA[0]
A3: 1 | B3: 1 | C3: 2 | D3: 2 | E3: GPB[4] | F3: PB.4 | G3: Analog1 | H3: EBI_ADR1 | I3: SD0_DAT2 | J3: EMAC_RMII_RXD0 | P3: LCD_SEG32 | S3: Analog1 | T3: EADC0_CH4 | V3: ACMP1_P1 | Z3: ALT1[1] | AA3: MFP1[1]
A4: 2 | B4: 2 | C4: 3 | D4: 3 | E4: GPB[3] | F4: PB.3 | G4: Analog2 | H4: EBI_ADR2 | I4: SD0_DAT1 | J4: EMAC_RMII_RXD1 | K4: SPI0_SS[ULQFP64(7*7)] | P4: LCD_SEG31 | S4: Analog2 | T4: EADC0_CH3 | U4: ACMP0_N | AA4: ALT[5]
A5: 3 | B5: 3 | C5: 4 | D5: 4 | E5: GPB[2] | F5: PB.2 | G5: Analog3 | H5: EBI_ADR3 | I5: SD0_DAT0 | J5: EMAC_RMII_CRSDV | P5: LCD_SEG30 | S5: Analog3 | T5: EADC0_CH2 | U5: ACMP0_P1
A6: 4 | B6: 4 | C6: 5 | D6: 5 | E6: GPC[12] | F6: PC.12 | H6: EBI_ADR4 | I6: UART0_TXD | J6: I2C0_SCL | P6: LCD_SEG29
A7: 5 | B7: 5 | C7: 6 | D7: 6 | E7: GPC[11] | F7: PC.11 | H7: EBI_ADR5 | I7: UART0_RXD | J7: I2C0_SDA | P7: LCD_SEG28
C8: 7 | D8: 7 | E8: GPC[10] | F8: PC.10 | H8: EBI_ADR6 | O8: LCD_SEG23 | P8: LCD_SEG27
C9: 8 | D9: 8 | E9: GPC[9] | F9: PC.9 | H9: EBI_ADR7 | O9: LCD_SEG22 | P9: LCD_SEG26
C10: 9 | D10: 9 | E10: GPB[1] | F10: PB.1 | G10: Analog4 | H10: EBI_ADR8 | I10: SD0_CLK | J10: EMAC_RMII_RXERR | O10: LCD_SEG21 | P10: LCD_SEG25 | S10: Analog4 | T10: EADC0_CH1
C11: 10 | D11: 10 | E11: GPB[0] | F11: PB.0 | G11: Analog5 | H11: EBI_ADR9 | I11: SD0_CMD | O11: LCD_SEG20 | P11: LCD_SEG24 | S11: Analog5 | T11: EADC0_CH0
C12: 11 | D12: 11 | E12: VSSPST | F12: VSS
C13: 12 | D13: 12 | E13: VDDPST | F13: VDD
C14: 13 | D14: 13 | E14: GPA[11] | F14: PA.11 | G14: Analog6 | H14: EBI_nRD | I14: SC2_PWR | J14: SPI2_SS | S14: Analog6 | U14: ACMP0_P0
C15: 14 | D15: 14 | E15: GPA[10] | F15: PA.10 | G15: Analog7 | H15: EBI_nWR | I15: SC2_RST | J15: SPI2_CLK | S15: Analog7 | V15: ACMP1_P0
C16: 15 | D16: 15 | E16: GPA[9] | F16: PA.9 | H16: EBI_MCLK | I16: SC2_DAT | J16: SPI2_MISO
A17: 6 | B17: 6 | C17: 16 | D17: 16 | E17: GPA[8] | F17: PA.8 | H17: EBI_ALE | I17: SC2_CLK | J17: SPI2_MOSI | N17: LCD_SEG19 | O17: LCD_SEG19 | P17: LCD_SEG23
A18: 7 | B18: 7 | C18: 17 | D18: 17 | E18: GPC[13] | F18: PC.13 | H18: EBI_ADR10 | I18: SC2_nCD | J18: SPI2_I2SMCLK | K18: I2C0_CL | N18: LCD_SEG18 | O18: LCD_SEG18 | P18: LCD_SEG22
A19: 8 | B19: 8 | C19: 18 | D19: 18 | E19: GPD[12] | F19: PD.12 | H19: EBI_nCS0 | K19: I2C0_DA | N19: LCD_SEG17 | O19: LCD_SEG17 | P19: LCD_SEG21
A20: 9 | B20: 9 | C20: 19 | D20: 19 | E20: GPD[11] | F20: PD.11 | H20: EBI_nCS1 | I20: BRAKE00 | J20: CAN0_TXD | N20: LCD_SEG16 | O20: LCD_SEG16 | P20: LCD_SEG20
A21: 10 | B21: 10 | C21: 20 | D21: 20 | E21: GPD[10] | F21: PD.10 | H21: EBI_nCS2 | I21: BRAKE01 | J21: CAN0_RXD | N21: LCD_SEG15 | O21: LCD_SEG15 | P21: LCD_SEG19
A22: 11 | B22: 11 | C22: 21 | D22: 21 | E22: VSSPST | F22: VSS | L22: SPI0_SCLK_O | N22: LCD_SEG14 | O22: LCD_SEG14 | P22: LCD_SEG18
A23: 12 | B23: 12 | C23: 22 | D23: 22 | E23: VDDPST | F23: VDD | N23: LCD_SEG13 | O23: LCD_SEG13 | P23: LCD_SEG17
A24: 13 | B24: 13 | C24: 23 | D24: 23 | E24: GPG[0] | F24: PG.0 | H24: EBI_ADR8 | J24: I2C0_SCL | N24: LCD_SEG12 | O24: LCD_SEG12 | P24: LCD_SEG16
A25: 14 | B25: 14 | C25: 24 | D25: 24 | E25: GPG[1] | F25: PG.1 | H25: EBI_ADR9 | I25: SPI2_I2SMCLK | J25: I2C0_SDA | N25: LCD_SEG11 | O25: LCD_SEG11 | P25: LCD_SEG15
A26: 15 | B26: 15 | C26: 25 | D26: 25 | E26: GPG[2] | F26: PG.2 | H26: EBI_ADR11 | I26: SPI2_SS | J26: I2C0_SMBAL | N26: LCD_SEG10 | O26: LCD_SEG10 | P26: LCD_SEG14
A27: 16 | B27: 16 | C27: 26 | D27: 26 | E27: GPG[3] | F27: PG.3 | H27: EBI_ADR12 | I27: SPI2_CLK | J27: I2C0_SMBSUS | N27: LCD_SEG9 | O27: LCD_SEG9 | P27: LCD_SEG13
C28: 27 | D28: 27 | E28: GPG[4] | F28: PG.4 | H28: EBI_ADR13 | I28: SPI2_MISO
C29: 28 | D29: 28 | E29: GPF[11] | F29: PF.11 | H29: EBI_ADR14 | I29: SPI2_MOSI
C30: 29 | D30: 29 | E30: GPF[10] | F30: PF.10 | H30: EBI_ADR15 | I30: SC0_nCD | J30: I2S0_BCLK
C31: 30 | D31: 30 | E31: GPF[9] | F31: PF.9 | H31: EBI_ADR16 | I31: SC0_PWR | J31: I2S0_MCLK
C32: 31 | D32: 31 | E32: GPF[8] | F32: PF.8 | H32: EBI_ADR17 | I32: SC0_RST | J32: I2S0_DI
C33: 32 | D33: 32 | E33: GPF[7] | F33: PF.7 | H33: EBI_ADR18 | I33: SC0_DAT | J33: I2S0_DO
C34: 33 | D34: 33 | E34: GPF[6] | F34: PF.6 | H34: EBI_ADR19 | I34: SC0_CLK | J34: I2S0_LRCK
C35: 34 | D35: 34 | E35: VBAT | F35: VDD
C36: 35 | D36: 35 | E36: GPF[5] | F36: PF.5 | H36: UART2_RXD | J36: UART2_nCTS
C37: 36 | D37: 36 | E37: GPF[4] | F37: PF.4 | H37: UART2_TXD | J37: UART2_nRTS
C38: 37 | D38: 37 | E38: GPH[0] | F38: PH.0 | H38: EBI_ADR7 | J38: UART5_TXD
C39: 38 | D39: 38 | E39: GPH[1] | F39: PH.1 | H39: EBI_ADR6 | J39: UART5_RXD
C40: 39 | D40: 39 | E40: GPH[2] | F40: PH.2 | H40: EBI_ADR5 | J40: UART5_nRTS
...

Sheet MFP
A1: PAD# | B1: LQFP100_B0x(14*14) | C1: TQFP80_B0x(12*12) | D1: TQFP64_B0x(10*10) | E1: TQFP48_B0x(7*7) | F1: LQFP100_B5x(14*14) | G1: TQFP80_B5x(12*12) | H1: TQFP64_B5x(10*10) | I1: PAD NAME | J1: PIN NAME | K1: MFP1 | L1: MFP2 | M1: MFP3 | N1: MFP4 | O1: MFP5 | P1: MFP6 | Q1: MFP7 | R1: MFP8 | S1: MFP9 | T1: MFP10 | V1: MFP1 | W1: AD | X1: VGA | Y1: CMP | AB1: MFP2 | AC1: AD | AD1: VGA | AE1: CMP | AG1: MFP6 | AH1: AD | AI1: VGA | AJ1: CMP | AL1: Bit3 | AM1: Bit2 | AN1: Bit1 | AO1: Bit0
A2: 1 | B2: 1 | F2: 1 | I2: GPE[5] | J2: PE.5 | K2: =IF('＠MFP (LSI name)'!K2="","",IF(COUNTIF('＠MFP (LSI name)'!K2,"Serial*")+COUNTIF('＠MFP (LSI name)'!K2,"Analog*")>0,'＠MFP (LSI name)'!K2,OFFSET('＠グループ、表示名'!$H$4,MATCH('＠MFP (LSI name)'!K2,'＠グループ、表示名'!$D$4:$D$250,0)-1,0))) -> IRQ00 | L2: =IF('＠MFP (LSI name)'!L2="","",IF(COUNTIF('＠MFP (LSI name)'!L2,"Serial*")+COUNTIF('＠MFP (LSI name)'!L2,"Analog*")>0,'＠MFP (LSI name)'!L2,OFFSET('＠グループ、表示名'!$H$4,MATCH('＠MFP (LSI name)'!L2,'＠グループ、表示名'!$D$4:$D$250,0)-1,0))) | M2: =IF('＠MFP (LSI name)'!M2="","",IF(COUNTIF('＠MFP (LSI name)'!M2,"Serial*")+COUNTIF('＠MFP (LSI name)'!M2,"Analog*")>0,'＠MFP (LSI name)'!M2,OFFSET('＠グループ、表示名'!$H$4,MATCH('＠MFP (LSI name)'!M2,'＠グループ、表示名'!$D$4:$D$250,0)-1,0))) | N2: =IF('＠MFP (LSI name)'!N2="","",IF(COUNTIF('＠MFP (LSI name)'!N2,"Serial*")+COUNTIF('＠MFP (LSI name)'!N2,"Analog*")>0,'＠MFP (LSI name)'!N2,OFFSET('＠グループ、表示名'!$H$4,MATCH('＠MFP (LSI name)'!N2,'＠グループ、表示名'!$D$4:$D$250,0)-1,0))) | O2: =IF('＠MFP (LSI name)'!O2="","",IF(COUNTIF('＠MFP (LSI name)'!O2,"Serial*")+COUNTIF('＠MFP (LSI name)'!O2,"Analog*")>0,'＠MFP (LSI name)'!O2,OFFSET('＠グループ、表示名'!$H$4,MATCH('＠MFP (LSI name)'!O2,'＠グループ、表示名'!$D$4:$D$250,0)-1,0))) | P2: =IF('＠MFP (LSI name)'!P2="","",IF(COUNTIF('＠MFP (LSI name)'!P2,"Serial*")+COUNTIF('＠MFP (LSI name)'!P2,"Analog*")>0,'＠MFP (LSI name)'!P2,OFFSET('＠グループ、表示名'!$H$4,MATCH('＠MFP (LSI name)'!P2,'＠グループ、表示名'!$D$4:$D$250,0)-1,0))) | Q2: =IF('＠MFP (LSI name)'!Q2="","",IF(COUNTIF('＠MFP (LSI name)'!Q2,"Serial*")+COUNTIF('＠MFP (LSI name)'!Q2,"Analog*")>0,'＠MFP (LSI name)'!Q2,OFFSET('＠グループ、表示名'!$H$4,MATCH('＠MFP (LSI name)'!Q2,'＠グループ、表示名'!$D$4:$D$250,0)-1,0))) | R2: =IF('＠MFP (LSI name)'!R2="","",IF(COUNTIF('＠MFP (LSI name)'!R2,"Serial*")+COUNTIF('＠MFP (LSI name)'!R2,"Analog*")>0,'＠MFP (LSI name)'!R2,OFFSET('＠グループ、表示名'!$H$4,MATCH('＠MFP (LSI name)'!R2,'＠グループ、表示名'!$D$4:$D$250,0)-1,0))) | ... AK2: =IF('＠MFP (LSI name)'!AK2="","",IF(COUNTIF('＠MFP (LSI name)'!AK2,"Serial*")+COUNTIF('＠MFP (LSI name)'!AK2,"Analog*")>0,'＠MFP (LSI name)'!AK2,OFFSET('＠グループ、表示名'!$H$4,MATCH('＠MFP (LSI name)'!AK2,'＠グループ、表示名'!$D$4:$D$250,0)-1,0))) | AL2: =IF(COUNTIF(J2,"P*")>0,"IO"&LEFT(J2,2)&"MD["&RIGHT(J2,1)*4+3&"]","") -> IOPEMD[23] | AM2: =IF(COUNTIF(J2,"P*")>0,"IO"&LEFT(J2,2)&"MD["&RIGHT(J2,1)*4+2&"]","") -> IOPEMD[22] | AN2: =IF(COUNTIF(J2,"P*")>0,"IO"&LEFT(J2,2)&"MD["&RIGHT(J2,1)*4+1&"]","") -> IOPEMD[21] | AO2: =IF(COUNTIF(J2,"P*")>0,"IO"&LEFT(J2,2)&"MD["&RIGHT(J2,1)*4&"]","") -> IOPEMD[20]
A3: 2 | B3: 2 | C3: 1 | D3: 1 | F3: 2 | G3: 1 | H3: 1 | I3: GP0[2] | J3: P0.2 | K3: =IF('＠MFP (LSI name)'!K3="","",IF(COUNTIF('＠MFP (LSI name)'!K3,"Serial*")+COUNTIF('＠MFP (LSI name)'!K3,"Analog*")>0,'＠MFP (LSI name)'!K3,OFFSET('＠グループ、表示名'!$H$4,MATCH('＠MFP (LSI name)'!K3,'＠グループ、表示名'!$D$4:$D$250,0)-1,0))) -> IRQ05 | L3: =IF('＠MFP (LSI name)'!L3="","",IF(COUNTIF('＠MFP (LSI name)'!L3,"Serial*")+COUNTIF('＠MFP (LSI name)'!L3,"Analog*")>0,'＠MFP (LSI name)'!L3,OFFSET('＠グループ、表示名'!$H$4,MATCH('＠MFP (LSI name)'!L3,'＠グループ、表示名'!$D$4:$D$250,0)-1,0))) -> TM15B | M3: =IF('＠MFP (LSI name)'!M3="","",IF(COUNTIF('＠MFP (LSI name)'!M3,"Serial*")+COUNTIF('＠MFP (LSI name)'!M3,"Analog*")>0,'＠MFP (LSI name)'!M3,OFFSET('＠グループ、表示名'!$H$4,MATCH('＠MFP (LSI name)'!M3,'＠グループ、表示名'!$D$4:$D$250,0)-1,0))) -> SIF1_SBCS1 | N3: =IF('＠MFP (LSI name)'!N3="","",IF(COUNTIF('＠MFP (LSI name)'!N3,"Serial*")+COUNTIF('＠MFP (LSI name)'!N3,"Analog*")>0,'＠MFP (LSI name)'!N3,OFFSET('＠グループ、表示名'!$H$4,MATCH('＠MFP (LSI name)'!N3,'＠グループ、表示名'!$D$4:$D$250,0)-1,0))) -> SIF4_SBI4 | O3: =IF('＠MFP (LSI name)'!O3="","",IF(COUNTIF('＠MFP (LSI name)'!O3,"Serial*")+COUNTIF('＠MFP (LSI name)'!O3,"Analog*")>0,'＠MFP (LSI name)'!O3,OFFSET('＠グループ、表示名'!$H$4,MATCH('＠MFP (LSI name)'!O3,'＠グループ、表示名'!$D$4:$D$250,0)-1,0))) -> SIF4_SBO4 | P3: =IF('＠MFP (LSI name)'!P3="","",IF(COUNTIF('＠MFP (LSI name)'!P3,"Serial*")+COUNTIF('＠MFP (LSI name)'!P3,"Analog*")>0,'＠MFP (LSI name)'!P3,OFFSET('＠グループ、表示名'!$H$4,MATCH('＠MFP (LSI name)'!P3,'＠グループ、表示名'!$D$4:$D$250,0)-1,0))) -> ADST0 | Q3: =IF('＠MFP (LSI name)'!Q3="","",IF(COUNTIF('＠MFP (LSI name)'!Q3,"Serial*")+COUNTIF('＠MFP (LSI name)'!Q3,"Analog*")>0,'＠MFP (LSI name)'!Q3,OFFSET('＠グループ、表示名'!$H$4,MATCH('＠MFP (LSI name)'!Q3,'＠グループ、表示名'!$D$4:$D$250,0)-1,0))) | R3: =IF('＠MFP (LSI name)'!R3="","",IF(COUNTIF('＠MFP (LSI name)'!R3,"Serial*")+COUNTIF('＠MFP (LSI name)'!R3,"Analog*")>0,'＠MFP (LSI name)'!R3,OFFSET('＠グループ、表示名'!$H$4,MATCH('＠MFP (LSI name)'!R3,'＠グループ、表示名'!$D$4:$D$250,0)-1,0))) | ... AK3: =IF('＠MFP (LSI name)'!AK3="","",IF(COUNTIF('＠MFP (LSI name)'!AK3,"Serial*")+COUNTIF('＠MFP (LSI name)'!AK3,"Analog*")>0,'＠MFP (LSI name)'!AK3,OFFSET('＠グループ、表示名'!$H$4,MATCH('＠MFP (LSI name)'!AK3,'＠グループ、表示名'!$D$4:$D$250,0)-1,0))) | AL3: =IF(COUNTIF(J3,"P*")>0,"IO"&LEFT(J3,2)&"MD["&RIGHT(J3,1)*4+3&"]","") -> IOP0MD[11] | AM3: =IF(COUNTIF(J3,"P*")>0,"IO"&LEFT(J3,2)&"MD["&RIGHT(J3,1)*4+2&"]","") -> IOP0MD[10] | AN3: =IF(COUNTIF(J3,"P*")>0,"IO"&LEFT(J3,2)&"MD["&RIGHT(J3,1)*4+1&"]","") -> IOP0MD[9] | AO3: =IF(COUNTIF(J3,"P*")>0,"IO"&LEFT(J3,2)&"MD["&RIGHT(J3,1)*4&"]","") -> IOP0MD[8]
A4: 3 | B4: 3 | C4: 2 | F4: 3 | G4: 2 | I4: GPF[0] | J4: PF.0 | K4: =IF('＠MFP (LSI name)'!K4="","",IF(COUNTIF('＠MFP (LSI name)'!K4,"Serial*")+COUNTIF('＠MFP (LSI name)'!K4,"Analog*")>0,'＠MFP (LSI name)'!K4,OFFSET('＠グループ、表示名'!$H$4,MATCH('＠MFP (LSI name)'!K4,'＠グループ、表示名'!$D$4:$D$250,0)-1,0))) -> TM15A | L4: =IF('＠MFP (LSI name)'!L4="","",IF(COUNTIF('＠MFP (LSI name)'!L4,"Serial*")+COUNTIF('＠MFP (LSI name)'!L4,"Analog*")>0,'＠MFP (LSI name)'!L4,OFFSET('＠グループ、表示名'!$H$4,MATCH('＠MFP (LSI name)'!L4,'＠グループ、表示名'!$D$4:$D$250,0)-1,0))) | M4: =IF('＠MFP (LSI name)'!M4="","",IF(COUNTIF('＠MFP (LSI name)'!M4,"Serial*")+COUNTIF('＠MFP (LSI name)'!M4,"Analog*")>0,'＠MFP (LSI name)'!M4,OFFSET('＠グループ、表示名'!$H$4,MATCH('＠MFP (LSI name)'!M4,'＠グループ、表示名'!$D$4:$D$250,0)-1,0))) | N4: =IF('＠MFP (LSI name)'!N4="","",IF(COUNTIF('＠MFP (LSI name)'!N4,"Serial*")+COUNTIF('＠MFP (LSI name)'!N4,"Analog*")>0,'＠MFP (LSI name)'!N4,OFFSET('＠グループ、表示名'!$H$4,MATCH('＠MFP (LSI name)'!N4,'＠グループ、表示名'!$D$4:$D$250,0)-1,0))) | O4: =IF('＠MFP (LSI name)'!O4="","",IF(COUNTIF('＠MFP (LSI name)'!O4,"Serial*")+COUNTIF('＠MFP (LSI name)'!O4,"Analog*")>0,'＠MFP (LSI name)'!O4,OFFSET('＠グループ、表示名'!$H$4,MATCH('＠MFP (LSI name)'!O4,'＠グループ、表示名'!$D$4:$D$250,0)-1,0))) | P4: =IF('＠MFP (LSI name)'!P4="","",IF(COUNTIF('＠MFP (LSI name)'!P4,"Serial*")+COUNTIF('＠MFP (LSI name)'!P4,"Analog*")>0,'＠MFP (LSI name)'!P4,OFFSET('＠グループ、表示名'!$H$4,MATCH('＠MFP (LSI name)'!P4,'＠グループ、表示名'!$D$4:$D$250,0)-1,0))) | Q4: =IF('＠MFP (LSI name)'!Q4="","",IF(COUNTIF('＠MFP (LSI name)'!Q4,"Serial*")+COUNTIF('＠MFP (LSI name)'!Q4,"Analog*")>0,'＠MFP (LSI name)'!Q4,OFFSET('＠グループ、表示名'!$H$4,MATCH('＠MFP (LSI name)'!Q4,'＠グループ、表示名'!$D$4:$D$250,0)-1,0))) | R4: =IF('＠MFP (LSI name)'!R4="","",IF(COUNTIF('＠MFP (LSI name)'!R4,"Serial*")+COUNTIF('＠MFP (LSI name)'!R4,"Analog*")>0,'＠MFP (LSI name)'!R4,OFFSET('＠グループ、表示名'!$H$4,MATCH('＠MFP (LSI name)'!R4,'＠グループ、表示名'!$D$4:$D$250,0)-1,0))) | ... AK4: =IF('＠MFP (LSI name)'!AK4="","",IF(COUNTIF('＠MFP (LSI name)'!AK4,"Serial*")+COUNTIF('＠MFP (LSI name)'!AK4,"Analog*")>0,'＠MFP (LSI name)'!AK4,OFFSET('＠グループ、表示名'!$H$4,MATCH('＠MFP (LSI name)'!AK4,'＠グループ、表示名'!$D$4:$D$250,0)-1,0))) | AL4: =IF(COUNTIF(J4,"P*")>0,"IO"&LEFT(J4,2)&"MD["&RIGHT(J4,1)*4+3&"]","") -> IOPFMD[3] | AM4: =IF(COUNTIF(J4,"P*")>0,"IO"&LEFT(J4,2)&"MD["&RIGHT(J4,1)*4+2&"]","") -> IOPFMD[2] | AN4: =IF(COUNTIF(J4,"P*")>0,"IO"&LEFT(J4,2)&"MD["&RIGHT(J4,1)*4+1&"]","") -> IOPFMD[1] | AO4: =IF(COUNTIF(J4,"P*")>0,"IO"&LEFT(J4,2)&"MD["&RIGHT(J4,1)*4&"]","") -> IOPFMD[0]
A5: 4 | B5: 4 | C5: 3 | D5: 2 | F5: 4 | G5: 3 | H5: 2 | I5: GP0[0] | J5: P0.0 | K5: =IF('＠MFP (LSI name)'!K5="","",IF(COUNTIF('＠MFP (LSI name)'!K5,"Serial*")+COUNTIF('＠MFP (LSI name)'!K5,"Analog*")>0,'＠MFP (LSI name)'!K5,OFFSET('＠グループ、表示名'!$H$4,MATCH('＠MFP (LSI name)'!K5,'＠グループ、表示名'!$D$4:$D$250,0)-1,0))) -> IRQ02 | L5: =IF('＠MFP (LSI name)'!L5="","",IF(COUNTIF('＠MFP (LSI name)'!L5,"Serial*")+COUNTIF('＠MFP (LSI name)'!L5,"Analog*")>0,'＠MFP (LSI name)'!L5,OFFSET('＠グループ、表示名'!$H$4,MATCH('＠MFP (LSI name)'!L5,'＠グループ、表示名'!$D$4:$D$250,0)-1,0))) -> SIF4_SBI4 | M5: =IF('＠MFP (LSI name)'!M5="","",IF(COUNTIF('＠MFP (LSI name)'!M5,"Serial*")+COUNTIF('＠MFP (LSI name)'!M5,"Analog*")>0,'＠MFP (LSI name)'!M5,OFFSET('＠グループ、表示名'!$H$4,MATCH('＠MFP (LSI name)'!M5,'＠グループ、表示名'!$D$4:$D$250,0)-1,0))) -> SIF4_SBO4 | N5: =IF('＠MFP (LSI name)'!N5="","",IF(COUNTIF('＠MFP (LSI name)'!N5,"Serial*")+COUNTIF('＠MFP (LSI name)'!N5,"Analog*")>0,'＠MFP (LSI name)'!N5,OFFSET('＠グループ、表示名'!$H$4,MATCH('＠MFP (LSI name)'!N5,'＠グループ、表示名'!$D$4:$D$250,0)-1,0))) -> ADST1 | O5: =IF('＠MFP (LSI name)'!O5="","",IF(COUNTIF('＠MFP (LSI name)'!O5,"Serial*")+COUNTIF('＠MFP (LSI name)'!O5,"Analog*")>0,'＠MFP (LSI name)'!O5,OFFSET('＠グループ、表示名'!$H$4,MATCH('＠MFP (LSI name)'!O5,'＠グループ、表示名'!$D$4:$D$250,0)-1,0))) | P5: =IF('＠MFP (LSI name)'!P5="","",IF(COUNTIF('＠MFP (LSI name)'!P5,"Serial*")+COUNTIF('＠MFP (LSI name)'!P5,"Analog*")>0,'＠MFP (LSI name)'!P5,OFFSET('＠グループ、表示名'!$H$4,MATCH('＠MFP (LSI name)'!P5,'＠グループ、表示名'!$D$4:$D$250,0)-1,0))) | Q5: =IF('＠MFP (LSI name)'!Q5="","",IF(COUNTIF('＠MFP (LSI name)'!Q5,"Serial*")+COUNTIF('＠MFP (LSI name)'!Q5,"Analog*")>0,'＠MFP (LSI name)'!Q5,OFFSET('＠グループ、表示名'!$H$4,MATCH('＠MFP (LSI name)'!Q5,'＠グループ、表示名'!$D$4:$D$250,0)-1,0))) | R5: =IF('＠MFP (LSI name)'!R5="","",IF(COUNTIF('＠MFP (LSI name)'!R5,"Serial*")+COUNTIF('＠MFP (LSI name)'!R5,"Analog*")>0,'＠MFP (LSI name)'!R5,OFFSET('＠グループ、表示名'!$H$4,MATCH('＠MFP (LSI name)'!R5,'＠グループ、表示名'!$D$4:$D$250,0)-1,0))) | ... AK5: =IF('＠MFP (LSI name)'!AK5="","",IF(COUNTIF('＠MFP (LSI name)'!AK5,"Serial*")+COUNTIF('＠MFP (LSI name)'!AK5,"Analog*")>0,'＠MFP (LSI name)'!AK5,OFFSET('＠グループ、表示名'!$H$4,MATCH('＠MFP (LSI name)'!AK5,'＠グループ、表示名'!$D$4:$D$250,0)-1,0))) | AL5: =IF(COUNTIF(J5,"P*")>0,"IO"&LEFT(J5,2)&"MD["&RIGHT(J5,1)*4+3&"]","") -> IOP0MD[3] | AM5: =IF(COUNTIF(J5,"P*")>0,"IO"&LEFT(J5,2)&"MD["&RIGHT(J5,1)*4+2&"]","") -> IOP0MD[2] | AN5: =IF(COUNTIF(J5,"P*")>0,"IO"&LEFT(J5,2)&"MD["&RIGHT(J5,1)*4+1&"]","") -> IOP0MD[1] | AO5: =IF(COUNTIF(J5,"P*")>0,"IO"&LEFT(J5,2)&"MD["&RIGHT(J5,1)*4&"]","") -> IOP0MD[0]
A6: 5 | B6: 5 | C6: 4 | D6: 3 | E6: 1 | F6: 5 | G6: 4 | H6: 3 | I6: VOUT12 | J6: VOUT12 | K6: =IF('＠MFP (LSI name)'!K6="","",IF(COUNTIF('＠MFP (LSI name)'!K6,"Serial*")+COUNTIF('＠MFP (LSI name)'!K6,"Analog*")>0,'＠MFP (LSI name)'!K6,OFFSET('＠グループ、表示名'!$H$4,MATCH('＠MFP (LSI name)'!K6,'＠グループ、表示名'!$D$4:$D$250,0)-1,0))) | L6: =IF('＠MFP (LSI name)'!L6="","",IF(COUNTIF('＠MFP (LSI name)'!L6,"Serial*")+COUNTIF('＠MFP (LSI name)'!L6,"Analog*")>0,'＠MFP (LSI name)'!L6,OFFSET('＠グループ、表示名'!$H$4,MATCH('＠MFP (LSI name)'!L6,'＠グループ、表示名'!$D$4:$D$250,0)-1,0))) | M6: =IF('＠MFP (LSI name)'!M6="","",IF(COUNTIF('＠MFP (LSI name)'!M6,"Serial*")+COUNTIF('＠MFP (LSI name)'!M6,"Analog*")>0,'＠MFP (LSI name)'!M6,OFFSET('＠グループ、表示名'!$H$4,MATCH('＠MFP (LSI name)'!M6,'＠グループ、表示名'!$D$4:$D$250,0)-1,0))) | N6: =IF('＠MFP (LSI name)'!N6="","",IF(COUNTIF('＠MFP (LSI name)'!N6,"Serial*")+COUNTIF('＠MFP (LSI name)'!N6,"Analog*")>0,'＠MFP (LSI name)'!N6,OFFSET('＠グループ、表示名'!$H$4,MATCH('＠MFP (LSI name)'!N6,'＠グループ、表示名'!$D$4:$D$250,0)-1,0))) | O6: =IF('＠MFP (LSI name)'!O6="","",IF(COUNTIF('＠MFP (LSI name)'!O6,"Serial*")+COUNTIF('＠MFP (LSI name)'!O6,"Analog*")>0,'＠MFP (LSI name)'!O6,OFFSET('＠グループ、表示名'!$H$4,MATCH('＠MFP (LSI name)'!O6,'＠グループ、表示名'!$D$4:$D$250,0)-1,0))) | P6: =IF('＠MFP (LSI name)'!P6="","",IF(COUNTIF('＠MFP (LSI name)'!P6,"Serial*")+COUNTIF('＠MFP (LSI name)'!P6,"Analog*")>0,'＠MFP (LSI name)'!P6,OFFSET('＠グループ、表示名'!$H$4,MATCH('＠MFP (LSI name)'!P6,'＠グループ、表示名'!$D$4:$D$250,0)-1,0))) | Q6: =IF('＠MFP (LSI name)'!Q6="","",IF(COUNTIF('＠MFP (LSI name)'!Q6,"Serial*")+COUNTIF('＠MFP (LSI name)'!Q6,"Analog*")>0,'＠MFP (LSI name)'!Q6,OFFSET('＠グループ、表示名'!$H$4,MATCH('＠MFP (LSI name)'!Q6,'＠グループ、表示名'!$D$4:$D$250,0)-1,0))) | R6: =IF('＠MFP (LSI name)'!R6="","",IF(COUNTIF('＠MFP (LSI name)'!R6,"Serial*")+COUNTIF('＠MFP (LSI name)'!R6,"Analog*")>0,'＠MFP (LSI name)'!R6,OFFSET('＠グループ、表示名'!$H$4,MATCH('＠MFP (LSI name)'!R6,'＠グループ、表示名'!$D$4:$D$250,0)-1,0))) | ... AK6: =IF('＠MFP (LSI name)'!AK6="","",IF(COUNTIF('＠MFP (LSI name)'!AK6,"Serial*")+COUNTIF('＠MFP (LSI name)'!AK6,"Analog*")>0,'＠MFP (LSI name)'!AK6,OFFSET('＠グループ、表示名'!$H$4,MATCH('＠MFP (LSI name)'!AK6,'＠グループ、表示名'!$D$4:$D$250,0)-1,0))) | AL6: =IF(COUNTIF(J6,"P*")>0,"IO"&LEFT(J6,2)&"MD["&RIGHT(J6,1)*4+3&"]","") | AM6: =IF(COUNTIF(J6,"P*")>0,"IO"&LEFT(J6,2)&"MD["&RIGHT(J6,1)*4+2&"]","") | AN6: =IF(COUNTIF(J6,"P*")>0,"IO"&LEFT(J6,2)&"MD["&RIGHT(J6,1)*4+1&"]","") | AO6: =IF(COUNTIF(J6,"P*")>0,"IO"&LEFT(J6,2)&"MD["&RIGHT(J6,1)*4&"]","")
A7: 6 | B7: 6 | C7: 5 | D7: 4 | E7: 2 | F7: 6 | G7: 5 | H7: 4 | I7: NBOOT | J7: NBOOT | K7: =IF('＠MFP (LSI name)'!K7="","",IF(COUNTIF('＠MFP (LSI name)'!K7,"Serial*")+COUNTIF('＠MFP (LSI name)'!K7,"Analog*")>0,'＠MFP (LSI name)'!K7,OFFSET('＠グループ、表示名'!$H$4,MATCH('＠MFP (LSI name)'!K7,'＠グループ、表示名'!$D$4:$D$250,0)-1,0))) | L7: =IF('＠MFP (LSI name)'!L7="","",IF(COUNTIF('＠MFP (LSI name)'!L7,"Serial*")+COUNTIF('＠MFP (LSI name)'!L7,"Analog*")>0,'＠MFP (LSI name)'!L7,OFFSET('＠グループ、表示名'!$H$4,MATCH('＠MFP (LSI name)'!L7,'＠グループ、表示名'!$D$4:$D$250,0)-1,0))) | M7: =IF('＠MFP (LSI name)'!M7="","",IF(COUNTIF('＠MFP (LSI name)'!M7,"Serial*")+COUNTIF('＠MFP (LSI name)'!M7,"Analog*")>0,'＠MFP (LSI name)'!M7,OFFSET('＠グループ、表示名'!$H$4,MATCH('＠MFP (LSI name)'!M7,'＠グループ、表示名'!$D$4:$D$250,0)-1,0))) | N7: =IF('＠MFP (LSI name)'!N7="","",IF(COUNTIF('＠MFP (LSI name)'!N7,"Serial*")+COUNTIF('＠MFP (LSI name)'!N7,"Analog*")>0,'＠MFP (LSI name)'!N7,OFFSET('＠グループ、表示名'!$H$4,MATCH('＠MFP (LSI name)'!N7,'＠グループ、表示名'!$D$4:$D$250,0)-1,0))) | O7: =IF('＠MFP (LSI name)'!O7="","",IF(COUNTIF('＠MFP (LSI name)'!O7,"Serial*")+COUNTIF('＠MFP (LSI name)'!O7,"Analog*")>0,'＠MFP (LSI name)'!O7,OFFSET('＠グループ、表示名'!$H$4,MATCH('＠MFP (LSI name)'!O7,'＠グループ、表示名'!$D$4:$D$250,0)-1,0))) | P7: =IF('＠MFP (LSI name)'!P7="","",IF(COUNTIF('＠MFP (LSI name)'!P7,"Serial*")+COUNTIF('＠MFP (LSI name)'!P7,"Analog*")>0,'＠MFP (LSI name)'!P7,OFFSET('＠グループ、表示名'!$H$4,MATCH('＠MFP (LSI name)'!P7,'＠グループ、表示名'!$D$4:$D$250,0)-1,0))) | Q7: =IF('＠MFP (LSI name)'!Q7="","",IF(COUNTIF('＠MFP (LSI name)'!Q7,"Serial*")+COUNTIF('＠MFP (LSI name)'!Q7,"Analog*")>0,'＠MFP (LSI name)'!Q7,OFFSET('＠グループ、表示名'!$H$4,MATCH('＠MFP (LSI name)'!Q7,'＠グループ、表示名'!$D$4:$D$250,0)-1,0))) | R7: =IF('＠MFP (LSI name)'!R7="","",IF(COUNTIF('＠MFP (LSI name)'!R7,"Serial*")+COUNTIF('＠MFP (LSI name)'!R7,"Analog*")>0,'＠MFP (LSI name)'!R7,OFFSET('＠グループ、表示名'!$H$4,MATCH('＠MFP (LSI name)'!R7,'＠グループ、表示名'!$D$4:$D$250,0)-1,0))) | ... AK7: =IF('＠MFP (LSI name)'!AK7="","",IF(COUNTIF('＠MFP (LSI name)'!AK7,"Serial*")+COUNTIF('＠MFP (LSI name)'!AK7,"Analog*")>0,'＠MFP (LSI name)'!AK7,OFFSET('＠グループ、表示名'!$H$4,MATCH('＠MFP (LSI name)'!AK7,'＠グループ、表示名'!$D$4:$D$250,0)-1,0))) | AL7: =IF(COUNTIF(J7,"P*")>0,"IO"&LEFT(J7,2)&"MD["&RIGHT(J7,1)*4+3&"]","") | AM7: =IF(COUNTIF(J7,"P*")>0,"IO"&LEFT(J7,2)&"MD["&RIGHT(J7,1)*4+2&"]","") | AN7: =IF(COUNTIF(J7,"P*")>0,"IO"&LEFT(J7,2)&"MD["&RIGHT(J7,1)*4+1&"]","") | AO7: =IF(COUNTIF(J7,"P*")>0,"IO"&LEFT(J7,2)&"MD["&RIGHT(J7,1)*4&"]","")
A8: 7 | B8: 7 | C8: 6 | D8: 5 | E8: 3 | F8: 7 | G8: 6 | H8: 5 | I8: GP0[1] | J8: P0.1 | K8: =IF('＠MFP (LSI name)'!K8="","",IF(COUNTIF('＠MFP (LSI name)'!K8,"Serial*")+COUNTIF('＠MFP (LSI name)'!K8,"Analog*")>0,'＠MFP (LSI name)'!K8,OFFSET('＠グループ、表示名'!$H$4,MATCH('＠MFP (LSI name)'!K8,'＠グループ、表示名'!$D$4:$D$250,0)-1,0))) -> IRQ04 | L8: =IF('＠MFP (LSI name)'!L8="","",IF(COUNTIF('＠MFP (LSI name)'!L8,"Serial*")+COUNTIF('＠MFP (LSI name)'!L8,"Analog*")>0,'＠MFP (LSI name)'!L8,OFFSET('＠グループ、表示名'!$H$4,MATCH('＠MFP (LSI name)'!L8,'＠グループ、表示名'!$D$4:$D$250,0)-1,0))) -> IRQ15 | M8: =IF('＠MFP (LSI name)'!M8="","",IF(COUNTIF('＠MFP (LSI name)'!M8,"Serial*")+COUNTIF('＠MFP (LSI name)'!M8,"Analog*")>0,'＠MFP (LSI name)'!M8,OFFSET('＠グループ、表示名'!$H$4,MATCH('＠MFP (LSI name)'!M8,'＠グループ、表示名'!$D$4:$D$250,0)-1,0))) -> GPWM6_GPWMST6 | N8: =IF('＠MFP (LSI name)'!N8="","",IF(COUNTIF('＠MFP (LSI name)'!N8,"Serial*")+COUNTIF('＠MFP (LSI name)'!N8,"Analog*")>0,'＠MFP (LSI name)'!N8,OFFSET('＠グループ、表示名'!$H$4,MATCH('＠MFP (LSI name)'!N8,'＠グループ、表示名'!$D$4:$D$250,0)-1,0))) -> ADST2 | O8: =IF('＠MFP (LSI name)'!O8="","",IF(COUNTIF('＠MFP (LSI name)'!O8,"Serial*")+COUNTIF('＠MFP (LSI name)'!O8,"Analog*")>0,'＠MFP (LSI name)'!O8,OFFSET('＠グループ、表示名'!$H$4,MATCH('＠MFP (LSI name)'!O8,'＠グループ、表示名'!$D$4:$D$250,0)-1,0))) -> SIF4_SBT4 | P8: =IF('＠MFP (LSI name)'!P8="","",IF(COUNTIF('＠MFP (LSI name)'!P8,"Serial*")+COUNTIF('＠MFP (LSI name)'!P8,"Analog*")>0,'＠MFP (LSI name)'!P8,OFFSET('＠グループ、表示名'!$H$4,MATCH('＠MFP (LSI name)'!P8,'＠グループ、表示名'!$D$4:$D$250,0)-1,0))) | Q8: =IF('＠MFP (LSI name)'!Q8="","",IF(COUNTIF('＠MFP (LSI name)'!Q8,"Serial*")+COUNTIF('＠MFP (LSI name)'!Q8,"Analog*")>0,'＠MFP (LSI name)'!Q8,OFFSET('＠グループ、表示名'!$H$4,MATCH('＠MFP (LSI name)'!Q8,'＠グループ、表示名'!$D$4:$D$250,0)-1,0))) | R8: =IF('＠MFP (LSI name)'!R8="","",IF(COUNTIF('＠MFP (LSI name)'!R8,"Serial*")+COUNTIF('＠MFP (LSI name)'!R8,"Analog*")>0,'＠MFP (LSI name)'!R8,OFFSET('＠グループ、表示名'!$H$4,MATCH('＠MFP (LSI name)'!R8,'＠グループ、表示名'!$D$4:$D$250,0)-1,0))) | ... AK8: =IF('＠MFP (LSI name)'!AK8="","",IF(COUNTIF('＠MFP (LSI name)'!AK8,"Serial*")+COUNTIF('＠MFP (LSI name)'!AK8,"Analog*")>0,'＠MFP (LSI name)'!AK8,OFFSET('＠グループ、表示名'!$H$4,MATCH('＠MFP (LSI name)'!AK8,'＠グループ、表示名'!$D$4:$D$250,0)-1,0))) | AL8: =IF(COUNTIF(J8,"P*")>0,"IO"&LEFT(J8,2)&"MD["&RIGHT(J8,1)*4+3&"]","") -> IOP0MD[7] | AM8: =IF(COUNTIF(J8,"P*")>0,"IO"&LEFT(J8,2)&"MD["&RIGHT(J8,1)*4+2&"]","") -> IOP0MD[6] | AN8: =IF(COUNTIF(J8,"P*")>0,"IO"&LEFT(J8,2)&"MD["&RIGHT(J8,1)*4+1&"]","") -> IOP0MD[5] | AO8: =IF(COUNTIF(J8,"P*")>0,"IO"&LEFT(J8,2)&"MD["&RIGHT(J8,1)*4&"]","") -> IOP0MD[4]
A9: 8 | B9: 8 | C9: 7 | F9: 8 | G9: 7 | I9: GPE[4] | J9: PE.4 | K9: =IF('＠MFP (LSI name)'!K9="","",IF(COUNTIF('＠MFP (LSI name)'!K9,"Serial*")+COUNTIF('＠MFP (LSI name)'!K9,"Analog*")>0,'＠MFP (LSI name)'!K9,OFFSET('＠グループ、表示名'!$H$4,MATCH('＠MFP (LSI name)'!K9,'＠グループ、表示名'!$D$4:$D$250,0)-1,0))) -> IRQ01 | L9: =IF('＠MFP (LSI name)'!L9="","",IF(COUNTIF('＠MFP (LSI name)'!L9,"Serial*")+COUNTIF('＠MFP (LSI name)'!L9,"Analog*")>0,'＠MFP (LSI name)'!L9,OFFSET('＠グループ、表示名'!$H$4,MATCH('＠MFP (LSI name)'!L9,'＠グループ、表示名'!$D$4:$D$250,0)-1,0))) -> IRQ13 | M9: =IF('＠MFP (LSI name)'!M9="","",IF(COUNTIF('＠MFP (LSI name)'!M9,"Serial*")+COUNTIF('＠MFP (LSI name)'!M9,"Analog*")>0,'＠MFP (LSI name)'!M9,OFFSET('＠グループ、表示名'!$H$4,MATCH('＠MFP (LSI name)'!M9,'＠グループ、表示名'!$D$4:$D$250,0)-1,0))) -> TM12A | N9: =IF('＠MFP (LSI name)'!N9="","",IF(COUNTIF('＠MFP (LSI name)'!N9,"Serial*")+COUNTIF('＠MFP (LSI name)'!N9,"Analog*")>0,'＠MFP (LSI name)'!N9,OFFSET('＠グループ、表示名'!$H$4,MATCH('＠MFP (LSI name)'!N9,'＠グループ、表示名'!$D$4:$D$250,0)-1,0))) -> SIF4_SBCS4 | O9: =IF('＠MFP (LSI name)'!O9="","",IF(COUNTIF('＠MFP (LSI name)'!O9,"Serial*")+COUNTIF('＠MFP (LSI name)'!O9,"Analog*")>0,'＠MFP (LSI name)'!O9,OFFSET('＠グループ、表示名'!$H$4,MATCH('＠MFP (LSI name)'!O9,'＠グループ、表示名'!$D$4:$D$250,0)-1,0))) | P9: =IF('＠MFP (LSI name)'!P9="","",IF(COUNTIF('＠MFP (LSI name)'!P9,"Serial*")+COUNTIF('＠MFP (LSI name)'!P9,"Analog*")>0,'＠MFP (LSI name)'!P9,OFFSET('＠グループ、表示名'!$H$4,MATCH('＠MFP (LSI name)'!P9,'＠グループ、表示名'!$D$4:$D$250,0)-1,0))) | Q9: =IF('＠MFP (LSI name)'!Q9="","",IF(COUNTIF('＠MFP (LSI name)'!Q9,"Serial*")+COUNTIF('＠MFP (LSI name)'!Q9,"Analog*")>0,'＠MFP (LSI name)'!Q9,OFFSET('＠グループ、表示名'!$H$4,MATCH('＠MFP (LSI name)'!Q9,'＠グループ、表示名'!$D$4:$D$250,0)-1,0))) | R9: =IF('＠MFP (LSI name)'!R9="","",IF(COUNTIF('＠MFP (LSI name)'!R9,"Serial*")+COUNTIF('＠MFP (LSI name)'!R9,"Analog*")>0,'＠MFP (LSI name)'!R9,OFFSET('＠グループ、表示名'!$H$4,MATCH('＠MFP (LSI name)'!R9,'＠グループ、表示名'!$D$4:$D$250,0)-1,0))) | ... AK9: =IF('＠MFP (LSI name)'!AK9="","",IF(COUNTIF('＠MFP (LSI name)'!AK9,"Serial*")+COUNTIF('＠MFP (LSI name)'!AK9,"Analog*")>0,'＠MFP (LSI name)'!AK9,OFFSET('＠グループ、表示名'!$H$4,MATCH('＠MFP (LSI name)'!AK9,'＠グループ、表示名'!$D$4:$D$250,0)-1,0))) | AL9: =IF(COUNTIF(J9,"P*")>0,"IO"&LEFT(J9,2)&"MD["&RIGHT(J9,1)*4+3&"]","") -> IOPEMD[19] | AM9: =IF(COUNTIF(J9,"P*")>0,"IO"&LEFT(J9,2)&"MD["&RIGHT(J9,1)*4+2&"]","") -> IOPEMD[18] | AN9: =IF(COUNTIF(J9,"P*")>0,"IO"&LEFT(J9,2)&"MD["&RIGHT(J9,1)*4+1&"]","") -> IOPEMD[17] | AO9: =IF(COUNTIF(J9,"P*")>0,"IO"&LEFT(J9,2)&"MD["&RIGHT(J9,1)*4&"]","") -> IOPEMD[16]
A10: 9 | B10: 9 | C10: 8 | F10: 9 | G10: 8 | I10: GPE[3] | J10: PE.3 | K10: =IF('＠MFP (LSI name)'!K10="","",IF(COUNTIF('＠MFP (LSI name)'!K10,"Serial*")+COUNTIF('＠MFP (LSI name)'!K10,"Analog*")>0,'＠MFP (LSI name)'!K10,OFFSET('＠グループ、表示名'!$H$4,MATCH('＠MFP (LSI name)'!K10,'＠グループ、表示名'!$D$4:$D$250,0)-1,0))) -> IRQ02 | L10: =IF('＠MFP (LSI name)'!L10="","",IF(COUNTIF('＠MFP (LSI name)'!L10,"Serial*")+COUNTIF('＠MFP (LSI name)'!L10,"Analog*")>0,'＠MFP (LSI name)'!L10,OFFSET('＠グループ、表示名'!$H$4,MATCH('＠MFP (LSI name)'!L10,'＠グループ、表示名'!$D$4:$D$250,0)-1,0))) -> IRQ14 | M10: =IF('＠MFP (LSI name)'!M10="","",IF(COUNTIF('＠MFP (LSI name)'!M10,"Serial*")+COUNTIF('＠MFP (LSI name)'!M10,"Analog*")>0,'＠MFP (LSI name)'!M10,OFFSET('＠グループ、表示名'!$H$4,MATCH('＠MFP (LSI name)'!M10,'＠グループ、表示名'!$D$4:$D$250,0)-1,0))) -> TM12B | N10: =IF('＠MFP (LSI name)'!N10="","",IF(COUNTIF('＠MFP (LSI name)'!N10,"Serial*")+COUNTIF('＠MFP (LSI name)'!N10,"Analog*")>0,'＠MFP (LSI name)'!N10,OFFSET('＠グループ、表示名'!$H$4,MATCH('＠MFP (LSI name)'!N10,'＠グループ、表示名'!$D$4:$D$250,0)-1,0))) | O10: =IF('＠MFP (LSI name)'!O10="","",IF(COUNTIF('＠MFP (LSI name)'!O10,"Serial*")+COUNTIF('＠MFP (LSI name)'!O10,"Analog*")>0,'＠MFP (LSI name)'!O10,OFFSET('＠グループ、表示名'!$H$4,MATCH('＠MFP (LSI name)'!O10,'＠グループ、表示名'!$D$4:$D$250,0)-1,0))) | P10: =IF('＠MFP (LSI name)'!P10="","",IF(COUNTIF('＠MFP (LSI name)'!P10,"Serial*")+COUNTIF('＠MFP (LSI name)'!P10,"Analog*")>0,'＠MFP (LSI name)'!P10,OFFSET('＠グループ、表示名'!$H$4,MATCH('＠MFP (LSI name)'!P10,'＠グループ、表示名'!$D$4:$D$250,0)-1,0))) | Q10: =IF('＠MFP (LSI name)'!Q10="","",IF(COUNTIF('＠MFP (LSI name)'!Q10,"Serial*")+COUNTIF('＠MFP (LSI name)'!Q10,"Analog*")>0,'＠MFP (LSI name)'!Q10,OFFSET('＠グループ、表示名'!$H$4,MATCH('＠MFP (LSI name)'!Q10,'＠グループ、表示名'!$D$4:$D$250,0)-1,0))) | R10: =IF('＠MFP (LSI name)'!R10="","",IF(COUNTIF('＠MFP (LSI name)'!R10,"Serial*")+COUNTIF('＠MFP (LSI name)'!R10,"Analog*")>0,'＠MFP (LSI name)'!R10,OFFSET('＠グループ、表示名'!$H$4,MATCH('＠MFP (LSI name)'!R10,'＠グループ、表示名'!$D$4:$D$250,0)-1,0))) | ... AK10: =IF('＠MFP (LSI name)'!AK10="","",IF(COUNTIF('＠MFP (LSI name)'!AK10,"Serial*")+COUNTIF('＠MFP (LSI name)'!AK10,"Analog*")>0,'＠MFP (LSI name)'!AK10,OFFSET('＠グループ、表示名'!$H$4,MATCH('＠MFP (LSI name)'!AK10,'＠グループ、表示名'!$D$4:$D$250,0)-1,0))) | AL10: =IF(COUNTIF(J10,"P*")>0,"IO"&LEFT(J10,2)&"MD["&RIGHT(J10,1)*4+3&"]","") -> IOPEMD[15] | AM10: =IF(COUNTIF(J10,"P*")>0,"IO"&LEFT(J10,2)&"MD["&RIGHT(J10,1)*4+2&"]","") -> IOPEMD[14] | AN10: =IF(COUNTIF(J10,"P*")>0,"IO"&LEFT(J10,2)&"MD["&RIGHT(J10,1)*4+1&"]","") -> IOPEMD[13] | AO10: =IF(COUNTIF(J10,"P*")>0,"IO"&LEFT(J10,2)&"MD["&RIGHT(J10,1)*4&"]","") -> IOPEMD[12]
A11: 10 | B11: 10 | C11: 9 | D11: 6 | E11: 4 | F11: 10 | G11: 9 | H11: 6 | I11: nRESET | J11: NRST | K11: =IF('＠MFP (LSI name)'!K11="","",IF(COUNTIF('＠MFP (LSI name)'!K11,"Serial*")+COUNTIF('＠MFP (LSI name)'!K11,"Analog*")>0,'＠MFP (LSI name)'!K11,OFFSET('＠グループ、表示名'!$H$4,MATCH('＠MFP (LSI name)'!K11,'＠グループ、表示名'!$D$4:$D$250,0)-1,0))) | L11: =IF('＠MFP (LSI name)'!L11="","",IF(COUNTIF('＠MFP (LSI name)'!L11,"Serial*")+COUNTIF('＠MFP (LSI name)'!L11,"Analog*")>0,'＠MFP (LSI name)'!L11,OFFSET('＠グループ、表示名'!$H$4,MATCH('＠MFP (LSI name)'!L11,'＠グループ、表示名'!$D$4:$D$250,0)-1,0))) | M11: =IF('＠MFP (LSI name)'!M11="","",IF(COUNTIF('＠MFP (LSI name)'!M11,"Serial*")+COUNTIF('＠MFP (LSI name)'!M11,"Analog*")>0,'＠MFP (LSI name)'!M11,OFFSET('＠グループ、表示名'!$H$4,MATCH('＠MFP (LSI name)'!M11,'＠グループ、表示名'!$D$4:$D$250,0)-1,0))) | N11: =IF('＠MFP (LSI name)'!N11="","",IF(COUNTIF('＠MFP (LSI name)'!N11,"Serial*")+COUNTIF('＠MFP (LSI name)'!N11,"Analog*")>0,'＠MFP (LSI name)'!N11,OFFSET('＠グループ、表示名'!$H$4,MATCH('＠MFP (LSI name)'!N11,'＠グループ、表示名'!$D$4:$D$250,0)-1,0))) | O11: =IF('＠MFP (LSI name)'!O11="","",IF(COUNTIF('＠MFP (LSI name)'!O11,"Serial*")+COUNTIF('＠MFP (LSI name)'!O11,"Analog*")>0,'＠MFP (LSI name)'!O11,OFFSET('＠グループ、表示名'!$H$4,MATCH('＠MFP (LSI name)'!O11,'＠グループ、表示名'!$D$4:$D$250,0)-1,0))) | P11: =IF('＠MFP (LSI name)'!P11="","",IF(COUNTIF('＠MFP (LSI name)'!P11,"Serial*")+COUNTIF('＠MFP (LSI name)'!P11,"Analog*")>0,'＠MFP (LSI name)'!P11,OFFSET('＠グループ、表示名'!$H$4,MATCH('＠MFP (LSI name)'!P11,'＠グループ、表示名'!$D$4:$D$250,0)-1,0))) | Q11: =IF('＠MFP (LSI name)'!Q11="","",IF(COUNTIF('＠MFP (LSI name)'!Q11,"Serial*")+COUNTIF('＠MFP (LSI name)'!Q11,"Analog*")>0,'＠MFP (LSI name)'!Q11,OFFSET('＠グループ、表示名'!$H$4,MATCH('＠MFP (LSI name)'!Q11,'＠グループ、表示名'!$D$4:$D$250,0)-1,0))) | R11: =IF('＠MFP (LSI name)'!R11="","",IF(COUNTIF('＠MFP (LSI name)'!R11,"Serial*")+COUNTIF('＠MFP (LSI name)'!R11,"Analog*")>0,'＠MFP (LSI name)'!R11,OFFSET('＠グループ、表示名'!$H$4,MATCH('＠MFP (LSI name)'!R11,'＠グループ、表示名'!$D$4:$D$250,0)-1,0))) | ... AK11: =IF('＠MFP (LSI name)'!AK11="","",IF(COUNTIF('＠MFP (LSI name)'!AK11,"Serial*")+COUNTIF('＠MFP (LSI name)'!AK11,"Analog*")>0,'＠MFP (LSI name)'!AK11,OFFSET('＠グループ、表示名'!$H$4,MATCH('＠MFP (LSI name)'!AK11,'＠グループ、表示名'!$D$4:$D$250,0)-1,0))) | AL11: =IF(COUNTIF(J11,"P*")>0,"IO"&LEFT(J11,2)&"MD["&RIGHT(J11,1)*4+3&"]","") | AM11: =IF(COUNTIF(J11,"P*")>0,"IO"&LEFT(J11,2)&"MD["&RIGHT(J11,1)*4+2&"]","") | AN11: =IF(COUNTIF(J11,"P*")>0,"IO"&LEFT(J11,2)&"MD["&RIGHT(J11,1)*4+1&"]","") | AO11: =IF(COUNTIF(J11,"P*")>0,"IO"&LEFT(J11,2)&"MD["&RIGHT(J11,1)*4&"]","")
A12: 11 | B12: 11 | C12: 10 | D12: 7 | E12: 5 | F12: 11 | G12: 10 | H12: 7 | I12: OSCO | J12: OSCO | K12: =IF('＠MFP (LSI name)'!K12="","",IF(COUNTIF('＠MFP (LSI name)'!K12,"Serial*")+COUNTIF('＠MFP (LSI name)'!K12,"Analog*")>0,'＠MFP (LSI name)'!K12,OFFSET('＠グループ、表示名'!$H$4,MATCH('＠MFP (LSI name)'!K12,'＠グループ、表示名'!$D$4:$D$250,0)-1,0))) | L12: =IF('＠MFP (LSI name)'!L12="","",IF(COUNTIF('＠MFP (LSI name)'!L12,"Serial*")+COUNTIF('＠MFP (LSI name)'!L12,"Analog*")>0,'＠MFP (LSI name)'!L12,OFFSET('＠グループ、表示名'!$H$4,MATCH('＠MFP (LSI name)'!L12,'＠グループ、表示名'!$D$4:$D$250,0)-1,0))) | M12: =IF('＠MFP (LSI name)'!M12="","",IF(COUNTIF('＠MFP (LSI name)'!M12,"Serial*")+COUNTIF('＠MFP (LSI name)'!M12,"Analog*")>0,'＠MFP (LSI name)'!M12,OFFSET('＠グループ、表示名'!$H$4,MATCH('＠MFP (LSI name)'!M12,'＠グループ、表示名'!$D$4:$D$250,0)-1,0))) | N12: =IF('＠MFP (LSI name)'!N12="","",IF(COUNTIF('＠MFP (LSI name)'!N12,"Serial*")+COUNTIF('＠MFP (LSI name)'!N12,"Analog*")>0,'＠MFP (LSI name)'!N12,OFFSET('＠グループ、表示名'!$H$4,MATCH('＠MFP (LSI name)'!N12,'＠グループ、表示名'!$D$4:$D$250,0)-1,0))) | O12: =IF('＠MFP (LSI name)'!O12="","",IF(COUNTIF('＠MFP (LSI name)'!O12,"Serial*")+COUNTIF('＠MFP (LSI name)'!O12,"Analog*")>0,'＠MFP (LSI name)'!O12,OFFSET('＠グループ、表示名'!$H$4,MATCH('＠MFP (LSI name)'!O12,'＠グループ、表示名'!$D$4:$D$250,0)-1,0))) | P12: =IF('＠MFP (LSI name)'!P12="","",IF(COUNTIF('＠MFP (LSI name)'!P12,"Serial*")+COUNTIF('＠MFP (LSI name)'!P12,"Analog*")>0,'＠MFP (LSI name)'!P12,OFFSET('＠グループ、表示名'!$H$4,MATCH('＠MFP (LSI name)'!P12,'＠グループ、表示名'!$D$4:$D$250,0)-1,0))) | Q12: =IF('＠MFP (LSI name)'!Q12="","",IF(COUNTIF('＠MFP (LSI name)'!Q12,"Serial*")+COUNTIF('＠MFP (LSI name)'!Q12,"Analog*")>0,'＠MFP (LSI name)'!Q12,OFFSET('＠グループ、表示名'!$H$4,MATCH('＠MFP (LSI name)'!Q12,'＠グループ、表示名'!$D$4:$D$250,0)-1,0))) | R12: =IF('＠MFP (LSI name)'!R12="","",IF(COUNTIF('＠MFP (LSI name)'!R12,"Serial*")+COUNTIF('＠MFP (LSI name)'!R12,"Analog*")>0,'＠MFP (LSI name)'!R12,OFFSET('＠グループ、表示名'!$H$4,MATCH('＠MFP (LSI name)'!R12,'＠グループ、表示名'!$D$4:$D$250,0)-1,0))) | ... AK12: =IF('＠MFP (LSI name)'!AK12="","",IF(COUNTIF('＠MFP (LSI name)'!AK12,"Serial*")+COUNTIF('＠MFP (LSI name)'!AK12,"Analog*")>0,'＠MFP (LSI name)'!AK12,OFFSET('＠グループ、表示名'!$H$4,MATCH('＠MFP (LSI name)'!AK12,'＠グループ、表示名'!$D$4:$D$250,0)-1,0))) | AL12: =IF(COUNTIF(J12,"P*")>0,"IO"&LEFT(J12,2)&"MD["&RIGHT(J12,1)*4+3&"]","") | AM12: =IF(COUNTIF(J12,"P*")>0,"IO"&LEFT(J12,2)&"MD["&RIGHT(J12,1)*4+2&"]","") | AN12: =IF(COUNTIF(J12,"P*")>0,"IO"&LEFT(J12,2)&"MD["&RIGHT(J12,1)*4+1&"]","") | AO12: =IF(COUNTIF(J12,"P*")>0,"IO"&LEFT(J12,2)&"MD["&RIGHT(J12,1)*4&"]","")
A13: 12 | B13: 12 | C13: 11 | D13: 8 | E13: 6 | F13: 12 | G13: 11 | H13: 8 | I13: VSSPST | J13: VSS | K13: =IF('＠MFP (LSI name)'!K13="","",IF(COUNTIF('＠MFP (LSI name)'!K13,"Serial*")+COUNTIF('＠MFP (LSI name)'!K13,"Analog*")>0,'＠MFP (LSI name)'!K13,OFFSET('＠グループ、表示名'!$H$4,MATCH('＠MFP (LSI name)'!K13,'＠グループ、表示名'!$D$4:$D$250,0)-1,0))) | L13: =IF('＠MFP (LSI name)'!L13="","",IF(COUNTIF('＠MFP (LSI name)'!L13,"Serial*")+COUNTIF('＠MFP (LSI name)'!L13,"Analog*")>0,'＠MFP (LSI name)'!L13,OFFSET('＠グループ、表示名'!$H$4,MATCH('＠MFP (LSI name)'!L13,'＠グループ、表示名'!$D$4:$D$250,0)-1,0))) | M13: =IF('＠MFP (LSI name)'!M13="","",IF(COUNTIF('＠MFP (LSI name)'!M13,"Serial*")+COUNTIF('＠MFP (LSI name)'!M13,"Analog*")>0,'＠MFP (LSI name)'!M13,OFFSET('＠グループ、表示名'!$H$4,MATCH('＠MFP (LSI name)'!M13,'＠グループ、表示名'!$D$4:$D$250,0)-1,0))) | N13: =IF('＠MFP (LSI name)'!N13="","",IF(COUNTIF('＠MFP (LSI name)'!N13,"Serial*")+COUNTIF('＠MFP (LSI name)'!N13,"Analog*")>0,'＠MFP (LSI name)'!N13,OFFSET('＠グループ、表示名'!$H$4,MATCH('＠MFP (LSI name)'!N13,'＠グループ、表示名'!$D$4:$D$250,0)-1,0))) | O13: =IF('＠MFP (LSI name)'!O13="","",IF(COUNTIF('＠MFP (LSI name)'!O13,"Serial*")+COUNTIF('＠MFP (LSI name)'!O13,"Analog*")>0,'＠MFP (LSI name)'!O13,OFFSET('＠グループ、表示名'!$H$4,MATCH('＠MFP (LSI name)'!O13,'＠グループ、表示名'!$D$4:$D$250,0)-1,0))) | P13: =IF('＠MFP (LSI name)'!P13="","",IF(COUNTIF('＠MFP (LSI name)'!P13,"Serial*")+COUNTIF('＠MFP (LSI name)'!P13,"Analog*")>0,'＠MFP (LSI name)'!P13,OFFSET('＠グループ、表示名'!$H$4,MATCH('＠MFP (LSI name)'!P13,'＠グループ、表示名'!$D$4:$D$250,0)-1,0))) | Q13: =IF('＠MFP (LSI name)'!Q13="","",IF(COUNTIF('＠MFP (LSI name)'!Q13,"Serial*")+COUNTIF('＠MFP (LSI name)'!Q13,"Analog*")>0,'＠MFP (LSI name)'!Q13,OFFSET('＠グループ、表示名'!$H$4,MATCH('＠MFP (LSI name)'!Q13,'＠グループ、表示名'!$D$4:$D$250,0)-1,0))) | R13: =IF('＠MFP (LSI name)'!R13="","",IF(COUNTIF('＠MFP (LSI name)'!R13,"Serial*")+COUNTIF('＠MFP (LSI name)'!R13,"Analog*")>0,'＠MFP (LSI name)'!R13,OFFSET('＠グループ、表示名'!$H$4,MATCH('＠MFP (LSI name)'!R13,'＠グループ、表示名'!$D$4:$D$250,0)-1,0))) | ... AK13: =IF('＠MFP (LSI name)'!AK13="","",IF(COUNTIF('＠MFP (LSI name)'!AK13,"Serial*")+COUNTIF('＠MFP (LSI name)'!AK13,"Analog*")>0,'＠MFP (LSI name)'!AK13,OFFSET('＠グループ、表示名'!$H$4,MATCH('＠MFP (LSI name)'!AK13,'＠グループ、表示名'!$D$4:$D$250,0)-1,0))) | AL13: =IF(COUNTIF(J13,"P*")>0,"IO"&LEFT(J13,2)&"MD["&RIGHT(J13,1)*4+3&"]","") | AM13: =IF(COUNTIF(J13,"P*")>0,"IO"&LEFT(J13,2)&"MD["&RIGHT(J13,1)*4+2&"]","") | AN13: =IF(COUNTIF(J13,"P*")>0,"IO"&LEFT(J13,2)&"MD["&RIGHT(J13,1)*4+1&"]","") | AO13: =IF(COUNTIF(J13,"P*")>0,"IO"&LEFT(J13,2)&"MD["&RIGHT(J13,1)*4&"]","")
A14: 13 | B14: 13 | C14: 12 | D14: 9 | E14: 7 | F14: 13 | G14: 12 | H14: 9 | I14: OSCI | J14: OSCI | K14: =IF('＠MFP (LSI name)'!K14="","",IF(COUNTIF('＠MFP (LSI name)'!K14,"Serial*")+COUNTIF('＠MFP (LSI name)'!K14,"Analog*")>0,'＠MFP (LSI name)'!K14,OFFSET('＠グループ、表示名'!$H$4,MATCH('＠MFP (LSI name)'!K14,'＠グループ、表示名'!$D$4:$D$250,0)-1,0))) | L14: =IF('＠MFP (LSI name)'!L14="","",IF(COUNTIF('＠MFP (LSI name)'!L14,"Serial*")+COUNTIF('＠MFP (LSI name)'!L14,"Analog*")>0,'＠MFP (LSI name)'!L14,OFFSET('＠グループ、表示名'!$H$4,MATCH('＠MFP (LSI name)'!L14,'＠グループ、表示名'!$D$4:$D$250,0)-1,0))) | M14: =IF('＠MFP (LSI name)'!M14="","",IF(COUNTIF('＠MFP (LSI name)'!M14,"Serial*")+COUNTIF('＠MFP (LSI name)'!M14,"Analog*")>0,'＠MFP (LSI name)'!M14,OFFSET('＠グループ、表示名'!$H$4,MATCH('＠MFP (LSI name)'!M14,'＠グループ、表示名'!$D$4:$D$250,0)-1,0))) | N14: =IF('＠MFP (LSI name)'!N14="","",IF(COUNTIF('＠MFP (LSI name)'!N14,"Serial*")+COUNTIF('＠MFP (LSI name)'!N14,"Analog*")>0,'＠MFP (LSI name)'!N14,OFFSET('＠グループ、表示名'!$H$4,MATCH('＠MFP (LSI name)'!N14,'＠グループ、表示名'!$D$4:$D$250,0)-1,0))) | O14: =IF('＠MFP (LSI name)'!O14="","",IF(COUNTIF('＠MFP (LSI name)'!O14,"Serial*")+COUNTIF('＠MFP (LSI name)'!O14,"Analog*")>0,'＠MFP (LSI name)'!O14,OFFSET('＠グループ、表示名'!$H$4,MATCH('＠MFP (LSI name)'!O14,'＠グループ、表示名'!$D$4:$D$250,0)-1,0))) | P14: =IF('＠MFP (LSI name)'!P14="","",IF(COUNTIF('＠MFP (LSI name)'!P14,"Serial*")+COUNTIF('＠MFP (LSI name)'!P14,"Analog*")>0,'＠MFP (LSI name)'!P14,OFFSET('＠グループ、表示名'!$H$4,MATCH('＠MFP (LSI name)'!P14,'＠グループ、表示名'!$D$4:$D$250,0)-1,0))) | Q14: =IF('＠MFP (LSI name)'!Q14="","",IF(COUNTIF('＠MFP (LSI name)'!Q14,"Serial*")+COUNTIF('＠MFP (LSI name)'!Q14,"Analog*")>0,'＠MFP (LSI name)'!Q14,OFFSET('＠グループ、表示名'!$H$4,MATCH('＠MFP (LSI name)'!Q14,'＠グループ、表示名'!$D$4:$D$250,0)-1,0))) | R14: =IF('＠MFP (LSI name)'!R14="","",IF(COUNTIF('＠MFP (LSI name)'!R14,"Serial*")+COUNTIF('＠MFP (LSI name)'!R14,"Analog*")>0,'＠MFP (LSI name)'!R14,OFFSET('＠グループ、表示名'!$H$4,MATCH('＠MFP (LSI name)'!R14,'＠グループ、表示名'!$D$4:$D$250,0)-1,0))) | ... AK14: =IF('＠MFP (LSI name)'!AK14="","",IF(COUNTIF('＠MFP (LSI name)'!AK14,"Serial*")+COUNTIF('＠MFP (LSI name)'!AK14,"Analog*")>0,'＠MFP (LSI name)'!AK14,OFFSET('＠グループ、表示名'!$H$4,MATCH('＠MFP (LSI name)'!AK14,'＠グループ、表示名'!$D$4:$D$250,0)-1,0))) | AL14: =IF(COUNTIF(J14,"P*")>0,"IO"&LEFT(J14,2)&"MD["&RIGHT(J14,1)*4+3&"]","") | AM14: =IF(COUNTIF(J14,"P*")>0,"IO"&LEFT(J14,2)&"MD["&RIGHT(J14,1)*4+2&"]","") | AN14: =IF(COUNTIF(J14,"P*")>0,"IO"&LEFT(J14,2)&"MD["&RIGHT(J14,1)*4+1&"]","") | AO14: =IF(COUNTIF(J14,"P*")>0,"IO"&LEFT(J14,2)&"MD["&RIGHT(J14,1)*4&"]","")
A15: 14 | B15: 14 | C15: 13 | D15: 10 | E15: 8 | F15: 14 | G15: 13 | H15: 10 | I15: VDDPST | J15: VDD50 | K15: =IF('＠MFP (LSI name)'!K15="","",IF(COUNTIF('＠MFP (LSI name)'!K15,"Serial*")+COUNTIF('＠MFP (LSI name)'!K15,"Analog*")>0,'＠MFP (LSI name)'!K15,OFFSET('＠グループ、表示名'!$H$4,MATCH('＠MFP (LSI name)'!K15,'＠グループ、表示名'!$D$4:$D$250,0)-1,0))) | L15: =IF('＠MFP (LSI name)'!L15="","",IF(COUNTIF('＠MFP (LSI name)'!L15,"Serial*")+COUNTIF('＠MFP (LSI name)'!L15,"Analog*")>0,'＠MFP (LSI name)'!L15,OFFSET('＠グループ、表示名'!$H$4,MATCH('＠MFP (LSI name)'!L15,'＠グループ、表示名'!$D$4:$D$250,0)-1,0))) | M15: =IF('＠MFP (LSI name)'!M15="","",IF(COUNTIF('＠MFP (LSI name)'!M15,"Serial*")+COUNTIF('＠MFP (LSI name)'!M15,"Analog*")>0,'＠MFP (LSI name)'!M15,OFFSET('＠グループ、表示名'!$H$4,MATCH('＠MFP (LSI name)'!M15,'＠グループ、表示名'!$D$4:$D$250,0)-1,0))) | N15: =IF('＠MFP (LSI name)'!N15="","",IF(COUNTIF('＠MFP (LSI name)'!N15,"Serial*")+COUNTIF('＠MFP (LSI name)'!N15,"Analog*")>0,'＠MFP (LSI name)'!N15,OFFSET('＠グループ、表示名'!$H$4,MATCH('＠MFP (LSI name)'!N15,'＠グループ、表示名'!$D$4:$D$250,0)-1,0))) | O15: =IF('＠MFP (LSI name)'!O15="","",IF(COUNTIF('＠MFP (LSI name)'!O15,"Serial*")+COUNTIF('＠MFP (LSI name)'!O15,"Analog*")>0,'＠MFP (LSI name)'!O15,OFFSET('＠グループ、表示名'!$H$4,MATCH('＠MFP (LSI name)'!O15,'＠グループ、表示名'!$D$4:$D$250,0)-1,0))) | P15: =IF('＠MFP (LSI name)'!P15="","",IF(COUNTIF('＠MFP (LSI name)'!P15,"Serial*")+COUNTIF('＠MFP (LSI name)'!P15,"Analog*")>0,'＠MFP (LSI name)'!P15,OFFSET('＠グループ、表示名'!$H$4,MATCH('＠MFP (LSI name)'!P15,'＠グループ、表示名'!$D$4:$D$250,0)-1,0))) | Q15: =IF('＠MFP (LSI name)'!Q15="","",IF(COUNTIF('＠MFP (LSI name)'!Q15,"Serial*")+COUNTIF('＠MFP (LSI name)'!Q15,"Analog*")>0,'＠MFP (LSI name)'!Q15,OFFSET('＠グループ、表示名'!$H$4,MATCH('＠MFP (LSI name)'!Q15,'＠グループ、表示名'!$D$4:$D$250,0)-1,0))) | R15: =IF('＠MFP (LSI name)'!R15="","",IF(COUNTIF('＠MFP (LSI name)'!R15,"Serial*")+COUNTIF('＠MFP (LSI name)'!R15,"Analog*")>0,'＠MFP (LSI name)'!R15,OFFSET('＠グループ、表示名'!$H$4,MATCH('＠MFP (LSI name)'!R15,'＠グループ、表示名'!$D$4:$D$250,0)-1,0))) | ... AK15: =IF('＠MFP (LSI name)'!AK15="","",IF(COUNTIF('＠MFP (LSI name)'!AK15,"Serial*")+COUNTIF('＠MFP (LSI name)'!AK15,"Analog*")>0,'＠MFP (LSI name)'!AK15,OFFSET('＠グループ、表示名'!$H$4,MATCH('＠MFP (LSI name)'!AK15,'＠グループ、表示名'!$D$4:$D$250,0)-1,0))) | AL15: =IF(COUNTIF(J15,"P*")>0,"IO"&LEFT(J15,2)&"MD["&RIGHT(J15,1)*4+3&"]","") | AM15: =IF(COUNTIF(J15,"P*")>0,"IO"&LEFT(J15,2)&"MD["&RIGHT(J15,1)*4+2&"]","") | AN15: =IF(COUNTIF(J15,"P*")>0,"IO"&LEFT(J15,2)&"MD["&RIGHT(J15,1)*4+1&"]","") | AO15: =IF(COUNTIF(J15,"P*")>0,"IO"&LEFT(J15,2)&"MD["&RIGHT(J15,1)*4&"]","")
A16: 15 | B16: 15 | C16: 14 | D16: 11 | E16: 9 | F16: 15 | G16: 14 | H16: 11 | I16: GPE[2] | J16: PE.2 | K16: =IF('＠MFP (LSI name)'!K16="","",IF(COUNTIF('＠MFP (LSI name)'!K16,"Serial*")+COUNTIF('＠MFP (LSI name)'!K16,"Analog*")>0,'＠MFP (LSI name)'!K16,OFFSET('＠グループ、表示名'!$H$4,MATCH('＠MFP (LSI name)'!K16,'＠グループ、表示名'!$D$4:$D$250,0)-1,0))) -> NMI | L16: =IF('＠MFP (LSI name)'!L16="","",IF(COUNTIF('＠MFP (LSI name)'!L16,"Serial*")+COUNTIF('＠MFP (LSI name)'!L16,"Analog*")>0,'＠MFP (LSI name)'!L16,OFFSET('＠グループ、表示名'!$H$4,MATCH('＠MFP (LSI name)'!L16,'＠グループ、表示名'!$D$4:$D$250,0)-1,0))) -> IRQ13 | M16: =IF('＠MFP (LSI name)'!M16="","",IF(COUNTIF('＠MFP (LSI name)'!M16,"Serial*")+COUNTIF('＠MFP (LSI name)'!M16,"Analog*")>0,'＠MFP (LSI name)'!M16,OFFSET('＠グループ、表示名'!$H$4,MATCH('＠MFP (LSI name)'!M16,'＠グループ、表示名'!$D$4:$D$250,0)-1,0))) | N16: =IF('＠MFP (LSI name)'!N16="","",IF(COUNTIF('＠MFP (LSI name)'!N16,"Serial*")+COUNTIF('＠MFP (LSI name)'!N16,"Analog*")>0,'＠MFP (LSI name)'!N16,OFFSET('＠グループ、表示名'!$H$4,MATCH('＠MFP (LSI name)'!N16,'＠グループ、表示名'!$D$4:$D$250,0)-1,0))) | O16: =IF('＠MFP (LSI name)'!O16="","",IF(COUNTIF('＠MFP (LSI name)'!O16,"Serial*")+COUNTIF('＠MFP (LSI name)'!O16,"Analog*")>0,'＠MFP (LSI name)'!O16,OFFSET('＠グループ、表示名'!$H$4,MATCH('＠MFP (LSI name)'!O16,'＠グループ、表示名'!$D$4:$D$250,0)-1,0))) | P16: =IF('＠MFP (LSI name)'!P16="","",IF(COUNTIF('＠MFP (LSI name)'!P16,"Serial*")+COUNTIF('＠MFP (LSI name)'!P16,"Analog*")>0,'＠MFP (LSI name)'!P16,OFFSET('＠グループ、表示名'!$H$4,MATCH('＠MFP (LSI name)'!P16,'＠グループ、表示名'!$D$4:$D$250,0)-1,0))) | Q16: =IF('＠MFP (LSI name)'!Q16="","",IF(COUNTIF('＠MFP (LSI name)'!Q16,"Serial*")+COUNTIF('＠MFP (LSI name)'!Q16,"Analog*")>0,'＠MFP (LSI name)'!Q16,OFFSET('＠グループ、表示名'!$H$4,MATCH('＠MFP (LSI name)'!Q16,'＠グループ、表示名'!$D$4:$D$250,0)-1,0))) | R16: =IF('＠MFP (LSI name)'!R16="","",IF(COUNTIF('＠MFP (LSI name)'!R16,"Serial*")+COUNTIF('＠MFP (LSI name)'!R16,"Analog*")>0,'＠MFP (LSI name)'!R16,OFFSET('＠グループ、表示名'!$H$4,MATCH('＠MFP (LSI name)'!R16,'＠グループ、表示名'!$D$4:$D$250,0)-1,0))) | ... AK16: =IF('＠MFP (LSI name)'!AK16="","",IF(COUNTIF('＠MFP (LSI name)'!AK16,"Serial*")+COUNTIF('＠MFP (LSI name)'!AK16,"Analog*")>0,'＠MFP (LSI name)'!AK16,OFFSET('＠グループ、表示名'!$H$4,MATCH('＠MFP (LSI name)'!AK16,'＠グループ、表示名'!$D$4:$D$250,0)-1,0))) | AL16: =IF(COUNTIF(J16,"P*")>0,"IO"&LEFT(J16,2)&"MD["&RIGHT(J16,1)*4+3&"]","") -> IOPEMD[11] | AM16: =IF(COUNTIF(J16,"P*")>0,"IO"&LEFT(J16,2)&"MD["&RIGHT(J16,1)*4+2&"]","") -> IOPEMD[10] | AN16: =IF(COUNTIF(J16,"P*")>0,"IO"&LEFT(J16,2)&"MD["&RIGHT(J16,1)*4+1&"]","") -> IOPEMD[9] | AO16: =IF(COUNTIF(J16,"P*")>0,"IO"&LEFT(J16,2)&"MD["&RIGHT(J16,1)*4&"]","") -> IOPEMD[8]
A17: 16 | B17: 16 | F17: 16 | I17: GPE[1] | J17: PE.1 | K17: =IF('＠MFP (LSI name)'!K17="","",IF(COUNTIF('＠MFP (LSI name)'!K17,"Serial*")+COUNTIF('＠MFP (LSI name)'!K17,"Analog*")>0,'＠MFP (LSI name)'!K17,OFFSET('＠グループ、表示名'!$H$4,MATCH('＠MFP (LSI name)'!K17,'＠グループ、表示名'!$D$4:$D$250,0)-1,0))) -> TM05A | L17: =IF('＠MFP (LSI name)'!L17="","",IF(COUNTIF('＠MFP (LSI name)'!L17,"Serial*")+COUNTIF('＠MFP (LSI name)'!L17,"Analog*")>0,'＠MFP (LSI name)'!L17,OFFSET('＠グループ、表示名'!$H$4,MATCH('＠MFP (LSI name)'!L17,'＠グループ、表示名'!$D$4:$D$250,0)-1,0))) -> TM15B | M17: =IF('＠MFP (LSI name)'!M17="","",IF(COUNTIF('＠MFP (LSI name)'!M17,"Serial*")+COUNTIF('＠MFP (LSI name)'!M17,"Analog*")>0,'＠MFP (LSI name)'!M17,OFFSET('＠グループ、表示名'!$H$4,MATCH('＠MFP (LSI name)'!M17,'＠グループ、表示名'!$D$4:$D$250,0)-1,0))) -> SIF0_SBCS0 | N17: =IF('＠MFP (LSI name)'!N17="","",IF(COUNTIF('＠MFP (LSI name)'!N17,"Serial*")+COUNTIF('＠MFP (LSI name)'!N17,"Analog*")>0,'＠MFP (LSI name)'!N17,OFFSET('＠グループ、表示名'!$H$4,MATCH('＠MFP (LSI name)'!N17,'＠グループ、表示名'!$D$4:$D$250,0)-1,0))) | O17: =IF('＠MFP (LSI name)'!O17="","",IF(COUNTIF('＠MFP (LSI name)'!O17,"Serial*")+COUNTIF('＠MFP (LSI name)'!O17,"Analog*")>0,'＠MFP (LSI name)'!O17,OFFSET('＠グループ、表示名'!$H$4,MATCH('＠MFP (LSI name)'!O17,'＠グループ、表示名'!$D$4:$D$250,0)-1,0))) | P17: =IF('＠MFP (LSI name)'!P17="","",IF(COUNTIF('＠MFP (LSI name)'!P17,"Serial*")+COUNTIF('＠MFP (LSI name)'!P17,"Analog*")>0,'＠MFP (LSI name)'!P17,OFFSET('＠グループ、表示名'!$H$4,MATCH('＠MFP (LSI name)'!P17,'＠グループ、表示名'!$D$4:$D$250,0)-1,0))) | Q17: =IF('＠MFP (LSI name)'!Q17="","",IF(COUNTIF('＠MFP (LSI name)'!Q17,"Serial*")+COUNTIF('＠MFP (LSI name)'!Q17,"Analog*")>0,'＠MFP (LSI name)'!Q17,OFFSET('＠グループ、表示名'!$H$4,MATCH('＠MFP (LSI name)'!Q17,'＠グループ、表示名'!$D$4:$D$250,0)-1,0))) | R17: =IF('＠MFP (LSI name)'!R17="","",IF(COUNTIF('＠MFP (LSI name)'!R17,"Serial*")+COUNTIF('＠MFP (LSI name)'!R17,"Analog*")>0,'＠MFP (LSI name)'!R17,OFFSET('＠グループ、表示名'!$H$4,MATCH('＠MFP (LSI name)'!R17,'＠グループ、表示名'!$D$4:$D$250,0)-1,0))) | ... AK17: =IF('＠MFP (LSI name)'!AK17="","",IF(COUNTIF('＠MFP (LSI name)'!AK17,"Serial*")+COUNTIF('＠MFP (LSI name)'!AK17,"Analog*")>0,'＠MFP (LSI name)'!AK17,OFFSET('＠グループ、表示名'!$H$4,MATCH('＠MFP (LSI name)'!AK17,'＠グループ、表示名'!$D$4:$D$250,0)-1,0))) | AL17: =IF(COUNTIF(J17,"P*")>0,"IO"&LEFT(J17,2)&"MD["&RIGHT(J17,1)*4+3&"]","") -> IOPEMD[7] | AM17: =IF(COUNTIF(J17,"P*")>0,"IO"&LEFT(J17,2)&"MD["&RIGHT(J17,1)*4+2&"]","") -> IOPEMD[6] | AN17: =IF(COUNTIF(J17,"P*")>0,"IO"&LEFT(J17,2)&"MD["&RIGHT(J17,1)*4+1&"]","") -> IOPEMD[5] | AO17: =IF(COUNTIF(J17,"P*")>0,"IO"&LEFT(J17,2)&"MD["&RIGHT(J17,1)*4&"]","") -> IOPEMD[4]
A18: 17 | B18: 17 | F18: 17 | I18: GPE[0] | J18: PE.0 | K18: =IF('＠MFP (LSI name)'!K18="","",IF(COUNTIF('＠MFP (LSI name)'!K18,"Serial*")+COUNTIF('＠MFP (LSI name)'!K18,"Analog*")>0,'＠MFP (LSI name)'!K18,OFFSET('＠グループ、表示名'!$H$4,MATCH('＠MFP (LSI name)'!K18,'＠グループ、表示名'!$D$4:$D$250,0)-1,0))) -> TM01B | L18: =IF('＠MFP (LSI name)'!L18="","",IF(COUNTIF('＠MFP (LSI name)'!L18,"Serial*")+COUNTIF('＠MFP (LSI name)'!L18,"Analog*")>0,'＠MFP (LSI name)'!L18,OFFSET('＠グループ、表示名'!$H$4,MATCH('＠MFP (LSI name)'!L18,'＠グループ、表示名'!$D$4:$D$250,0)-1,0))) -> TM05B | M18: =IF('＠MFP (LSI name)'!M18="","",IF(COUNTIF('＠MFP (LSI name)'!M18,"Serial*")+COUNTIF('＠MFP (LSI name)'!M18,"Analog*")>0,'＠MFP (LSI name)'!M18,OFFSET('＠グループ、表示名'!$H$4,MATCH('＠MFP (LSI name)'!M18,'＠グループ、表示名'!$D$4:$D$250,0)-1,0))) -> TM14B | N18: =IF('＠MFP (LSI name)'!N18="","",IF(COUNTIF('＠MFP (LSI name)'!N18,"Serial*")+COUNTIF('＠MFP (LSI name)'!N18,"Analog*")>0,'＠MFP (LSI name)'!N18,OFFSET('＠グループ、表示名'!$H$4,MATCH('＠MFP (LSI name)'!N18,'＠グループ、表示名'!$D$4:$D$250,0)-1,0))) | O18: =IF('＠MFP (LSI name)'!O18="","",IF(COUNTIF('＠MFP (LSI name)'!O18,"Serial*")+COUNTIF('＠MFP (LSI name)'!O18,"Analog*")>0,'＠MFP (LSI name)'!O18,OFFSET('＠グループ、表示名'!$H$4,MATCH('＠MFP (LSI name)'!O18,'＠グループ、表示名'!$D$4:$D$250,0)-1,0))) | P18: =IF('＠MFP (LSI name)'!P18="","",IF(COUNTIF('＠MFP (LSI name)'!P18,"Serial*")+COUNTIF('＠MFP (LSI name)'!P18,"Analog*")>0,'＠MFP (LSI name)'!P18,OFFSET('＠グループ、表示名'!$H$4,MATCH('＠MFP (LSI name)'!P18,'＠グループ、表示名'!$D$4:$D$250,0)-1,0))) | Q18: =IF('＠MFP (LSI name)'!Q18="","",IF(COUNTIF('＠MFP (LSI name)'!Q18,"Serial*")+COUNTIF('＠MFP (LSI name)'!Q18,"Analog*")>0,'＠MFP (LSI name)'!Q18,OFFSET('＠グループ、表示名'!$H$4,MATCH('＠MFP (LSI name)'!Q18,'＠グループ、表示名'!$D$4:$D$250,0)-1,0))) | R18: =IF('＠MFP (LSI name)'!R18="","",IF(COUNTIF('＠MFP (LSI name)'!R18,"Serial*")+COUNTIF('＠MFP (LSI name)'!R18,"Analog*")>0,'＠MFP (LSI name)'!R18,OFFSET('＠グループ、表示名'!$H$4,MATCH('＠MFP (LSI name)'!R18,'＠グループ、表示名'!$D$4:$D$250,0)-1,0))) | ... AK18: =IF('＠MFP (LSI name)'!AK18="","",IF(COUNTIF('＠MFP (LSI name)'!AK18,"Serial*")+COUNTIF('＠MFP (LSI name)'!AK18,"Analog*")>0,'＠MFP (LSI name)'!AK18,OFFSET('＠グループ、表示名'!$H$4,MATCH('＠MFP (LSI name)'!AK18,'＠グループ、表示名'!$D$4:$D$250,0)-1,0))) | AL18: =IF(COUNTIF(J18,"P*")>0,"IO"&LEFT(J18,2)&"MD["&RIGHT(J18,1)*4+3&"]","") -> IOPEMD[3] | AM18: =IF(COUNTIF(J18,"P*")>0,"IO"&LEFT(J18,2)&"MD["&RIGHT(J18,1)*4+2&"]","") -> IOPEMD[2] | AN18: =IF(COUNTIF(J18,"P*")>0,"IO"&LEFT(J18,2)&"MD["&RIGHT(J18,1)*4+1&"]","") -> IOPEMD[1] | AO18: =IF(COUNTIF(J18,"P*")>0,"IO"&LEFT(J18,2)&"MD["&RIGHT(J18,1)*4&"]","") -> IOPEMD[0]
A19: 18 | B19: 18 | C19: 15 | D19: 12 | E19: 10 | F19: 18 | G19: 15 | H19: 12 | I19: GPD[7] | J19: PD.7 | K19: =IF('＠MFP (LSI name)'!K19="","",IF(COUNTIF('＠MFP (LSI name)'!K19,"Serial*")+COUNTIF('＠MFP (LSI name)'!K19,"Analog*")>0,'＠MFP (LSI name)'!K19,OFFSET('＠グループ、表示名'!$H$4,MATCH('＠MFP (LSI name)'!K19,'＠グループ、表示名'!$D$4:$D$250,0)-1,0))) -> GPWM7_GPWM70 | L19: =IF('＠MFP (LSI name)'!L19="","",IF(COUNTIF('＠MFP (LSI name)'!L19,"Serial*")+COUNTIF('＠MFP (LSI name)'!L19,"Analog*")>0,'＠MFP (LSI name)'!L19,OFFSET('＠グループ、表示名'!$H$4,MATCH('＠MFP (LSI name)'!L19,'＠グループ、表示名'!$D$4:$D$250,0)-1,0))) -> IRQ31 | M19: =IF('＠MFP (LSI name)'!M19="","",IF(COUNTIF('＠MFP (LSI name)'!M19,"Serial*")+COUNTIF('＠MFP (LSI name)'!M19,"Analog*")>0,'＠MFP (LSI name)'!M19,OFFSET('＠グループ、表示名'!$H$4,MATCH('＠MFP (LSI name)'!M19,'＠グループ、表示名'!$D$4:$D$250,0)-1,0))) -> IRQ35 | N19: =IF('＠MFP (LSI name)'!N19="","",IF(COUNTIF('＠MFP (LSI name)'!N19,"Serial*")+COUNTIF('＠MFP (LSI name)'!N19,"Analog*")>0,'＠MFP (LSI name)'!N19,OFFSET('＠グループ、表示名'!$H$4,MATCH('＠MFP (LSI name)'!N19,'＠グループ、表示名'!$D$4:$D$250,0)-1,0))) -> TM14A | O19: =IF('＠MFP (LSI name)'!O19="","",IF(COUNTIF('＠MFP (LSI name)'!O19,"Serial*")+COUNTIF('＠MFP (LSI name)'!O19,"Analog*")>0,'＠MFP (LSI name)'!O19,OFFSET('＠グループ、表示名'!$H$4,MATCH('＠MFP (LSI name)'!O19,'＠グループ、表示名'!$D$4:$D$250,0)-1,0))) -> SIF3_SBCS3 | P19: =IF('＠MFP (LSI name)'!P19="","",IF(COUNTIF('＠MFP (LSI name)'!P19,"Serial*")+COUNTIF('＠MFP (LSI name)'!P19,"Analog*")>0,'＠MFP (LSI name)'!P19,OFFSET('＠グループ、表示名'!$H$4,MATCH('＠MFP (LSI name)'!P19,'＠グループ、表示名'!$D$4:$D$250,0)-1,0))) | Q19: =IF('＠MFP (LSI name)'!Q19="","",IF(COUNTIF('＠MFP (LSI name)'!Q19,"Serial*")+COUNTIF('＠MFP (LSI name)'!Q19,"Analog*")>0,'＠MFP (LSI name)'!Q19,OFFSET('＠グループ、表示名'!$H$4,MATCH('＠MFP (LSI name)'!Q19,'＠グループ、表示名'!$D$4:$D$250,0)-1,0))) | R19: =IF('＠MFP (LSI name)'!R19="","",IF(COUNTIF('＠MFP (LSI name)'!R19,"Serial*")+COUNTIF('＠MFP (LSI name)'!R19,"Analog*")>0,'＠MFP (LSI name)'!R19,OFFSET('＠グループ、表示名'!$H$4,MATCH('＠MFP (LSI name)'!R19,'＠グループ、表示名'!$D$4:$D$250,0)-1,0))) | ... AK19: =IF('＠MFP (LSI name)'!AK19="","",IF(COUNTIF('＠MFP (LSI name)'!AK19,"Serial*")+COUNTIF('＠MFP (LSI name)'!AK19,"Analog*")>0,'＠MFP (LSI name)'!AK19,OFFSET('＠グループ、表示名'!$H$4,MATCH('＠MFP (LSI name)'!AK19,'＠グループ、表示名'!$D$4:$D$250,0)-1,0))) | AL19: =IF(COUNTIF(J19,"P*")>0,"IO"&LEFT(J19,2)&"MD["&RIGHT(J19,1)*4+3&"]","") -> IOPDMD[31] | AM19: =IF(COUNTIF(J19,"P*")>0,"IO"&LEFT(J19,2)&"MD["&RIGHT(J19,1)*4+2&"]","") -> IOPDMD[30] | AN19: =IF(COUNTIF(J19,"P*")>0,"IO"&LEFT(J19,2)&"MD["&RIGHT(J19,1)*4+1&"]","") -> IOPDMD[29] | AO19: =IF(COUNTIF(J19,"P*")>0,"IO"&LEFT(J19,2)&"MD["&RIGHT(J19,1)*4&"]","") -> IOPDMD[28]
A20: 19 | B20: 19 | C20: 16 | D20: 13 | F20: 19 | G20: 16 | H20: 13 | I20: GPD[6] | J20: PD.6 | K20: =IF('＠MFP (LSI name)'!K20="","",IF(COUNTIF('＠MFP (LSI name)'!K20,"Serial*")+COUNTIF('＠MFP (LSI name)'!K20,"Analog*")>0,'＠MFP (LSI name)'!K20,OFFSET('＠グループ、表示名'!$H$4,MATCH('＠MFP (LSI name)'!K20,'＠グループ、表示名'!$D$4:$D$250,0)-1,0))) -> GPWM7_GPWM71 | L20: =IF('＠MFP (LSI name)'!L20="","",IF(COUNTIF('＠MFP (LSI name)'!L20,"Serial*")+COUNTIF('＠MFP (LSI name)'!L20,"Analog*")>0,'＠MFP (LSI name)'!L20,OFFSET('＠グループ、表示名'!$H$4,MATCH('＠MFP (LSI name)'!L20,'＠グループ、表示名'!$D$4:$D$250,0)-1,0))) -> IRQ05 | M20: =IF('＠MFP (LSI name)'!M20="","",IF(COUNTIF('＠MFP (LSI name)'!M20,"Serial*")+COUNTIF('＠MFP (LSI name)'!M20,"Analog*")>0,'＠MFP (LSI name)'!M20,OFFSET('＠グループ、表示名'!$H$4,MATCH('＠MFP (LSI name)'!M20,'＠グループ、表示名'!$D$4:$D$250,0)-1,0))) -> TM01A | N20: =IF('＠MFP (LSI name)'!N20="","",IF(COUNTIF('＠MFP (LSI name)'!N20,"Serial*")+COUNTIF('＠MFP (LSI name)'!N20,"Analog*")>0,'＠MFP (LSI name)'!N20,OFFSET('＠グループ、表示名'!$H$4,MATCH('＠MFP (LSI name)'!N20,'＠グループ、表示名'!$D$4:$D$250,0)-1,0))) -> TM15A | O20: =IF('＠MFP (LSI name)'!O20="","",IF(COUNTIF('＠MFP (LSI name)'!O20,"Serial*")+COUNTIF('＠MFP (LSI name)'!O20,"Analog*")>0,'＠MFP (LSI name)'!O20,OFFSET('＠グループ、表示名'!$H$4,MATCH('＠MFP (LSI name)'!O20,'＠グループ、表示名'!$D$4:$D$250,0)-1,0))) -> SIF1_SBCS1 | P20: =IF('＠MFP (LSI name)'!P20="","",IF(COUNTIF('＠MFP (LSI name)'!P20,"Serial*")+COUNTIF('＠MFP (LSI name)'!P20,"Analog*")>0,'＠MFP (LSI name)'!P20,OFFSET('＠グループ、表示名'!$H$4,MATCH('＠MFP (LSI name)'!P20,'＠グループ、表示名'!$D$4:$D$250,0)-1,0))) -> SIF3_SBCS3 | Q20: =IF('＠MFP (LSI name)'!Q20="","",IF(COUNTIF('＠MFP (LSI name)'!Q20,"Serial*")+COUNTIF('＠MFP (LSI name)'!Q20,"Analog*")>0,'＠MFP (LSI name)'!Q20,OFFSET('＠グループ、表示名'!$H$4,MATCH('＠MFP (LSI name)'!Q20,'＠グループ、表示名'!$D$4:$D$250,0)-1,0))) -> ADST0 | R20: =IF('＠MFP (LSI name)'!R20="","",IF(COUNTIF('＠MFP (LSI name)'!R20,"Serial*")+COUNTIF('＠MFP (LSI name)'!R20,"Analog*")>0,'＠MFP (LSI name)'!R20,OFFSET('＠グループ、表示名'!$H$4,MATCH('＠MFP (LSI name)'!R20,'＠グループ、表示名'!$D$4:$D$250,0)-1,0))) | ... AK20: =IF('＠MFP (LSI name)'!AK20="","",IF(COUNTIF('＠MFP (LSI name)'!AK20,"Serial*")+COUNTIF('＠MFP (LSI name)'!AK20,"Analog*")>0,'＠MFP (LSI name)'!AK20,OFFSET('＠グループ、表示名'!$H$4,MATCH('＠MFP (LSI name)'!AK20,'＠グループ、表示名'!$D$4:$D$250,0)-1,0))) | AL20: =IF(COUNTIF(J20,"P*")>0,"IO"&LEFT(J20,2)&"MD["&RIGHT(J20,1)*4+3&"]","") -> IOPDMD[27] | AM20: =IF(COUNTIF(J20,"P*")>0,"IO"&LEFT(J20,2)&"MD["&RIGHT(J20,1)*4+2&"]","") -> IOPDMD[26] | AN20: =IF(COUNTIF(J20,"P*")>0,"IO"&LEFT(J20,2)&"MD["&RIGHT(J20,1)*4+1&"]","") -> IOPDMD[25] | AO20: =IF(COUNTIF(J20,"P*")>0,"IO"&LEFT(J20,2)&"MD["&RIGHT(J20,1)*4&"]","") -> IOPDMD[24]
A21: 20 | B21: 20 | C21: 17 | D21: 14 | E21: 11 | I21: GPD[5] | J21: PD.5 | K21: =IF('＠MFP (LSI name)'!K21="","",IF(COUNTIF('＠MFP (LSI name)'!K21,"Serial*")+COUNTIF('＠MFP (LSI name)'!K21,"Analog*")>0,'＠MFP (LSI name)'!K21,OFFSET('＠グループ、表示名'!$H$4,MATCH('＠MFP (LSI name)'!K21,'＠グループ、表示名'!$D$4:$D$250,0)-1,0))) -> DBG_SWDCLK | L21: =IF('＠MFP (LSI name)'!L21="","",IF(COUNTIF('＠MFP (LSI name)'!L21,"Serial*")+COUNTIF('＠MFP (LSI name)'!L21,"Analog*")>0,'＠MFP (LSI name)'!L21,OFFSET('＠グループ、表示名'!$H$4,MATCH('＠MFP (LSI name)'!L21,'＠グループ、表示名'!$D$4:$D$250,0)-1,0))) -> IRQ03 | M21: =IF('＠MFP (LSI name)'!M21="","",IF(COUNTIF('＠MFP (LSI name)'!M21,"Serial*")+COUNTIF('＠MFP (LSI name)'!M21,"Analog*")>0,'＠MFP (LSI name)'!M21,OFFSET('＠グループ、表示名'!$H$4,MATCH('＠MFP (LSI name)'!M21,'＠グループ、表示名'!$D$4:$D$250,0)-1,0))) -> IRQ30 | N21: =IF('＠MFP (LSI name)'!N21="","",IF(COUNTIF('＠MFP (LSI name)'!N21,"Serial*")+COUNTIF('＠MFP (LSI name)'!N21,"Analog*")>0,'＠MFP (LSI name)'!N21,OFFSET('＠グループ、表示名'!$H$4,MATCH('＠MFP (LSI name)'!N21,'＠グループ、表示名'!$D$4:$D$250,0)-1,0))) -> IRQ36 | O21: =IF('＠MFP (LSI name)'!O21="","",IF(COUNTIF('＠MFP (LSI name)'!O21,"Serial*")+COUNTIF('＠MFP (LSI name)'!O21,"Analog*")>0,'＠MFP (LSI name)'!O21,OFFSET('＠グループ、表示名'!$H$4,MATCH('＠MFP (LSI name)'!O21,'＠グループ、表示名'!$D$4:$D$250,0)-1,0))) -> SIF1_SBI1 | P21: =IF('＠MFP (LSI name)'!P21="","",IF(COUNTIF('＠MFP (LSI name)'!P21,"Serial*")+COUNTIF('＠MFP (LSI name)'!P21,"Analog*")>0,'＠MFP (LSI name)'!P21,OFFSET('＠グループ、表示名'!$H$4,MATCH('＠MFP (LSI name)'!P21,'＠グループ、表示名'!$D$4:$D$250,0)-1,0))) -> SIF1_SBO1 | Q21: =IF('＠MFP (LSI name)'!Q21="","",IF(COUNTIF('＠MFP (LSI name)'!Q21,"Serial*")+COUNTIF('＠MFP (LSI name)'!Q21,"Analog*")>0,'＠MFP (LSI name)'!Q21,OFFSET('＠グループ、表示名'!$H$4,MATCH('＠MFP (LSI name)'!Q21,'＠グループ、表示名'!$D$4:$D$250,0)-1,0))) -> SIF1_SBT1 | R21: =IF('＠MFP (LSI name)'!R21="","",IF(COUNTIF('＠MFP (LSI name)'!R21,"Serial*")+COUNTIF('＠MFP (LSI name)'!R21,"Analog*")>0,'＠MFP (LSI name)'!R21,OFFSET('＠グループ、表示名'!$H$4,MATCH('＠MFP (LSI name)'!R21,'＠グループ、表示名'!$D$4:$D$250,0)-1,0))) | ... AK21: =IF('＠MFP (LSI name)'!AK21="","",IF(COUNTIF('＠MFP (LSI name)'!AK21,"Serial*")+COUNTIF('＠MFP (LSI name)'!AK21,"Analog*")>0,'＠MFP (LSI name)'!AK21,OFFSET('＠グループ、表示名'!$H$4,MATCH('＠MFP (LSI name)'!AK21,'＠グループ、表示名'!$D$4:$D$250,0)-1,0))) | AL21: =IF(COUNTIF(J21,"P*")>0,"IO"&LEFT(J21,2)&"MD["&RIGHT(J21,1)*4+3&"]","") -> IOPDMD[23] | AM21: =IF(COUNTIF(J21,"P*")>0,"IO"&LEFT(J21,2)&"MD["&RIGHT(J21,1)*4+2&"]","") -> IOPDMD[22] | AN21: =IF(COUNTIF(J21,"P*")>0,"IO"&LEFT(J21,2)&"MD["&RIGHT(J21,1)*4+1&"]","") -> IOPDMD[21] | AO21: =IF(COUNTIF(J21,"P*")>0,"IO"&LEFT(J21,2)&"MD["&RIGHT(J21,1)*4&"]","") -> IOPDMD[20]
A22: 20' | F22: 20 | G22: 17 | H22: 14 | I22: GPD[5] | J22: PD.5 | K22: =IF('＠MFP (LSI name)'!K22="","",IF(COUNTIF('＠MFP (LSI name)'!K22,"Serial*")+COUNTIF('＠MFP (LSI name)'!K22,"Analog*")>0,'＠MFP (LSI name)'!K22,OFFSET('＠グループ、表示名'!$H$4,MATCH('＠MFP (LSI name)'!K22,'＠グループ、表示名'!$D$4:$D$250,0)-1,0))) | L22: =IF('＠MFP (LSI name)'!L22="","",IF(COUNTIF('＠MFP (LSI name)'!L22,"Serial*")+COUNTIF('＠MFP (LSI name)'!L22,"Analog*")>0,'＠MFP (LSI name)'!L22,OFFSET('＠グループ、表示名'!$H$4,MATCH('＠MFP (LSI name)'!L22,'＠グループ、表示名'!$D$4:$D$250,0)-1,0))) -> IRQ03 | M22: =IF('＠MFP (LSI name)'!M22="","",IF(COUNTIF('＠MFP (LSI name)'!M22,"Serial*")+COUNTIF('＠MFP (LSI name)'!M22,"Analog*")>0,'＠MFP (LSI name)'!M22,OFFSET('＠グループ、表示名'!$H$4,MATCH('＠MFP (LSI name)'!M22,'＠グループ、表示名'!$D$4:$D$250,0)-1,0))) -> IRQ30 | N22: =IF('＠MFP (LSI name)'!N22="","",IF(COUNTIF('＠MFP (LSI name)'!N22,"Serial*")+COUNTIF('＠MFP (LSI name)'!N22,"Analog*")>0,'＠MFP (LSI name)'!N22,OFFSET('＠グループ、表示名'!$H$4,MATCH('＠MFP (LSI name)'!N22,'＠グループ、表示名'!$D$4:$D$250,0)-1,0))) -> IRQ36 | O22: =IF('＠MFP (LSI name)'!O22="","",IF(COUNTIF('＠MFP (LSI name)'!O22,"Serial*")+COUNTIF('＠MFP (LSI name)'!O22,"Analog*")>0,'＠MFP (LSI name)'!O22,OFFSET('＠グループ、表示名'!$H$4,MATCH('＠MFP (LSI name)'!O22,'＠グループ、表示名'!$D$4:$D$250,0)-1,0))) -> SIF1_SBI1 | P22: =IF('＠MFP (LSI name)'!P22="","",IF(COUNTIF('＠MFP (LSI name)'!P22,"Serial*")+COUNTIF('＠MFP (LSI name)'!P22,"Analog*")>0,'＠MFP (LSI name)'!P22,OFFSET('＠グループ、表示名'!$H$4,MATCH('＠MFP (LSI name)'!P22,'＠グループ、表示名'!$D$4:$D$250,0)-1,0))) -> SIF1_SBO1 | Q22: =IF('＠MFP (LSI name)'!Q22="","",IF(COUNTIF('＠MFP (LSI name)'!Q22,"Serial*")+COUNTIF('＠MFP (LSI name)'!Q22,"Analog*")>0,'＠MFP (LSI name)'!Q22,OFFSET('＠グループ、表示名'!$H$4,MATCH('＠MFP (LSI name)'!Q22,'＠グループ、表示名'!$D$4:$D$250,0)-1,0))) -> SIF1_SBT1 | R22: =IF('＠MFP (LSI name)'!R22="","",IF(COUNTIF('＠MFP (LSI name)'!R22,"Serial*")+COUNTIF('＠MFP (LSI name)'!R22,"Analog*")>0,'＠MFP (LSI name)'!R22,OFFSET('＠グループ、表示名'!$H$4,MATCH('＠MFP (LSI name)'!R22,'＠グループ、表示名'!$D$4:$D$250,0)-1,0))) | ... AK22: =IF('＠MFP (LSI name)'!AK22="","",IF(COUNTIF('＠MFP (LSI name)'!AK22,"Serial*")+COUNTIF('＠MFP (LSI name)'!AK22,"Analog*")>0,'＠MFP (LSI name)'!AK22,OFFSET('＠グループ、表示名'!$H$4,MATCH('＠MFP (LSI name)'!AK22,'＠グループ、表示名'!$D$4:$D$250,0)-1,0))) | AL22: =IF(COUNTIF(J22,"P*")>0,"IO"&LEFT(J22,2)&"MD["&RIGHT(J22,1)*4+3&"]","") -> IOPDMD[23] | AM22: =IF(COUNTIF(J22,"P*")>0,"IO"&LEFT(J22,2)&"MD["&RIGHT(J22,1)*4+2&"]","") -> IOPDMD[22] | AN22: =IF(COUNTIF(J22,"P*")>0,"IO"&LEFT(J22,2)&"MD["&RIGHT(J22,1)*4+1&"]","") -> IOPDMD[21] | AO22: =IF(COUNTIF(J22,"P*")>0,"IO"&LEFT(J22,2)&"MD["&RIGHT(J22,1)*4&"]","") -> IOPDMD[20]
