Workbook

Sheet MFP(sample)
A1: LQFP64(7*7) | B1: ULQFP64(7*7) | C1: LQFP128(14*14) | D1: ULQFP128(14*14) | E1: PAD Name | F1: Pin Name | G1: MFP1 | H1: MFP2 | I1: MFP3 | J1: MFP4 | K1: MFP5 | L1: MFP6 | M1: MFP7 | N1: MFP8(LQFP64) | O1: MFP8(LQFP128) | P1: MFP8(ULQFP128) | Q1: MFP31 | S1: MFP1 | T1: ADC | U1: ACMP0 | V1: ACMP1 | X1: Bit3 | Y1: Bit2 | Z1: Bit1 | AA1: Bit0
C2: 1 | D2: 1 | E2: GPB[5] | F2: PB.5 | G2: Analog0 | H2: EBI_ADR0 | I2: SD0_DAT3 | J2: EMAC_RMII_REFCLK | P2: LCD_SEG33 | S2: Analog0 | T2: EADC0_CH5 | V2: ACMP1_N | X2: MFPA[3] | Y2: MFPA[2] | Z2: MFPA[1] | AA2: MFPA[0]
A3: 1 | B3: 1 | C3: 2 | D3: 2 | E3: GPB[4] | F3: PB.4 | G3: Analog1 | H3: EBI_ADR1 | I3: SD0_DAT2 | J3: EMAC_RMII_RXD0 | P3: LCD_SEG32 | S3: Analog1 | T3: EADC0_CH4 | V3: ACMP1_P1 | Z3: ALT1[1] | AA3: MFP1[1]
A4: 2 | B4: 2 | C4: 3 | D4: 3 | E4: GPB[3] | F4: PB.3 | G4: Analog2 | H4: EBI_ADR2 | I4: SD0_DAT1 | J4: EMAC_RMII_RXD1 | K4: SPI0_SS[ULQFP64(7*7)] | P4: LCD_SEG31 | S4: Analog2 | T4: EADC0_CH3 | U4: ACMP0_N | AA4: ALT[5]
A5: 3 | B5: 3 | C5: 4 | D5: 4 | E5: GPB[2] | F5: PB.2 | G5: Analog3 | H5: EBI_ADR3 | I5: SD0_DAT0 | J5: EMAC_RMII_CRSDV | P5: LCD_SEG30 | S5: Analog3 | T5: EADC0_CH2 | U5: ACMP0_P1
A6: 4 | B6: 4 | C6: 5 | D6: 5 | E6: GPC[12] | F6: PC.12 | H6: EBI_ADR4 | I6: UART0_TXD | J6: I2C0_SCL | P6: LCD_SEG29
A7: 5 | B7: 5 | C7: 6 | D7: 6 | E7: GPC[11] | F7: PC.11 | H7: EBI_ADR5 | I7: UART0_RXD | J7: I2C0_SDA | P7: LCD_SEG28
C8: 7 | D8: 7 | E8: GPC[10] | F8: PC.10 | H8: EBI_ADR6 | O8: LCD_SEG23 | P8: LCD_SEG27
C9: 8 | D9: 8 | E9: GPC[9] | F9: PC.9 | H9: EBI_ADR7 | O9: LCD_SEG22 | P9: LCD_SEG26
C10: 9 | D10: 9 | E10: GPB[1] | F10: PB.1 | G10: Analog4 | H10: EBI_ADR8 | I10: SD0_CLK | J10: EMAC_RMII_RXERR | O10: LCD_SEG21 | P10: LCD_SEG25 | S10: Analog4 | T10: EADC0_CH1
C11: 10 | D11: 10 | E11: GPB[0] | F11: PB.0 | G11: Analog5 | H11: EBI_ADR9 | I11: SD0_CMD | O11: LCD_SEG20 | P11: LCD_SEG24 | S11: Analog5 | T11: EADC0_CH0
C12: 11 | D12: 11 | E12: VSSPST | F12: VSS
C13: 12 | D13: 12 | E13: VDDPST | F13: VDD
C14: 13 | D14: 13 | E14: GPA[11] | F14: PA.11 | G14: Analog6 | H14: EBI_nRD | I14: SC2_PWR | J14: SPI2_SS | S14: Analog6 | U14: ACMP0_P0
C15: 14 | D15: 14 | E15: GPA[10] | F15: PA.10 | G15: Analog7 | H15: EBI_nWR | I15: SC2_RST | J15: SPI2_CLK | S15: Analog7 | V15: ACMP1_P0
C16: 15 | D16: 15 | E16: GPA[9] | F16: PA.9 | H16: EBI_MCLK | I16: SC2_DAT | J16: SPI2_MISO
A17: 6 | B17: 6 | C17: 16 | D17: 16 | E17: GPA[8] | F17: PA.8 | H17: EBI_ALE | I17: SC2_CLK | J17: SPI2_MOSI | N17: LCD_SEG19 | O17: LCD_SEG19 | P17: LCD_SEG23
A18: 7 | B18: 7 | C18: 17 | D18: 17 | E18: GPC[13] | F18: PC.13 | H18: EBI_ADR10 | I18: SC2_nCD | J18: SPI2_I2SMCLK | K18: I2C0_CL | N18: LCD_SEG18 | O18: LCD_SEG18 | P18: LCD_SEG22
A19: 8 | B19: 8 | C19: 18 | D19: 18 | E19: GPD[12] | F19: PD.12 | H19: EBI_nCS0 | K19: I2C0_DA | N19: LCD_SEG17 | O19: LCD_SEG17 | P19: LCD_SEG21
A20: 9 | B20: 9 | C20: 19 | D20: 19 | E20: GPD[11] | F20: PD.11 | H20: EBI_nCS1 | I20: BRAKE00 | J20: CAN0_TXD | N20: LCD_SEG16 | O20: LCD_SEG16 | P20: LCD_SEG20
A21: 10 | B21: 10 | C21: 20 | D21: 20 | E21: GPD[10] | F21: PD.10 | H21: EBI_nCS2 | I21: BRAKE01 | J21: CAN0_RXD | N21: LCD_SEG15 | O21: LCD_SEG15 | P21: LCD_SEG19
A22: 11 | B22: 11 | C22: 21 | D22: 21 | E22: VSSPST | F22: VSS | L22: SPI0_SCLK_O | N22: LCD_SEG14 | O22: LCD_SEG14 | P22: LCD_SEG18
A23: 12 | B23: 12 | C23: 22 | D23: 22 | E23: VDDPST | F23: VDD | N23: LCD_SEG13 | O23: LCD_SEG13 | P23: LCD_SEG17
A24: 13 | B24: 13 | C24: 23 | D24: 23 | E24: GPG[0] | F24: PG.0 | H24: EBI_ADR8 | J24: I2C0_SCL | N24: LCD_SEG12 | O24: LCD_SEG12 | P24: LCD_SEG16
A25: 14 | B25: 14 | C25: 24 | D25: 24 | E25: GPG[1] | F25: PG.1 | H25: EBI_ADR9 | I25: SPI2_I2SMCLK | J25: I2C0_SDA | N25: LCD_SEG11 | O25: LCD_SEG11 | P25: LCD_SEG15
A26: 15 | B26: 15 | C26: 25 | D26: 25 | E26: GPG[2] | F26: PG.2 | H26: EBI_ADR11 | I26: SPI2_SS | J26: I2C0_SMBAL | N26: LCD_SEG10 | O26: LCD_SEG10 | P26: LCD_SEG14
A27: 16 | B27: 16 | C27: 26 | D27: 26 | E27: GPG[3] | F27: PG.3 | H27: EBI_ADR12 | I27: SPI2_CLK | J27: I2C0_SMBSUS | N27: LCD_SEG9 | O27: LCD_SEG9 | P27: LCD_SEG13
C28: 27 | D28: 27 | E28: GPG[4] | F28: PG.4 | H28: EBI_ADR13 | I28: SPI2_MISO
C29: 28 | D29: 28 | E29: GPF[11] | F29: PF.11 | H29: EBI_ADR14 | I29: SPI2_MOSI
C30: 29 | D30: 29 | E30: GPF[10] | F30: PF.10 | H30: EBI_ADR15 | I30: SC0_nCD | J30: I2S0_BCLK
C31: 30 | D31: 30 | E31: GPF[9] | F31: PF.9 | H31: EBI_ADR16 | I31: SC0_PWR | J31: I2S0_MCLK
C32: 31 | D32: 31 | E32: GPF[8] | F32: PF.8 | H32: EBI_ADR17 | I32: SC0_RST | J32: I2S0_DI
C33: 32 | D33: 32 | E33: GPF[7] | F33: PF.7 | H33: EBI_ADR18 | I33: SC0_DAT | J33: I2S0_DO
C34: 33 | D34: 33 | E34: GPF[6] | F34: PF.6 | H34: EBI_ADR19 | I34: SC0_CLK | J34: I2S0_LRCK
C35: 34 | D35: 34 | E35: VBAT | F35: VDD
C36: 35 | D36: 35 | E36: GPF[5] | F36: PF.5 | H36: UART2_RXD | J36: UART2_nCTS
C37: 36 | D37: 36 | E37: GPF[4] | F37: PF.4 | H37: UART2_TXD | J37: UART2_nRTS
C38: 37 | D38: 37 | E38: GPH[0] | F38: PH.0 | H38: EBI_ADR7 | J38: UART5_TXD
C39: 38 | D39: 38 | E39: GPH[1] | F39: PH.1 | H39: EBI_ADR6 | J39: UART5_RXD
C40: 39 | D40: 39 | E40: GPH[2] | F40: PH.2 | H40: EBI_ADR5 | J40: UART5_nRTS
...

Sheet MFP
A1: PAD# | B1: TQFP80 (12*12) | C1: TQFP64 (10*10) | D1: TQFP48 (7*7) | E1: TQFP32 (7*7) | F1: PAD NAME | G1: PIN NAME | H1: MFP1 | I1: MFP2 | J1: MFP3 | K1: MFP4 | L1: MFP5 | M1: MFP6 | N1: MFP7 | P1: MFP1 | Q1: AD | R1: CMP | T1: Bit3 | U1: Bit2 | V1: Bit1 | W1: Bit0
A2: 1 | B2: 1 | F2: GP0[0] | G2: P0.0 | H2: GPWM6_GPWM60 | I2: GPWM6_GPWMH60 | J2: TM12A | T2: IOP0MD[3] | U2: IOP0MD[2] | V2: IOP0MD[1] | W2: IOP0MD[0]
A3: 2 | B3: 2 | F3: GP0[1] | G3: P0.1 | H3: GPWM6_GPWM61 | I3: GPWM6_GPWMH61 | J3: TM12B | T3: IOP0MD[7] | U3: IOP0MD[6] | V3: IOP0MD[5] | W3: IOP0MD[4]
A4: 3 | B4: 3 | C4: 1 | D4: 1 | E4: 1 | F4: GP0[2] | G4: P0.2 | H4: GPWM3_GPWM30 | I4: GPWM3_GPWMH30 | J4: TM03A | T4: IOP0MD[11] | U4: IOP0MD[10] | V4: IOP0MD[9] | W4: IOP0MD[8]
A5: 4 | B5: 4 | C5: 2 | D5: 2 | E5: 2 | F5: GP0[3] | G5: P0.3 | H5: GPWM3_GPWM31 | I5: GPWM3_GPWMH31 | J5: TM03B | T5: IOP0MD[15] | U5: IOP0MD[14] | V5: IOP0MD[13] | W5: IOP0MD[12]
A6: 5 | B6: 5 | C6: 3 | F6: GP0[4] | G6: P0.4 | H6: GPWM4_GPWM40 | I6: GPWM4_GPWMH40 | J6: TM04A | T6: IOP0MD[19] | U6: IOP0MD[18] | V6: IOP0MD[17] | W6: IOP0MD[16]
A7: 6 | B7: 6 | C7: 4 | F7: GP0[5] | G7: P0.5 | H7: GPWM4_GPWM41 | I7: GPWM4_GPWMH41 | J7: TM04B | T7: IOP0MD[23] | U7: IOP0MD[22] | V7: IOP0MD[21] | W7: IOP0MD[20]
A8: 7 | B8: 7 | C8: 5 | D8: 3 | E8: 3 | F8: GP0[6] | G8: P0.6 | H8: GPWM5_GPWM50 | I8: GPWM5_GPWMH50 | J8: TM05A | T8: IOP0MD[27] | U8: IOP0MD[26] | V8: IOP0MD[25] | W8: IOP0MD[24]
A9: 8 | B9: 8 | C9: 6 | D9: 4 | E9: 4 | F9: GP0[7] | G9: P0.7 | H9: GPWM5_GPWM51 | I9: GPWM5_GPWMH51 | J9: TM05B | T9: IOP0MD[31] | U9: IOP0MD[30] | V9: IOP0MD[29] | W9: IOP0MD[28]
A10: 9 | B10: 9 | C10: 7 | D10: 5 | E10: 5 | F10: GP1[0] | G10: P1.0 | H10: DAC_DAOUT0 | I10: FPSB08 | T10: IOP1MD[3] | U10: IOP1MD[2] | V10: IOP1MD[1] | W10: IOP1MD[0]
A11: 10 | B11: 10 | C11: 8 | D11: 6 | F11: GP1[1] | G11: P1.1 | H11: DAC_DAOUT1 | I11: FPSB09 | T11: IOP1MD[7] | U11: IOP1MD[6] | V11: IOP1MD[5] | W11: IOP1MD[4]
A12: 11 | B12: 11 | C12: 9 | D12: 7 | F12: VSSPST | G12: VSS
A13: 12 | B13: 12 | C13: 10 | D13: 8 | F13: VDDPST | G13: VDD33
A14: 13 | B14: 13 | C14: 11 | F14: GP1[2] | G14: P1.2 | H14: TM06A | I14: FPSB10 | T14: IOP1MD[11] | U14: IOP1MD[10] | V14: IOP1MD[9] | W14: IOP1MD[8]
A15: 14 | B15: 14 | C15: 12 | F15: GP1[3] | G15: P1.3 | H15: TM06B | I15: FPSB11 | T15: IOP1MD[15] | U15: IOP1MD[14] | V15: IOP1MD[13] | W15: IOP1MD[12]
A16: 15 | B16: 15 | C16: 13 | D16: 9 | E16: 6 | F16: GP2[0] | G16: P2.0 | H16: Analog1 | P16: Analog1 | Q16: ADIN00 | R16: CMP0_CMP00 | T16: IOP2MD[3] | U16: IOP2MD[2] | V16: IOP2MD[1] | W16: IOP2MD[0]
A17: 16 | B17: 16 | C17: 14 | D17: 10 | E17: 7 | F17: GP2[1] | G17: P2.1 | H17: Analog2 | P17: Analog2 | Q17: ADIN01 | R17: CMP0_CMP01 | T17: IOP2MD[7] | U17: IOP2MD[6] | V17: IOP2MD[5] | W17: IOP2MD[4]
A18: 17 | B18: 17 | C18: 15 | D18: 11 | E18: 8 | F18: GP2[2] | G18: P2.2 | H18: Analog3 | P18: Analog3 | Q18: ADIN02 | R18: CMP0_CMPREF0 | T18: IOP2MD[11] | U18: IOP2MD[10] | V18: IOP2MD[9] | W18: IOP2MD[8]
A19: 18 | B19: 18 | C19: 16 | D19: 12 | F19: GP2[3] | G19: P2.3 | H19: Analog4 | P19: Analog4 | Q19: ADIN03 | R19: CMP1_CMP10 | T19: IOP2MD[15] | U19: IOP2MD[14] | V19: IOP2MD[13] | W19: IOP2MD[12]
A20: 19 | B20: 19 | F20: GP2[4] | G20: P2.4 | H20: Analog5 | P20: Analog5 | Q20: ADIN18 | T20: IOP2MD[19] | U20: IOP2MD[18] | V20: IOP2MD[17] | W20: IOP2MD[16]
A21: 20 | B21: 20 | F21: GP2[5] | G21: P2.5 | H21: Analog6 | P21: Analog6 | Q21: ADIN19 | T21: IOP2MD[23] | U21: IOP2MD[22] | V21: IOP2MD[21] | W21: IOP2MD[20]
A22: 21 | B22: 21 | C22: 17 | D22: 13 | F22: GP2[6] | G22: P2.6 | H22: Analog7 | P22: Analog7 | Q22: ADIN04 | R22: CMP1_CMP11 | T22: IOP2MD[27] | U22: IOP2MD[26] | V22: IOP2MD[25] | W22: IOP2MD[24]
A23: 22 | B23: 22 | C23: 18 | D23: 14 | E23: 9 | F23: GP2[7] | G23: P2.7 | H23: Analog8 | P23: Analog8 | Q23: ADIN05 | R23: CMP1_CMPREF1 | T23: IOP2MD[31] | U23: IOP2MD[30] | V23: IOP2MD[29] | W23: IOP2MD[28]
A24: 23 | B24: 23 | F24: GP3[0] | G24: P3.0 | H24: Analog9 | P24: Analog9 | Q24: ADIN20 | T24: IOP3MD[3] | U24: IOP3MD[2] | V24: IOP3MD[1] | W24: IOP3MD[0]
A25: 24 | B25: 24 | F25: GP3[1] | G25: P3.1 | H25: Analog10 | P25: Analog10 | Q25: ADIN21 | T25: IOP3MD[7] | U25: IOP3MD[6] | V25: IOP3MD[5] | W25: IOP3MD[4]
A26: 25 | B26: 25 | C26: 19 | D26: 15 | E26: 10 | F26: VDDPST | G26: AVDD
A27: 26 | B27: 26 | C27: 20 | D27: 16 | E27: 11 | F27: VSSPST | G27: AVSS
A28: 27 | B28: 27 | C28: 21 | D28: 17 | F28: GP3[2] | G28: P3.2 | H28: Analog11 | P28: Analog11 | Q28: ADIN06 | R28: CMP2_CMP20 | T28: IOP3MD[11] | U28: IOP3MD[10] | V28: IOP3MD[9] | W28: IOP3MD[8]
A29: 28 | B29: 28 | C29: 22 | F29: GP3[3] | G29: P3.3 | H29: Analog12 | P29: Analog12 | Q29: ADIN07 | R29: CMP2_CMP21 | T29: IOP3MD[15] | U29: IOP3MD[14] | V29: IOP3MD[13] | W29: IOP3MD[12]
A30: 29 | B30: 29 | C30: 23 | F30: GP3[4] | G30: P3.4 | H30: Analog13 | P30: Analog13 | Q30: ADIN08 | R30: CMP2_CMPREF2 | T30: IOP3MD[19] | U30: IOP3MD[18] | V30: IOP3MD[17] | W30: IOP3MD[16]
A31: 30 | B31: 30 | C31: 24 | D31: 18 | E31: 12 | F31: GP3[5] | G31: P3.5 | H31: Analog14 | P31: Analog14 | Q31: ADIN09 | R31: CMP3_CMP30 | T31: IOP3MD[23] | U31: IOP3MD[22] | V31: IOP3MD[21] | W31: IOP3MD[20]
A32: 31 | B32: 31 | C32: 25 | F32: VDDPST | G32: VDD33
A33: 32 | B33: 32 | C33: 26 | F33: VSSPST | G33: VSS
A34: 33 | B34: 33 | C34: 27 | D34: 19 | E34: 13 | F34: GP3[6] | G34: P3.6 | H34: Analog15 | P34: Analog15 | Q34: ADIN10 | R34: CMP3_CMP31 | T34: IOP3MD[27] | U34: IOP3MD[26] | V34: IOP3MD[25] | W34: IOP3MD[24]
A35: 34 | B35: 34 | C35: 28 | D35: 20 | E35: 14 | F35: GP3[7] | G35: P3.7 | H35: Analog16 | P35: Analog16 | Q35: ADIN11 | R35: CMP3_CMPREF3 | T35: IOP3MD[31] | U35: IOP3MD[30] | V35: IOP3MD[29] | W35: IOP3MD[28]
A36: 35 | B36: 35 | C36: 29 | D36: 21 | F36: GP4[0] | G36: P4.0 | H36: Analog17 | P36: Analog17 | Q36: ADIN12 | R36: CMP4_CMP40 | T36: IOP4MD[3] | U36: IOP4MD[2] | V36: IOP4MD[1] | W36: IOP4MD[0]
A37: 36 | B37: 36 | C37: 30 | D37: 22 | E37: 15 | F37: GP4[1] | G37: P4.1 | H37: Analog18 | P37: Analog18 | Q37: ADIN13 | R37: CMP4_CMP41 | T37: IOP4MD[7] | U37: IOP4MD[6] | V37: IOP4MD[5] | W37: IOP4MD[4]
A38: 37 | B38: 37 | C38: 31 | D38: 23 | F38: GP4[2] | G38: P4.2 | H38: Analog19 | P38: Analog19 | Q38: ADIN14 | R38: CMP4_CMPREF4 | T38: IOP4MD[11] | U38: IOP4MD[10] | V38: IOP4MD[9] | W38: IOP4MD[8]
A39: 38 | B39: 38 | C39: 32 | D39: 24 | E39: 16 | F39: GP4[3] | G39: P4.3 | H39: Analog20 | P39: Analog20 | Q39: ADIN15 | R39: CMP5_CMP50 | T39: IOP4MD[15] | U39: IOP4MD[14] | V39: IOP4MD[13] | W39: IOP4MD[12]
A40: 39 | B40: 39 | F40: GP4[4] | G40: P4.4 | H40: Analog21 | P40: Analog21 | Q40: ADIN22 | T40: IOP4MD[19] | U40: IOP4MD[18] | V40: IOP4MD[17] | W40: IOP4MD[16]
...

Sheet FPS
A1: Pins | C1: MFP | G1: Value | I1: Note
A2: FPSA | B2: No selection | G2: 0b000000 | H2: ="0x"&BIN2HEX(RIGHT(G2,6),2) -> 0x00
B3: External interrupt | C3: IRQ00 | G3: 0b000001 | H3: ="0x"&BIN2HEX(RIGHT(G3,6),2) -> 0x01
C4: IRQ01 | G4: 0b000010 | H4: ="0x"&BIN2HEX(RIGHT(G4,6),2) -> 0x02
C5: IRQ02 | G5: 0b000011 | H5: ="0x"&BIN2HEX(RIGHT(G5,6),2) -> 0x03
C6: IRQ03 | G6: 0b000100 | H6: ="0x"&BIN2HEX(RIGHT(G6,6),2) -> 0x04
C7: IRQ08 | G7: 0b000101 | H7: ="0x"&BIN2HEX(RIGHT(G7,6),2) -> 0x05
C8: IRQ09 | G8: 0b000110 | H8: ="0x"&BIN2HEX(RIGHT(G8,6),2) -> 0x06
C9: IRQ10 | G9: 0b000111 | H9: ="0x"&BIN2HEX(RIGHT(G9,6),2) -> 0x07
C10: IRQ11 | G10: 0b001000 | H10: ="0x"&BIN2HEX(RIGHT(G10,6),2) -> 0x08
B11: Serial I/F 0 | C11: SPI0_SBO0 | D11: UART0_TX0 | E11: I2C0_SDA0 | G11: 0b001001 | H11: ="0x"&BIN2HEX(RIGHT(G11,6),2) -> 0x09
C12: SPI0_SBI0 | D12: UART0_RX0 | G12: 0b001010 | H12: ="0x"&BIN2HEX(RIGHT(G12,6),2) -> 0x0A
C13: SPI0_SBT0 | E13: I2C0_SCL0 | G13: 0b001011 | H13: ="0x"&BIN2HEX(RIGHT(G13,6),2) -> 0x0B
C14: SPI0_SBCS0 | G14: 0b001100 | H14: ="0x"&BIN2HEX(RIGHT(G14,6),2) -> 0x0C
B15: Serial I/F 2 | C15: SPI2_SBO2 | D15: UART2_TX2 | G15: 0b001101 | H15: ="0x"&BIN2HEX(RIGHT(G15,6),2) -> 0x0D
C16: SPI2_SBI2 | D16: UART2_RX2 | G16: 0b001110 | H16: ="0x"&BIN2HEX(RIGHT(G16,6),2) -> 0x0E
C17: SPI2_SBT2 | G17: 0b001111 | H17: ="0x"&BIN2HEX(RIGHT(G17,6),2) -> 0x0F | I17: This pin cannot be set to FPSA06 or FPSA10.
C18: SPI2_SBCS2 | G18: 0b010000 | H18: ="0x"&BIN2HEX(RIGHT(G18,6),2) -> 0x10
B19: Serial I/F 3 | C19: SPI3_SBO3 | D19: UART3_TX3 | G19: 0b010001 | H19: ="0x"&BIN2HEX(RIGHT(G19,6),2) -> 0x11
C20: SPI3_SBI3 | D20: UART3_RX3 | G20: 0b010010 | H20: ="0x"&BIN2HEX(RIGHT(G20,6),2) -> 0x12
C21: SPI3_SBT3 | G21: 0b010011 | H21: ="0x"&BIN2HEX(RIGHT(G21,6),2) -> 0x13
C22: SPI3_SBCS3 | G22: 0b010100 | H22: ="0x"&BIN2HEX(RIGHT(G22,6),2) -> 0x14
B23: CAN-FD | C23: CAN_CTX | G23: 0b010101 | H23: ="0x"&BIN2HEX(RIGHT(G23,6),2) -> 0x15
C24: CAN_CRX | G24: 0b010110 | H24: ="0x"&BIN2HEX(RIGHT(G24,6),2) -> 0x16
B25: Real-time clock output | C25: RTCOUT | G25: 0b010111 | H25: ="0x"&BIN2HEX(RIGHT(G25,6),2) -> 0x17
B26: GPWM count state output | C26: GWPM0_GPWMBCST0 | G26: 0b011000 | H26: ="0x"&BIN2HEX(RIGHT(G26,6),2) -> 0x18
C27: GWPM1_GPWMBCST1 | G27: 0b011001 | H27: ="0x"&BIN2HEX(RIGHT(G27,6),2) -> 0x19
C28: GWPM2_GPWMBCST2 | G28: 0b011010 | H28: ="0x"&BIN2HEX(RIGHT(G28,6),2) -> 0x1A
C29: GWPM3_GPWMBCST3 | G29: 0b011011 | H29: ="0x"&BIN2HEX(RIGHT(G29,6),2) -> 0x1B
C30: GWPM4_GPWMBCST4 | G30: 0b011100 | H30: ="0x"&BIN2HEX(RIGHT(G30,6),2) -> 0x1C
C31: GWPM5_GPWMBCST5 | G31: 0b011101 | H31: ="0x"&BIN2HEX(RIGHT(G31,6),2) -> 0x1D
C32: GWPM6_GPWMBCST6 | G32: 0b011110 | H32: ="0x"&BIN2HEX(RIGHT(G32,6),2) -> 0x1E
C33: GWPM7_GPWMBCST7 | G33: 0b011111 | H33: ="0x"&BIN2HEX(RIGHT(G33,6),2) -> 0x1F
B34: A/D conversion state output | C34: ADSTATE0 | G34: 0b100000 | H34: ="0x"&BIN2HEX(RIGHT(G34,6),2) -> 0x20
C35: ADSTATE1 | G35: 0b100001 | H35: ="0x"&BIN2HEX(RIGHT(G35,6),2) -> 0x21
C36: ADSTATE2 | G36: 0b100010 | H36: ="0x"&BIN2HEX(RIGHT(G36,6),2) -> 0x22
B37: Comparator output | C37: CMP0_CMPOT00 | G37: 0b100011 | H37: ="0x"&BIN2HEX(RIGHT(G37,6),2) -> 0x23
C38: CMP0_CMPOT01 | G38: 0b100100 | H38: ="0x"&BIN2HEX(RIGHT(G38,6),2) -> 0x24
C39: CMP1_CMPOT10 | G39: 0b100101 | H39: ="0x"&BIN2HEX(RIGHT(G39,6),2) -> 0x25
C40: CMP1_CMPOT11 | G40: 0b100110 | H40: ="0x"&BIN2HEX(RIGHT(G40,6),2) -> 0x26
...

Sheet Package Type
B3: Part No. | C3: TQFP80 (12*12) | E3: TQFP64 (10*10) | G3: TQFP48 (7*7) | I3: TQFP32 (7*7)
B4: KM1M7CF0 | C4: KM1M7CF03N/K | D4: TQFP80 | E4: KM1M7CF04N/K | F4: TQFP64 | G4: KM1M7CF05N/K | H4: TQFP48 | I4: KM1M7CF06N/K | J4: TQFP32
B5: KM1M7CF1 | C5: KM1M7CF13N/K | D5: TQFP80 | E5: KM1M7CF14N/K | F5: TQFP64 | G5: KM1M7CF15N/K | H5: TQFP48 | I5: KM1M7CF16N/K | J5: TQFP32
B10: TQFP80 (12*12) | C10: TQFP64 (10*10) | D10: TQFP48 (7*7) | E10: TQFP32 (7*7)
B11: TQFP80 | C11: TQFP64 | D11: TQFP48 | E11: TQFP32
B13: VDD33 | C13: no specific power domin
B15: AVDD | C15: no specific power domin
B17: VOUT11 | C17: no specific power domin

Sheet Unused IP
B1: MFP | C1: MFP | D1: MFP | E1: MFP | F1: MFP | G1: MFP | H1: MFP | I1: MFP
B2: KM1M7CF03N/K | C2: KM1M7CF04N/K | D2: KM1M7CF05N/K | E2: KM1M7CF06N/K | F2: KM1M7CF13N/K | G2: KM1M7CF14N/K | H2: KM1M7CF15N/K | I2: KM1M7CF16N/K
A3: All | B3: TQFP80 (12*12) | C3: TQFP64 (10*10) | D3: TQFP48 (7*7) | E3: TQFP32 (7*7) | F3: TQFP80 (12*12) | G3: TQFP64 (10*10) | H3: TQFP48 (7*7) | I3: TQFP32 (7*7)
A4: Power Control PWM | E4: GPWM0 | I4: GPWM0
E5: GPWM1 | I5: GPWM1
D6: GPWM4 | E6: GPWM4 | H6: GPWM4 | I6: GPWM4
C7: GPWM6 | D7: GPWM6 | E7: GPWM6 | G7: GPWM6 | H7: GPWM6 | I7: GPWM6
C8: GPWM7 | D8: GPWM7 | E8: GPWM7 | G8: GPWM7 | H8: GPWM7 | I8: GPWM7
A9: Comparator | E9: CMP1 | I9: CMP1
D10: CMP2 | E10: CMP2 | H10: CMP2 | I10: CMP2
E11: CMP4 | I11: CMP4
A12: Secure function | B12: CRYPTO | C12: CRYPTO | D12: CRYPTO | E12: CRYPTO
B13: TRNG | C13: TRNG | D13: TRNG | E13: TRNG

Sheet Special Group Name
A1: Group Name | B1: MFP Function
A2: OSC | B2: OSCI
A3: OSC | B3: OSCO
A4: TM00 | B4: TM00A
A5: TM00 | B5: TM00B
A6: TM01 | B6: TM01A
A7: TM01 | B7: TM01B
A8: TM02 | B8: TM02A
A9: TM02 | B9: TM02B
A10: TM03 | B10: TM03A
A11: TM03 | B11: TM03B
A12: TM04 | B12: TM04A
... A104: CLK | B104: CLKOUT

Sheet Port Control Register
A1: Port Control Register | B1: Address | C1: Default value
A2: GPIO_MD0->IOPnMD | B2: 0x40100080 | C2: 0x00000000
A3: GPIO_MD1->IOPnMD | B3: 0x40100084 | C3: 0x00000000
A4: GPIO_MD2->IOPnMD | B4: 0x40100088 | C4: 0x00000000
A5: GPIO_MD3->IOPnMD | B5: 0x4010008C | C5: 0x00000000
A6: GPIO_MD4->IOPnMD | B6: 0x40100090 | C6: 0x00000000
A7: GPIO_MD5->IOPnMD | B7: 0x40100094 | C7: 0x00000000
A8: GPIO_MD6->IOPnMD | B8: 0x40100098 | C8: 0x00110000
A9: GPIO_MD7->IOPnMD | B9: 0x4010009C | C9: 0x00000000
A10: GPIO_MD8->IOPnMD | B10: 0x401000A0 | C10: 0x00000000

Sheet ＠グループ、表示名
B2: Function | C2: Group | D2: Pins | F2: 1：XXX_AAA | G2: Group | H2: MFP
F3: 2：Special Group Name
B4: Debugger | C4: DBG | D4: SWDCLK | F4: 1 | G4: =C4 -> DBG | H4: =IF(F4=1,C4&"_"&D4,D4) -> DBG_SWDCLK
C5: DBG | D5: SWDD | F5: 1 | G5: =C5 -> DBG | H5: =IF(F5=1,C5&"_"&D5,D5) -> DBG_SWDD
C6: DBG | D6: TRCSWO | F6: 1 | G6: =C6 -> DBG | H6: =IF(F6=1,C6&"_"&D6,D6) -> DBG_TRCSWO
B7: External oscillation | C7: OSC | D7: OSCI | F7: 2 | G7: =C7 -> OSC | H7: =IF(F7=1,C7&"_"&D7,D7) -> OSCI
C8: OSC | D8: OSCO | F8: 2 | G8: =C8 -> OSC | H8: =IF(F8=1,C8&"_"&D8,D8) -> OSCO
B9: 16-bit timer | C9: TM00 | D9: TM00A | F9: 2 | G9: =C9 -> TM00 | H9: =IF(F9=1,C9&"_"&D9,D9) -> TM00A
C10: TM00 | D10: TM00B | F10: 2 | G10: =C10 -> TM00 | H10: =IF(F10=1,C10&"_"&D10,D10) -> TM00B
C11: TM01 | D11: TM01A | F11: 2 | G11: =C11 -> TM01 | H11: =IF(F11=1,C11&"_"&D11,D11) -> TM01A
C12: TM01 | D12: TM01B | F12: 2 | G12: =C12 -> TM01 | H12: =IF(F12=1,C12&"_"&D12,D12) -> TM01B
C13: TM02 | D13: TM02A | F13: 2 | G13: =C13 -> TM02 | H13: =IF(F13=1,C13&"_"&D13,D13) -> TM02A
C14: TM02 | D14: TM02B | F14: 2 | G14: =C14 -> TM02 | H14: =IF(F14=1,C14&"_"&D14,D14) -> TM02B
C15: TM03 | D15: TM03A | F15: 2 | G15: =C15 -> TM03 | H15: =IF(F15=1,C15&"_"&D15,D15) -> TM03A
C16: TM03 | D16: TM03B | F16: 2 | G16: =C16 -> TM03 | H16: =IF(F16=1,C16&"_"&D16,D16) -> TM03B
C17: TM04 | D17: TM04A | F17: 2 | G17: =C17 -> TM04 | H17: =IF(F17=1,C17&"_"&D17,D17) -> TM04A
C18: TM04 | D18: TM04B | F18: 2 | G18: =C18 -> TM04 | H18: =IF(F18=1,C18&"_"&D18,D18) -> TM04B
C19: TM05 | D19: TM05A | F19: 2 | G19: =C19 -> TM05 | H19: =IF(F19=1,C19&"_"&D19,D19) -> TM05A
C20: TM05 | D20: TM05B | F20: 2 | G20: =C20 -> TM05 | H20: =IF(F20=1,C20&"_"&D20,D20) -> TM05B
C21: TM06 | D21: TM06A | F21: 2 | G21: =C21 -> TM06 | H21: =IF(F21=1,C21&"_"&D21,D21) -> TM06A
... C36: TM13 | D36: TM13B | F36: 2 | G36: =C36 -> TM13 | H36: =IF(F36=1,C36&"_"&D36,D36) -> TM13B
B37: Power control PWM | C37: GPWM0 | D37: GPWM00 | F37: 1 | G37: =C37 -> GPWM0 | H37: =IF(F37=1,C37&"_"&D37,D37) -> GPWM0_GPWM00
C38: GPWM0 | D38: GPWMH00 | F38: 1 | G38: =C38 -> GPWM0 | H38: =IF(F38=1,C38&"_"&D38,D38) -> GPWM0_GPWMH00
C39: GPWM0 | D39: GPWM01 | F39: 1 | G39: =C39 -> GPWM0 | H39: =IF(F39=1,C39&"_"&D39,D39) -> GPWM0_GPWM01
C40: GPWM0 | D40: GPWMH01 | F40: 1 | G40: =C40 -> GPWM0 | H40: =IF(F40=1,C40&"_"&D40,D40) -> GPWM0_GPWMH01
C41: GPWM1 | D41: GPWM10 | F41: 1 | G41: =C41 -> GPWM1 | H41: =IF(F41=1,C41&"_"&D41,D41) -> GPWM1_GPWM10
C42: GPWM1 | D42: GPWMH10 | F42: 1 | G42: =C42 -> GPWM1 | H42: =IF(F42=1,C42&"_"&D42,D42) -> GPWM1_GPWMH10
C43: GPWM1 | D43: GPWM11 | F43: 1 | G43: =C43 -> GPWM1 | H43: =IF(F43=1,C43&"_"&D43,D43) -> GPWM1_GPWM11
C44: GPWM1 | D44: GPWMH11 | F44: 1 | G44: =C44 -> GPWM1 | H44: =IF(F44=1,C44&"_"&D44,D44) -> GPWM1_GPWMH11
C45: GPWM2 | D45: GPWM20 | F45: 1 | G45: =C45 -> GPWM2 | H45: =IF(F45=1,C45&"_"&D45,D45) -> GPWM2_GPWM20
C46: GPWM2 | D46: GPWMH20 | F46: 1 | G46: =C46 -> GPWM2 | H46: =IF(F46=1,C46&"_"&D46,D46) -> GPWM2_GPWMH20
C47: GPWM2 | D47: GPWM21 | F47: 1 | G47: =C47 -> GPWM2 | H47: =IF(F47=1,C47&"_"&D47,D47) -> GPWM2_GPWM21
C48: GPWM2 | D48: GPWMH21 | F48: 1 | G48: =C48 -> GPWM2 | H48: =IF(F48=1,C48&"_"&D48,D48) -> GPWM2_GPWMH21
C49: GPWM3 | D49: GPWM30 | F49: 1 | G49: =C49 -> GPWM3 | H49: =IF(F49=1,C49&"_"&D49,D49) -> GPWM3_GPWM30
... C68: GPWM7 | D68: GPWMH71 | F68: 1 | G68: =C68 -> GPWM7 | H68: =IF(F68=1,C68&"_"&D68,D68) -> GPWM7_GPWMH71
B69: SMbus | C69: SMBUS | D69: SMCL | F69: 1 | G69: =C69 -> SMBUS | H69: =IF(F69=1,C69&"_"&D69,D69) -> SMBUS_SMCL
C70: SMBUS | D70: SMDA | F70: 1 | G70: =C70 -> SMBUS | H70: =IF(F70=1,C70&"_"&D70,D70) -> SMBUS_SMDA
B71: A/D Input | C71: AD | D71: ADIN00 | F71: 2 | G71: =C71 -> AD | H71: =IF(F71=1,C71&"_"&D71,D71) -> ADIN00
C72: AD | D72: ADIN01 | F72: 2 | G72: =C72 -> AD | H72: =IF(F72=1,C72&"_"&D72,D72) -> ADIN01
C73: AD | D73: ADIN02 | F73: 2 | G73: =C73 -> AD | H73: =IF(F73=1,C73&"_"&D73,D73) -> ADIN02
...

Sheet @Pin Component List記載
B2: 表示名案 | D2: 説明文案 | H2: Pin Component List記載
B3: グループ名 | C3: 端子機能名 | D3: 説明(L説) | E3: 19.1.4 List of A/D Converter Ports | F3: 入出力 | G3: 説明形式(pinconfig) | H3: Pin Name | I3: Description ( '*', '$' are wildcard characters) | J3: Type
B4: ='＠グループ、表示名'!G4 -> DBG | C4: ='＠グループ、表示名'!H4 -> DBG_SWDCLK | D4: Debug clock pin | E4: Table 28.1-2 List of Debug Interface Pins | F4: I | G4: Debug clock input pin | H4: DBG_SWDCLK | I4: Debug clock input pin | J4: =F4 -> I
B5: ='＠グループ、表示名'!G5 -> DBG | C5: ='＠グループ、表示名'!H5 -> DBG_SWDD | D5: Debug data pin | E5: Table 28.1-2 List of Debug Interface Pins | F5: I/O | G5: Debug data input/output pin | H5: DBG_SWDD | I5: Debug data input/output pin | J5: =F5 -> I/O
B6: ='＠グループ、表示名'!G6 -> DBG | C6: ='＠グループ、表示名'!H6 -> DBG_TRCSWO | D6: Serial wire output pin | E6: Table 28.1-2 List of Debug Interface Pins | F6: O | G6: Serial wire output pin | H6: DBG_TRCSWO | I6: Serial wire output pin | J6: =F6 -> O
B7: ='＠グループ、表示名'!G7 -> OSC | C7: ='＠グループ、表示名'!H7 -> OSCI | D7: External oscillation input pin | E7: Table 1.4-2 Pin Functions | F7: I | G7: External oscillation input pin | H7: OSCI | I7: External oscillation input pin | J7: =F7 -> I
B8: ='＠グループ、表示名'!G8 -> OSC | C8: ='＠グループ、表示名'!H8 -> OSCO | D8: External oscillation input pin | E8: Table 1.4-2 Pin Functions | F8: O | G8: External oscillation output pin | H8: OSCO | I8: External oscillation output pin | J8: =F8 -> O
B9: ='＠グループ、表示名'!G9 -> TM00 | C9: ='＠グループ、表示名'!H9 -> TM00A | D9: Timer pin A | E9: 11.1.4 List of 16-bit Timer Ports | F9: I/O | G9: Timer 0 input/output pin A | H9: TM00A | I9: Timer 0 input/output pin A | J9: =F9 -> I/O
B10: ='＠グループ、表示名'!G10 -> TM00 | C10: ='＠グループ、表示名'!H10 -> TM00B | D10: Timer pin B | E10: 11.1.4 List of 16-bit Timer Ports | F10: I/O | G10: Timer 0 input/output pin B | H10: TM00B | I10: Timer 0 input/output pin B | J10: =F10 -> I/O
B11: ='＠グループ、表示名'!G11 -> TM01 | C11: ='＠グループ、表示名'!H11 -> TM01A | D11: Timer pin A | E11: 11.1.4 List of 16-bit Timer Ports | F11: I/O | G11: Timer 1 input/output pin A | H11: TM01A | I11: Timer 1 input/output pin A | J11: =F11 -> I/O
B12: ='＠グループ、表示名'!G12 -> TM01 | C12: ='＠グループ、表示名'!H12 -> TM01B | D12: Timer pin B | E12: 11.1.4 List of 16-bit Timer Ports | F12: I/O | G12: Timer 1 input/output pin B | H12: TM01B | I12: Timer 1 input/output pin B | J12: =F12 -> I/O
B13: ='＠グループ、表示名'!G13 -> TM02 | C13: ='＠グループ、表示名'!H13 -> TM02A | D13: Timer pin A | E13: 11.1.4 List of 16-bit Timer Ports | F13: I/O | G13: Timer 2 input/output pin A | H13: TM02A | I13: Timer 2 input/output pin A | J13: =F13 -> I/O
B14: ='＠グループ、表示名'!G14 -> TM02 | C14: ='＠グループ、表示名'!H14 -> TM02B | D14: Timer pin B | E14: 11.1.4 List of 16-bit Timer Ports | F14: I/O | G14: Timer 2 input/output pin B | H14: TM02B | I14: Timer 2 input/output pin B | J14: =F14 -> I/O
B15: ='＠グループ、表示名'!G15 -> TM03 | C15: ='＠グループ、表示名'!H15 -> TM03A | D15: Timer pin A | E15: 11.1.4 List of 16-bit Timer Ports | F15: I/O | G15: Timer 3 input/output pin A | H15: TM03A | I15: Timer 3 input/output pin A | J15: =F15 -> I/O
... B36: ='＠グループ、表示名'!G36 -> TM13 | C36: ='＠グループ、表示名'!H36 -> TM13B | D36: Timer pin B | E36: 11.1.4 List of 16-bit Timer Ports | F36: I/O | G36: Timer 13 input/output pin B | H36: TM13B | I36: Timer 13 input/output pin B | J36: =F36 -> I/O
B37: ='＠グループ、表示名'!G37 -> GPWM0 | C37: ='＠グループ、表示名'!H37 -> GPWM0_GPWM00 | D37: GPWM output pin | E37: 12.1.4 List of Power Control PWM Ports | F37: O | G37: GPWM00 output pin | H37: GPWM*_GPWM*0 | I37: GPWM*0 output pin | J37: O
B38: ='＠グループ、表示名'!G38 -> GPWM0 | C38: ='＠グループ、表示名'!H38 -> GPWM0_GPWMH00 | D38: GPWM high-resolution output pin | E38: 12.1.4 List of Power Control PWM Ports | F38: O | G38: GPWM00 high-resolution output pin | H38: GPWM*_GPWMH*0 | I38: GPWM*0 high-resolution output pin | J38: O
B39: ='＠グループ、表示名'!G39 -> GPWM0 | C39: ='＠グループ、表示名'!H39 -> GPWM0_GPWM01 | D39: GPWM output pin | E39: 12.1.4 List of Power Control PWM Ports | F39: O | G39: GPWM01 output pin | H39: GPWM*_GPWM*1 | I39: GPWM*1 output pin | J39: O
B40: ='＠グループ、表示名'!G40 -> GPWM0 | C40: ='＠グループ、表示名'!H40 -> GPWM0_GPWMH01 | D40: GPWM high-resolution output pin | E40: 12.1.4 List of Power Control PWM Ports | F40: O | G40: GPWM01 high-resolution output pin | H40: GPWM*_GPWMH*1 | I40: GPWM*1 high-resolution output pin | J40: O
B41: ='＠グループ、表示名'!G41 -> GPWM1 | C41: ='＠グループ、表示名'!H41 -> GPWM1_GPWM10 | D41: GPWM output pin | E41: 12.1.4 List of Power Control PWM Ports | F41: O | G41: GPWM10 output pin | H41: GPWM*_GPWM*0 | I41: GPWM*0 output pin | J41: O
B42: ='＠グループ、表示名'!G42 -> GPWM1 | C42: ='＠グループ、表示名'!H42 -> GPWM1_GPWMH10 | D42: GPWM high-resolution output pin | E42: 12.1.4 List of Power Control PWM Ports | F42: O | G42: GPWM10 high-resolution output pin | H42: GPWM*_GPWMH*0 | I42: GPWM*0 high-resolution output pin | J42: O
B43: ='＠グループ、表示名'!G43 -> GPWM1 | C43: ='＠グループ、表示名'!H43 -> GPWM1_GPWM11 | D43: GPWM output pin | E43: 12.1.4 List of Power Control PWM Ports | F43: O | G43: GPWM11 output pin | H43: GPWM*_GPWM*1 | I43: GPWM*1 output pin | J43: O
B44: ='＠グループ、表示名'!G44 -> GPWM1 | C44: ='＠グループ、表示名'!H44 -> GPWM1_GPWMH11 | D44: GPWM high-resolution output pin | E44: 12.1.4 List of Power Control PWM Ports | F44: O | G44: GPWM11 high-resolution output pin | H44: GPWM*_GPWMH*1 | I44: GPWM*1 high-resolution output pin | J44: O
B45: ='＠グループ、表示名'!G45 -> GPWM2 | C45: ='＠グループ、表示名'!H45 -> GPWM2_GPWM20 | D45: GPWM output pin | E45: 12.1.4 List of Power Control PWM Ports | F45: O | G45: GPWM20 output pin | H45: GPWM*_GPWM*0 | I45: GPWM*0 output pin | J45: O
B46: ='＠グループ、表示名'!G46 -> GPWM2 | C46: ='＠グループ、表示名'!H46 -> GPWM2_GPWMH20 | D46: GPWM high-resolution output pin | E46: 12.1.4 List of Power Control PWM Ports | F46: O | G46: GPWM20 high-resolution output pin | H46: GPWM*_GPWMH*0 | I46: GPWM*0 high-resolution output pin | J46: O
B47: ='＠グループ、表示名'!G47 -> GPWM2 | C47: ='＠グループ、表示名'!H47 -> GPWM2_GPWM21 | D47: GPWM output pin | E47: 12.1.4 List of Power Control PWM Ports | F47: O | G47: GPWM21 output pin | H47: GPWM*_GPWM*1 | I47: GPWM*1 output pin | J47: O
B48: ='＠グループ、表示名'!G48 -> GPWM2 | C48: ='＠グループ、表示名'!H48 -> GPWM2_GPWMH21 | D48: GPWM high-resolution output pin | E48: 12.1.4 List of Power Control PWM Ports | F48: O | G48: GPWM21 high-resolution output pin | H48: GPWM*_GPWMH*1 | I48: GPWM*1 high-resolution output pin | J48: O
... B68: ='＠グループ、表示名'!G68 -> GPWM7 | C68: ='＠グループ、表示名'!H68 -> GPWM7_GPWMH71 | D68: GPWM high-resolution output pin | E68: 12.1.4 List of Power Control PWM Ports | F68: O | G68: GPWM71 high-resolution output pin | H68: GPWM*_GPWMH*1 | I68: GPWM*1 high-resolution output pin | J68: O
B69: ='＠グループ、表示名'!G69 -> SMBUS | C69: ='＠グループ、表示名'!H69 -> SMBUS_SMCL | D69: SMBus data input/output (Nch open-drain control can be used.) | E69: [Register Manual] 5. I/O Port | F69: I/O | G69: SMBUS data input/output pin | H69: SMBUS_SMCL | I69: SMBUS data input/output pin | J69: =F69 -> I/O
B70: ='＠グループ、表示名'!G70 -> SMBUS | C70: ='＠グループ、表示名'!H70 -> SMBUS_SMDA | D70: SMBus clock input/output (Use Nch open-drain) | E70: [Register Manual] 5. I/O Port | F70: I/O | G70: SMBUS clock input/output pin | H70: SMBUS_SMDA | I70: SMBUS clock input/output pin | J70: =F70 -> I/O
B71: ='＠グループ、表示名'!G71 -> AD | C71: ='＠グループ、表示名'!H71 -> ADIN00 | D71: Analog input pin | E71: 19.1.4 List of A/D Converter Ports | F71: A | G71: A/D converter analog input 00 pin | H71: ADIN* | I71: A/D converter analog input * pin | J71: =F71 -> A
B72: ='＠グループ、表示名'!G72 -> AD | C72: ='＠グループ、表示名'!H72 -> ADIN01 | D72: Analog input pin | E72: 19.1.4 List of A/D Converter Ports | F72: A | G72: A/D converter analog input 01 pin | H72: ADIN* | I72: A/D converter analog input * pin | J72: =F72 -> A
B73: ='＠グループ、表示名'!G73 -> AD | C73: ='＠グループ、表示名'!H73 -> ADIN02 | D73: Analog input pin | E73: 19.1.4 List of A/D Converter Ports | F73: A | G73: A/D converter analog input 02 pin | H73: ADIN* | I73: A/D converter analog input * pin | J73: =F73 -> A
B74: ='＠グループ、表示名'!G74 -> AD | C74: ='＠グループ、表示名'!H74 -> ADIN03 | D74: Analog input pin | E74: 19.1.4 List of A/D Converter Ports | F74: A | G74: A/D converter analog input 03 pin | H74: ADIN* | I74: A/D converter analog input * pin | J74: =F74 -> A
B75: ='＠グループ、表示名'!G75 -> AD | C75: ='＠グループ、表示名'!H75 -> ADIN04 | D75: Analog input pin | E75: 19.1.4 List of A/D Converter Ports | F75: A | G75: A/D converter analog input 04 pin | H75: ADIN* | I75: A/D converter analog input * pin | J75: =F75 -> A
B76: ='＠グループ、表示名'!G76 -> AD | C76: ='＠グループ、表示名'!H76 -> ADIN05 | D76: Analog input pin | E76: 19.1.4 List of A/D Converter Ports | F76: A | G76: A/D converter analog input 05 pin | H76: ADIN* | I76: A/D converter analog input * pin | J76: =F76 -> A
B77: ='＠グループ、表示名'!G77 -> AD | C77: ='＠グループ、表示名'!H77 -> ADIN06 | D77: Analog input pin | E77: 19.1.4 List of A/D Converter Ports | F77: A | G77: A/D converter analog input 06 pin | H77: ADIN* | I77: A/D converter analog input * pin | J77: =F77 -> A
B78: ='＠グループ、表示名'!G78 -> AD | C78: ='＠グループ、表示名'!H78 -> ADIN07 | D78: Analog input pin | E78: 19.1.4 List of A/D Converter Ports | F78: A | G78: A/D converter analog input 07 pin | H78: ADIN* | I78: A/D converter analog input * pin | J78: =F78 -> A
B79: ='＠グループ、表示名'!G79 -> AD | C79: ='＠グループ、表示名'!H79 -> ADIN08 | D79: Analog input pin | E79: 19.1.4 List of A/D Converter Ports | F79: A | G79: A/D converter analog input 08 pin | H79: ADIN* | I79: A/D converter analog input * pin | J79: =F79 -> A
B80: ='＠グループ、表示名'!G80 -> AD | C80: ='＠グループ、表示名'!H80 -> ADIN09 | D80: Analog input pin | E80: 19.1.4 List of A/D Converter Ports | F80: A | G80: A/D converter analog input 09 pin | H80: ADIN* | I80: A/D converter analog input * pin | J80: =F80 -> A
...

Sheet Sheet1
A2: GPIO | B2: =IFERROR(IF(D2="","","/*!< "&D2&". \hideinitializer */"),"") -> /*!< General-purpose input/output pin. \hideinitializer */ | C2: =SUBSTITUTE(A2," ","") -> GPIO | D2: =IF(C2="GPIO","General-purpose input/output pin",IF(C2="","",INDEX('@Pin Component List記載'!$C$4:$G$299,MATCH(C2,'@Pin Component List記載'!$C$4:$C$299,0),5))) -> General-purpose input/output pin
A3: IRQ00 | B3: =IFERROR(IF(D3="","","/*!< "&D3&". \hideinitializer */"),"") -> /*!< External interrupt 0 input pin. \hideinitializer */ | C3: =SUBSTITUTE(A3," ","") -> IRQ00 | D3: =IF(C3="GPIO","General-purpose input/output pin",IF(C3="","",INDEX('@Pin Component List記載'!$C$4:$G$299,MATCH(C3,'@Pin Component List記載'!$C$4:$C$299,0),5))) -> External interrupt 0 input pin
A4: TM20A | B4: =IFERROR(IF(D4="","","/*!< "&D4&". \hideinitializer */"),"") | C4: =SUBSTITUTE(A4," ","") -> TM20A | D4: =IF(C4="GPIO","General-purpose input/output pin",IF(C4="","",INDEX('@Pin Component List記載'!$C$4:$G$299,MATCH(C4,'@Pin Component List記載'!$C$4:$C$299,0),5))) -> #N/A
A5: DBG_TRCCLK | B5: =IFERROR(IF(D5="","","/*!< "&D5&". \hideinitializer */"),"") | C5: =SUBSTITUTE(A5," ","") -> DBG_TRCCLK | D5: =IF(C5="GPIO","General-purpose input/output pin",IF(C5="","",INDEX('@Pin Component List記載'!$C$4:$G$299,MATCH(C5,'@Pin Component List記載'!$C$4:$C$299,0),5))) -> #N/A
B6: =IFERROR(IF(D6="","","/*!< "&D6&". \hideinitializer */"),"") | C6: =SUBSTITUTE(A6," ","") | D6: =IF(C6="GPIO","General-purpose input/output pin",IF(C6="","",INDEX('@Pin Component List記載'!$C$4:$G$299,MATCH(C6,'@Pin Component List記載'!$C$4:$C$299,0),5)))
A7: GPIO | B7: =IFERROR(IF(D7="","","/*!< "&D7&". \hideinitializer */"),"") -> /*!< General-purpose input/output pin. \hideinitializer */ | C7: =SUBSTITUTE(A7," ","") -> GPIO | D7: =IF(C7="GPIO","General-purpose input/output pin",IF(C7="","",INDEX('@Pin Component List記載'!$C$4:$G$299,MATCH(C7,'@Pin Component List記載'!$C$4:$C$299,0),5))) -> General-purpose input/output pin
A8: IRQ01 | B8: =IFERROR(IF(D8="","","/*!< "&D8&". \hideinitializer */"),"") -> /*!< External interrupt 1 input pin. \hideinitializer */ | C8: =SUBSTITUTE(A8," ","") -> IRQ01 | D8: =IF(C8="GPIO","General-purpose input/output pin",IF(C8="","",INDEX('@Pin Component List記載'!$C$4:$G$299,MATCH(C8,'@Pin Component List記載'!$C$4:$C$299,0),5))) -> External interrupt 1 input pin
A9: TM20B | B9: =IFERROR(IF(D9="","","/*!< "&D9&". \hideinitializer */"),"") | C9: =SUBSTITUTE(A9," ","") -> TM20B | D9: =IF(C9="GPIO","General-purpose input/output pin",IF(C9="","",INDEX('@Pin Component List記載'!$C$4:$G$299,MATCH(C9,'@Pin Component List記載'!$C$4:$C$299,0),5))) -> #N/A
A10: DBG_TRCSWO | B10: =IFERROR(IF(D10="","","/*!< "&D10&". \hideinitializer */"),"") -> /*!< Serial wire output pin. \hideinitializer */ | C10: =SUBSTITUTE(A10," ","") -> DBG_TRCSWO | D10: =IF(C10="GPIO","General-purpose input/output pin",IF(C10="","",INDEX('@Pin Component List記載'!$C$4:$G$299,MATCH(C10,'@Pin Component List記載'!$C$4:$C$299,0),5))) -> Serial wire output pin
B11: =IFERROR(IF(D11="","","/*!< "&D11&". \hideinitializer */"),"") | C11: =SUBSTITUTE(A11," ","") | D11: =IF(C11="GPIO","General-purpose input/output pin",IF(C11="","",INDEX('@Pin Component List記載'!$C$4:$G$299,MATCH(C11,'@Pin Component List記載'!$C$4:$C$299,0),5)))
A12: GPIO | B12: =IFERROR(IF(D12="","","/*!< "&D12&". \hideinitializer */"),"") -> /*!< General-purpose input/output pin. \hideinitializer */ | C12: =SUBSTITUTE(A12," ","") -> GPIO | D12: =IF(C12="GPIO","General-purpose input/output pin",IF(C12="","",INDEX('@Pin Component List記載'!$C$4:$G$299,MATCH(C12,'@Pin Component List記載'!$C$4:$C$299,0),5))) -> General-purpose input/output pin
A13: IRQ02 | B13: =IFERROR(IF(D13="","","/*!< "&D13&". \hideinitializer */"),"") -> /*!< External interrupt 2 input pin. \hideinitializer */ | C13: =SUBSTITUTE(A13," ","") -> IRQ02 | D13: =IF(C13="GPIO","General-purpose input/output pin",IF(C13="","",INDEX('@Pin Component List記載'!$C$4:$G$299,MATCH(C13,'@Pin Component List記載'!$C$4:$C$299,0),5))) -> External interrupt 2 input pin
A14: TM00A | B14: =IFERROR(IF(D14="","","/*!< "&D14&". \hideinitializer */"),"") -> /*!< Timer 0 input/output pin A. \hideinitializer */ | C14: =SUBSTITUTE(A14," ","") -> TM00A | D14: =IF(C14="GPIO","General-purpose input/output pin",IF(C14="","",INDEX('@Pin Component List記載'!$C$4:$G$299,MATCH(C14,'@Pin Component List記載'!$C$4:$C$299,0),5))) -> Timer 0 input/output pin A
A15: DBG_TRCD0 | B15: =IFERROR(IF(D15="","","/*!< "&D15&". \hideinitializer */"),"") | C15: =SUBSTITUTE(A15," ","") -> DBG_TRCD0 | D15: =IF(C15="GPIO","General-purpose input/output pin",IF(C15="","",INDEX('@Pin Component List記載'!$C$4:$G$299,MATCH(C15,'@Pin Component List記載'!$C$4:$C$299,0),5))) -> #N/A
B16: =IFERROR(IF(D16="","","/*!< "&D16&". \hideinitializer */"),"") | C16: =SUBSTITUTE(A16," ","") | D16: =IF(C16="GPIO","General-purpose input/output pin",IF(C16="","",INDEX('@Pin Component List記載'!$C$4:$G$299,MATCH(C16,'@Pin Component List記載'!$C$4:$C$299,0),5)))
A17: GPIO | B17: =IFERROR(IF(D17="","","/*!< "&D17&". \hideinitializer */"),"") -> /*!< General-purpose input/output pin. \hideinitializer */ | C17: =SUBSTITUTE(A17," ","") -> GPIO | D17: =IF(C17="GPIO","General-purpose input/output pin",IF(C17="","",INDEX('@Pin Component List記載'!$C$4:$G$299,MATCH(C17,'@Pin Component List記載'!$C$4:$C$299,0),5))) -> General-purpose input/output pin
A18: IRQ03 | B18: =IFERROR(IF(D18="","","/*!< "&D18&". \hideinitializer */"),"") -> /*!< External interrupt 3 input pin. \hideinitializer */ | C18: =SUBSTITUTE(A18," ","") -> IRQ03 | D18: =IF(C18="GPIO","General-purpose input/output pin",IF(C18="","",INDEX('@Pin Component List記載'!$C$4:$G$299,MATCH(C18,'@Pin Component List記載'!$C$4:$C$299,0),5))) -> External interrupt 3 input pin
A19: TM00B | B19: =IFERROR(IF(D19="","","/*!< "&D19&". \hideinitializer */"),"") -> /*!< Timer 0 input/output pin B. \hideinitializer */ | C19: =SUBSTITUTE(A19," ","") -> TM00B | D19: =IF(C19="GPIO","General-purpose input/output pin",IF(C19="","",INDEX('@Pin Component List記載'!$C$4:$G$299,MATCH(C19,'@Pin Component List記載'!$C$4:$C$299,0),5))) -> Timer 0 input/output pin B
A20: DBG_TRCD1 | B20: =IFERROR(IF(D20="","","/*!< "&D20&". \hideinitializer */"),"") | C20: =SUBSTITUTE(A20," ","") -> DBG_TRCD1 | D20: =IF(C20="GPIO","General-purpose input/output pin",IF(C20="","",INDEX('@Pin Component List記載'!$C$4:$G$299,MATCH(C20,'@Pin Component List記載'!$C$4:$C$299,0),5))) -> #N/A
B21: =IFERROR(IF(D21="","","/*!< "&D21&". \hideinitializer */"),"") | C21: =SUBSTITUTE(A21," ","") | D21: =IF(C21="GPIO","General-purpose input/output pin",IF(C21="","",INDEX('@Pin Component List記載'!$C$4:$G$299,MATCH(C21,'@Pin Component List記載'!$C$4:$C$299,0),5)))
A22: GPIO | B22: =IFERROR(IF(D22="","","/*!< "&D22&". \hideinitializer */"),"") -> /*!< General-purpose input/output pin. \hideinitializer */ | C22: =SUBSTITUTE(A22," ","") -> GPIO | D22: =IF(C22="GPIO","General-purpose input/output pin",IF(C22="","",INDEX('@Pin Component List記載'!$C$4:$G$299,MATCH(C22,'@Pin Component List記載'!$C$4:$C$299,0),5))) -> General-purpose input/output pin
A23: IRQ04 | B23: =IFERROR(IF(D23="","","/*!< "&D23&". \hideinitializer */"),"") -> /*!< External interrupt 4 input pin. \hideinitializer */ | C23: =SUBSTITUTE(A23," ","") -> IRQ04 | D23: =IF(C23="GPIO","General-purpose input/output pin",IF(C23="","",INDEX('@Pin Component List記載'!$C$4:$G$299,MATCH(C23,'@Pin Component List記載'!$C$4:$C$299,0),5))) -> External interrupt 4 input pin
A24: TM01A | B24: =IFERROR(IF(D24="","","/*!< "&D24&". \hideinitializer */"),"") -> /*!< Timer 1 input/output pin A. \hideinitializer */ | C24: =SUBSTITUTE(A24," ","") -> TM01A | D24: =IF(C24="GPIO","General-purpose input/output pin",IF(C24="","",INDEX('@Pin Component List記載'!$C$4:$G$299,MATCH(C24,'@Pin Component List記載'!$C$4:$C$299,0),5))) -> Timer 1 input/output pin A
A25: DBG_TRCD2 | B25: =IFERROR(IF(D25="","","/*!< "&D25&". \hideinitializer */"),"") | C25: =SUBSTITUTE(A25," ","") -> DBG_TRCD2 | D25: =IF(C25="GPIO","General-purpose input/output pin",IF(C25="","",INDEX('@Pin Component List記載'!$C$4:$G$299,MATCH(C25,'@Pin Component List記載'!$C$4:$C$299,0),5))) -> #N/A
B26: =IFERROR(IF(D26="","","/*!< "&D26&". \hideinitializer */"),"") | C26: =SUBSTITUTE(A26," ","") | D26: =IF(C26="GPIO","General-purpose input/output pin",IF(C26="","",INDEX('@Pin Component List記載'!$C$4:$G$299,MATCH(C26,'@Pin Component List記載'!$C$4:$C$299,0),5)))
A27: GPIO | B27: =IFERROR(IF(D27="","","/*!< "&D27&". \hideinitializer */"),"") -> /*!< General-purpose input/output pin. \hideinitializer */ | C27: =SUBSTITUTE(A27," ","") -> GPIO | D27: =IF(C27="GPIO","General-purpose input/output pin",IF(C27="","",INDEX('@Pin Component List記載'!$C$4:$G$299,MATCH(C27,'@Pin Component List記載'!$C$4:$C$299,0),5))) -> General-purpose input/output pin
A28: IRQ05 | B28: =IFERROR(IF(D28="","","/*!< "&D28&". \hideinitializer */"),"") -> /*!< External interrupt 5 input pin. \hideinitializer */ | C28: =SUBSTITUTE(A28," ","") -> IRQ05 | D28: =IF(C28="GPIO","General-purpose input/output pin",IF(C28="","",INDEX('@Pin Component List記載'!$C$4:$G$299,MATCH(C28,'@Pin Component List記載'!$C$4:$C$299,0),5))) -> External interrupt 5 input pin
A29: TM01B | B29: =IFERROR(IF(D29="","","/*!< "&D29&". \hideinitializer */"),"") -> /*!< Timer 1 input/output pin B. \hideinitializer */ | C29: =SUBSTITUTE(A29," ","") -> TM01B | D29: =IF(C29="GPIO","General-purpose input/output pin",IF(C29="","",INDEX('@Pin Component List記載'!$C$4:$G$299,MATCH(C29,'@Pin Component List記載'!$C$4:$C$299,0),5))) -> Timer 1 input/output pin B
A30: DBG_TRCD3 | B30: =IFERROR(IF(D30="","","/*!< "&D30&". \hideinitializer */"),"") | C30: =SUBSTITUTE(A30," ","") -> DBG_TRCD3 | D30: =IF(C30="GPIO","General-purpose input/output pin",IF(C30="","",INDEX('@Pin Component List記載'!$C$4:$G$299,MATCH(C30,'@Pin Component List記載'!$C$4:$C$299,0),5))) -> #N/A
B31: =IFERROR(IF(D31="","","/*!< "&D31&". \hideinitializer */"),"") | C31: =SUBSTITUTE(A31," ","") | D31: =IF(C31="GPIO","General-purpose input/output pin",IF(C31="","",INDEX('@Pin Component List記載'!$C$4:$G$299,MATCH(C31,'@Pin Component List記載'!$C$4:$C$299,0),5)))
A32: GPIO | B32: =IFERROR(IF(D32="","","/*!< "&D32&". \hideinitializer */"),"") -> /*!< General-purpose input/output pin. \hideinitializer */ | C32: =SUBSTITUTE(A32," ","") -> GPIO | D32: =IF(C32="GPIO","General-purpose input/output pin",IF(C32="","",INDEX('@Pin Component List記載'!$C$4:$G$299,MATCH(C32,'@Pin Component List記載'!$C$4:$C$299,0),5))) -> General-purpose input/output pin
A33: IRQ06 | B33: =IFERROR(IF(D33="","","/*!< "&D33&". \hideinitializer */"),"") -> /*!< External interrupt 6 input pin. \hideinitializer */ | C33: =SUBSTITUTE(A33," ","") -> IRQ06 | D33: =IF(C33="GPIO","General-purpose input/output pin",IF(C33="","",INDEX('@Pin Component List記載'!$C$4:$G$299,MATCH(C33,'@Pin Component List記載'!$C$4:$C$299,0),5))) -> External interrupt 6 input pin
A34: TM02A | B34: =IFERROR(IF(D34="","","/*!< "&D34&". \hideinitializer */"),"") -> /*!< Timer 2 input/output pin A. \hideinitializer */ | C34: =SUBSTITUTE(A34," ","") -> TM02A | D34: =IF(C34="GPIO","General-purpose input/output pin",IF(C34="","",INDEX('@Pin Component List記載'!$C$4:$G$299,MATCH(C34,'@Pin Component List記載'!$C$4:$C$299,0),5))) -> Timer 2 input/output pin A
A35: SMBUS_SMCL | B35: =IFERROR(IF(D35="","","/*!< "&D35&". \hideinitializer */"),"") -> /*!< SMBUS data input/output pin. \hideinitializer */ | C35: =SUBSTITUTE(A35," ","") -> SMBUS_SMCL | D35: =IF(C35="GPIO","General-purpose input/output pin",IF(C35="","",INDEX('@Pin Component List記載'!$C$4:$G$299,MATCH(C35,'@Pin Component List記載'!$C$4:$C$299,0),5))) -> SMBUS data input/output pin
A36: CAN1_CRX | B36: =IFERROR(IF(D36="","","/*!< "&D36&". \hideinitializer */"),"") | C36: =SUBSTITUTE(A36," ","") -> CAN1_CRX | D36: =IF(C36="GPIO","General-purpose input/output pin",IF(C36="","",INDEX('@Pin Component List記載'!$C$4:$G$299,MATCH(C36,'@Pin Component List記載'!$C$4:$C$299,0),5))) -> #N/A
B37: =IFERROR(IF(D37="","","/*!< "&D37&". \hideinitializer */"),"") | C37: =SUBSTITUTE(A37," ","") | D37: =IF(C37="GPIO","General-purpose input/output pin",IF(C37="","",INDEX('@Pin Component List記載'!$C$4:$G$299,MATCH(C37,'@Pin Component List記載'!$C$4:$C$299,0),5)))
A38: GPIO | B38: =IFERROR(IF(D38="","","/*!< "&D38&". \hideinitializer */"),"") -> /*!< General-purpose input/output pin. \hideinitializer */ | C38: =SUBSTITUTE(A38," ","") -> GPIO | D38: =IF(C38="GPIO","General-purpose input/output pin",IF(C38="","",INDEX('@Pin Component List記載'!$C$4:$G$299,MATCH(C38,'@Pin Component List記載'!$C$4:$C$299,0),5))) -> General-purpose input/output pin
A39: IRQ07 | B39: =IFERROR(IF(D39="","","/*!< "&D39&". \hideinitializer */"),"") -> /*!< External interrupt 7 input pin. \hideinitializer */ | C39: =SUBSTITUTE(A39," ","") -> IRQ07 | D39: =IF(C39="GPIO","General-purpose input/output pin",IF(C39="","",INDEX('@Pin Component List記載'!$C$4:$G$299,MATCH(C39,'@Pin Component List記載'!$C$4:$C$299,0),5))) -> External interrupt 7 input pin
A40: TM02B | B40: =IFERROR(IF(D40="","","/*!< "&D40&". \hideinitializer */"),"") -> /*!< Timer 2 input/output pin B. \hideinitializer */ | C40: =SUBSTITUTE(A40," ","") -> TM02B | D40: =IF(C40="GPIO","General-purpose input/output pin",IF(C40="","",INDEX('@Pin Component List記載'!$C$4:$G$299,MATCH(C40,'@Pin Component List記載'!$C$4:$C$299,0),5))) -> Timer 2 input/output pin B
A41: SMBUS_SMDA | B41: =IFERROR(IF(D41="","","/*!< "&D41&". \hideinitializer */"),"") -> /*!< SMBUS clock input/output pin. \hideinitializer */ | C41: =SUBSTITUTE(A41," ","") -> SMBUS_SMDA | D41: =IF(C41="GPIO","General-purpose input/output pin",IF(C41="","",INDEX('@Pin Component List記載'!$C$4:$G$299,MATCH(C41,'@Pin Component List記載'!$C$4:$C$299,0),5))) -> SMBUS clock input/output pin
...
