Workbook

Sheet MFP(sample)
A1: LQFP64(7*7) | B1: ULQFP64(7*7) | C1: LQFP128(14*14) | D1: ULQFP128(14*14) | E1: PAD Name | F1: Pin Name | G1: MFP1 | H1: MFP2 | I1: MFP3 | J1: MFP4 | K1: MFP5 | L1: MFP6 | M1: MFP7 | N1: MFP8(LQFP64) | O1: MFP8(LQFP128) | P1: MFP8(ULQFP128) | Q1: MFP31 | S1: MFP1 | T1: ADC | U1: ACMP0 | V1: ACMP1 | X1: Bit3 | Y1: Bit2 | Z1: Bit1 | AA1: Bit0
C2: 1 | D2: 1 | E2: GPB[5] | F2: PB.5 | G2: Analog0 | H2: EBI_ADR0 | I2: SD0_DAT3 | J2: EMAC_RMII_REFCLK | P2: LCD_SEG33 | S2: Analog0 | T2: EADC0_CH5 | V2: ACMP1_N | X2: MFPA[3] | Y2: MFPA[2] | Z2: MFPA[1] | AA2: MFPA[0]
A3: 1 | B3: 1 | C3: 2 | D3: 2 | E3: GPB[4] | F3: PB.4 | G3: Analog1 | H3: EBI_ADR1 | I3: SD0_DAT2 | J3: EMAC_RMII_RXD0 | P3: LCD_SEG32 | S3: Analog1 | T3: EADC0_CH4 | V3: ACMP1_P1 | Z3: ALT1[1] | AA3: MFP1[1]
A4: 2 | B4: 2 | C4: 3 | D4: 3 | E4: GPB[3] | F4: PB.3 | G4: Analog2 | H4: EBI_ADR2 | I4: SD0_DAT1 | J4: EMAC_RMII_RXD1 | K4: SPI0_SS[ULQFP64(7*7)] | P4: LCD_SEG31 | S4: Analog2 | T4: EADC0_CH3 | U4: ACMP0_N | AA4: ALT[5]
A5: 3 | B5: 3 | C5: 4 | D5: 4 | E5: GPB[2] | F5: PB.2 | G5: Analog3 | H5: EBI_ADR3 | I5: SD0_DAT0 | J5: EMAC_RMII_CRSDV | P5: LCD_SEG30 | S5: Analog3 | T5: EADC0_CH2 | U5: ACMP0_P1
A6: 4 | B6: 4 | C6: 5 | D6: 5 | E6: GPC[12] | F6: PC.12 | H6: EBI_ADR4 | I6: UART0_TXD | J6: I2C0_SCL | P6: LCD_SEG29
A7: 5 | B7: 5 | C7: 6 | D7: 6 | E7: GPC[11] | F7: PC.11 | H7: EBI_ADR5 | I7: UART0_RXD | J7: I2C0_SDA | P7: LCD_SEG28
C8: 7 | D8: 7 | E8: GPC[10] | F8: PC.10 | H8: EBI_ADR6 | O8: LCD_SEG23 | P8: LCD_SEG27
C9: 8 | D9: 8 | E9: GPC[9] | F9: PC.9 | H9: EBI_ADR7 | O9: LCD_SEG22 | P9: LCD_SEG26
C10: 9 | D10: 9 | E10: GPB[1] | F10: PB.1 | G10: Analog4 | H10: EBI_ADR8 | I10: SD0_CLK | J10: EMAC_RMII_RXERR | O10: LCD_SEG21 | P10: LCD_SEG25 | S10: Analog4 | T10: EADC0_CH1
C11: 10 | D11: 10 | E11: GPB[0] | F11: PB.0 | G11: Analog5 | H11: EBI_ADR9 | I11: SD0_CMD | O11: LCD_SEG20 | P11: LCD_SEG24 | S11: Analog5 | T11: EADC0_CH0
C12: 11 | D12: 11 | E12: VSSPST | F12: VSS
C13: 12 | D13: 12 | E13: VDDPST | F13: VDD
C14: 13 | D14: 13 | E14: GPA[11] | F14: PA.11 | G14: Analog6 | H14: EBI_nRD | I14: SC2_PWR | J14: SPI2_SS | S14: Analog6 | U14: ACMP0_P0
C15: 14 | D15: 14 | E15: GPA[10] | F15: PA.10 | G15: Analog7 | H15: EBI_nWR | I15: SC2_RST | J15: SPI2_CLK | S15: Analog7 | V15: ACMP1_P0
C16: 15 | D16: 15 | E16: GPA[9] | F16: PA.9 | H16: EBI_MCLK | I16: SC2_DAT | J16: SPI2_MISO
A17: 6 | B17: 6 | C17: 16 | D17: 16 | E17: GPA[8] | F17: PA.8 | H17: EBI_ALE | I17: SC2_CLK | J17: SPI2_MOSI | N17: LCD_SEG19 | O17: LCD_SEG19 | P17: LCD_SEG23
A18: 7 | B18: 7 | C18: 17 | D18: 17 | E18: GPC[13] | F18: PC.13 | H18: EBI_ADR10 | I18: SC2_nCD | J18: SPI2_I2SMCLK | K18: I2C0_CL | N18: LCD_SEG18 | O18: LCD_SEG18 | P18: LCD_SEG22
A19: 8 | B19: 8 | C19: 18 | D19: 18 | E19: GPD[12] | F19: PD.12 | H19: EBI_nCS0 | K19: I2C0_DA | N19: LCD_SEG17 | O19: LCD_SEG17 | P19: LCD_SEG21
A20: 9 | B20: 9 | C20: 19 | D20: 19 | E20: GPD[11] | F20: PD.11 | H20: EBI_nCS1 | I20: BRAKE00 | J20: CAN0_TXD | N20: LCD_SEG16 | O20: LCD_SEG16 | P20: LCD_SEG20
A21: 10 | B21: 10 | C21: 20 | D21: 20 | E21: GPD[10] | F21: PD.10 | H21: EBI_nCS2 | I21: BRAKE01 | J21: CAN0_RXD | N21: LCD_SEG15 | O21: LCD_SEG15 | P21: LCD_SEG19
A22: 11 | B22: 11 | C22: 21 | D22: 21 | E22: VSSPST | F22: VSS | L22: SPI0_SCLK_O | N22: LCD_SEG14 | O22: LCD_SEG14 | P22: LCD_SEG18
A23: 12 | B23: 12 | C23: 22 | D23: 22 | E23: VDDPST | F23: VDD | N23: LCD_SEG13 | O23: LCD_SEG13 | P23: LCD_SEG17
A24: 13 | B24: 13 | C24: 23 | D24: 23 | E24: GPG[0] | F24: PG.0 | H24: EBI_ADR8 | J24: I2C0_SCL | N24: LCD_SEG12 | O24: LCD_SEG12 | P24: LCD_SEG16
A25: 14 | B25: 14 | C25: 24 | D25: 24 | E25: GPG[1] | F25: PG.1 | H25: EBI_ADR9 | I25: SPI2_I2SMCLK | J25: I2C0_SDA | N25: LCD_SEG11 | O25: LCD_SEG11 | P25: LCD_SEG15
A26: 15 | B26: 15 | C26: 25 | D26: 25 | E26: GPG[2] | F26: PG.2 | H26: EBI_ADR11 | I26: SPI2_SS | J26: I2C0_SMBAL | N26: LCD_SEG10 | O26: LCD_SEG10 | P26: LCD_SEG14
A27: 16 | B27: 16 | C27: 26 | D27: 26 | E27: GPG[3] | F27: PG.3 | H27: EBI_ADR12 | I27: SPI2_CLK | J27: I2C0_SMBSUS | N27: LCD_SEG9 | O27: LCD_SEG9 | P27: LCD_SEG13
C28: 27 | D28: 27 | E28: GPG[4] | F28: PG.4 | H28: EBI_ADR13 | I28: SPI2_MISO
C29: 28 | D29: 28 | E29: GPF[11] | F29: PF.11 | H29: EBI_ADR14 | I29: SPI2_MOSI
C30: 29 | D30: 29 | E30: GPF[10] | F30: PF.10 | H30: EBI_ADR15 | I30: SC0_nCD | J30: I2S0_BCLK
C31: 30 | D31: 30 | E31: GPF[9] | F31: PF.9 | H31: EBI_ADR16 | I31: SC0_PWR | J31: I2S0_MCLK
C32: 31 | D32: 31 | E32: GPF[8] | F32: PF.8 | H32: EBI_ADR17 | I32: SC0_RST | J32: I2S0_DI
C33: 32 | D33: 32 | E33: GPF[7] | F33: PF.7 | H33: EBI_ADR18 | I33: SC0_DAT | J33: I2S0_DO
C34: 33 | D34: 33 | E34: GPF[6] | F34: PF.6 | H34: EBI_ADR19 | I34: SC0_CLK | J34: I2S0_LRCK
C35: 34 | D35: 34 | E35: VBAT | F35: VDD
C36: 35 | D36: 35 | E36: GPF[5] | F36: PF.5 | H36: UART2_RXD | J36: UART2_nCTS
C37: 36 | D37: 36 | E37: GPF[4] | F37: PF.4 | H37: UART2_TXD | J37: UART2_nRTS
C38: 37 | D38: 37 | E38: GPH[0] | F38: PH.0 | H38: EBI_ADR7 | J38: UART5_TXD
C39: 38 | D39: 38 | E39: GPH[1] | F39: PH.1 | H39: EBI_ADR6 | J39: UART5_RXD
C40: 39 | D40: 39 | E40: GPH[2] | F40: PH.2 | H40: EBI_ADR5 | J40: UART5_nRTS
...

Sheet MFP
A1: PAD# | B1: HQFP80 (14*14) | C1: HQFP100 (14*14) | D1: HQFP128 (18*18) | E1: HQFP144 (20*20) | F1: PAD NAME | G1: PIN NAME | H1: MFP1 | I1: MFP2 | J1: MFP3 | K1: MFP4 | L1: MFP5 | M1: MFP6 | N1: MFP7 | P1: MFP1 | Q1: AD | R1: VGA | S1: CMP | U1: MFP1 | V1: SPI | W1: UART | X1: LIN | Y1: IIC | AA1: MFP2 | AB1: SPI | AC1: UART | AD1: LIN | AE1: IIC | AG1: MFP3 | AH1: SPI | AI1: UART | AK1: MFP4 | AL1: SPI | AM1: UART | AN1: IIC | AP1: MFP5 | AQ1: SPI | AR1: UART | AS1: IIC | AU1: MFP6 | AV1: SPI | AW1: UART | AX1: IIC | AZ1: Bit3 | BA1: Bit2 | BB1: Bit1 | BC1: Bit0
A2: 1 | E2: 1 | F2: VSSPST | G2: VSS
A3: 2 | D3: 1 | E3: 2 | F3: GP9[6] | G3: P9.6 | AZ3: IOP9MD[27] | BA3: IOP9MD[26] | BB3: IOP9MD[25] | BC3: IOP9MD[24]
A4: 3 | E4: 3 | F4: VDDPST | G4: VDD50
A5: 4 | D5: 2 | E5: 4 | F5: GP9[7] | G5: P9.7 | AZ5: IOP9MD[31] | BA5: IOP9MD[30] | BB5: IOP9MD[29] | BC5: IOP9MD[28]
A6: 5 | B6: 1 | C6: 1 | D6: 3 | E6: 5 | F6: GP0[0] | G6: P0.0 | H6: IRQ00 | I6: TM20A | K6: DBG_TRCCLK | AZ6: IOP0MD[3] | BA6: IOP0MD[2] | BB6: IOP0MD[1] | BC6: IOP0MD[0]
A7: 6 | B7: 2 | C7: 2 | D7: 4 | E7: 6 | F7: GP0[1] | G7: P0.1 | H7: IRQ01 | I7: TM20B | K7: DBG_TRCSWO | AZ7: IOP0MD[7] | BA7: IOP0MD[6] | BB7: IOP0MD[5] | BC7: IOP0MD[4]
A8: 7 | B8: 3 | C8: 3 | D8: 5 | E8: 7 | F8: GP0[2] | G8: P0.2 | H8: IRQ02 | I8: TM00A | K8: DBG_TRCD0 | AZ8: IOP0MD[11] | BA8: IOP0MD[10] | BB8: IOP0MD[9] | BC8: IOP0MD[8]
A9: 8 | B9: 4 | C9: 4 | D9: 6 | E9: 8 | F9: GP0[3] | G9: P0.3 | H9: IRQ03 | I9: TM00B | K9: DBG_TRCD1 | AZ9: IOP0MD[15] | BA9: IOP0MD[14] | BB9: IOP0MD[13] | BC9: IOP0MD[12]
A10: 9 | B10: 5 | C10: 5 | D10: 7 | E10: 9 | F10: GP0[4] | G10: P0.4 | H10: IRQ04 | I10: TM01A | K10: DBG_TRCD2 | AZ10: IOP0MD[19] | BA10: IOP0MD[18] | BB10: IOP0MD[17] | BC10: IOP0MD[16]
A11: 10 | B11: 6 | C11: 6 | D11: 8 | E11: 10 | F11: GP0[5] | G11: P0.5 | H11: IRQ05 | I11: TM01B | K11: DBG_TRCD3 | AZ11: IOP0MD[23] | BA11: IOP0MD[22] | BB11: IOP0MD[21] | BC11: IOP0MD[20]
A12: 11 | D12: 9 | E12: 11 | F12: GP0[6] | G12: P0.6 | H12: IRQ06 | I12: TM02A | J12: SMBUS_SMCL | K12: CAN1_CRX | AZ12: IOP0MD[27] | BA12: IOP0MD[26] | BB12: IOP0MD[25] | BC12: IOP0MD[24]
A13: 12 | D13: 10 | E13: 12 | F13: GP0[7] | G13: P0.7 | H13: IRQ07 | I13: TM02B | J13: SMBUS_SMDA | K13: CAN1_CTX | AZ13: IOP0MD[31] | BA13: IOP0MD[30] | BB13: IOP0MD[29] | BC13: IOP0MD[28]
A14: 13 | B14: 7 | C14: 7 | D14: 11 | E14: 13 | F14: nRESET | G14: NRST
A15: 14 | C15: 8 | D15: 12 | E15: 14 | F15: GP6[0] | G15: P6.0 | H15: TM03A | I15: GPWM5_GPWMST5 | J15: Serial301 | K15: Serial401 | AG15: Serial301 | AH15: SPI4_SBI | AI15: UART4_RX | AK15: Serial401 | AL15: SPI7_SBI | AM15: UART7_RX | AZ15: IOP6MD[3] | BA15: IOP6MD[2] | BB15: IOP6MD[1] | BC15: IOP6MD[0]
A16: 15 | C16: 9 | D16: 13 | E16: 15 | F16: GP6[1] | G16: P6.1 | H16: TM03B | I16: GPWM6_GPWMST6 | J16: Serial302 | K16: Serial402 | L16: Serial501 | M16: Serial601 | AG16: Serial302 | AH16: SPI4_SBO | AI16: UART4_TX | AK16: Serial402 | AL16: SPI4_SBT | AP16: Serial501 | AQ16: SPI7_SBO | AR16: UART7_TX | AS16: IIC7_SDA | AU16: Serial601 | AV16: SPI7_SBT | AX16: IIC7_SCL | AZ16: IOP6MD[7] | BA16: IOP6MD[6] | BB16: IOP6MD[5] | BC16: IOP6MD[4]
A17: 16 | C17: 10 | D17: 14 | E17: 16 | F17: GP6[2] | G17: P6.2 | H17: TM04A | I17: GPWM7_GPWMST7 | J17: Serial303 | K17: Serial403 | L17: Serial502 | M17: Serial602 | AG17: Serial303 | AH17: SPI4_SBT | AK17: Serial403 | AL17: SPI4_SBO | AM17: UART4_TX | AP17: Serial502 | AQ17: SPI7_SBT | AS17: IIC7_SCL | AU17: Serial602 | AV17: SPI7_SBO | AW17: UART7_TX | AX17: IIC7_SDA | AZ17: IOP6MD[11] | BA17: IOP6MD[10] | BB17: IOP6MD[9] | BC17: IOP6MD[8]
A18: 17 | D18: 15 | E18: 17 | F18: GP6[3] | G18: P6.3 | H18: TM04B | I18: GPWM8_GPWMST8 | J18: Serial304 | K18: Serial404 | AG18: Serial304 | AH18: SPI4_SBCS | AK18: Serial404 | AL18: SPI7_SBCS | AZ18: IOP6MD[15] | BA18: IOP6MD[14] | BB18: IOP6MD[13] | BC18: IOP6MD[12]
A19: 18 | B19: 8 | C19: 11 | D19: 16 | E19: 18 | F19: TEST | G19: TEST
A20: 19 | D20: 17 | E20: 19 | F20: GP6[4] | G20: P6.4 | H20: TM05A | AZ20: IOP6MD[19] | BA20: IOP6MD[18] | BB20: IOP6MD[17] | BC20: IOP6MD[16]
A21: 20 | D21: 18 | E21: 20 | F21: GP6[5] | G21: P6.5 | H21: TM05B | AZ21: IOP6MD[23] | BA21: IOP6MD[22] | BB21: IOP6MD[21] | BC21: IOP6MD[20]
A22: 21 | B22: 9 | C22: 12 | D22: 19 | E22: 21 | F22: SWDCLK | G22: SWDCLK
A23: 22 | B23: 10 | C23: 13 | D23: 20 | E23: 22 | F23: SWDD | G23: SWDD
A24: 23 | B24: 11 | C24: 14 | D24: 21 | E24: 23 | F24: VDDPST | G24: VDD50
A25: 24 | B25: 12 | C25: 15 | D25: 22 | E25: 24 | F25: OSCI | G25: OSCI
A26: 25 | B26: 13 | C26: 16 | D26: 23 | E26: 25 | F26: OSCO | G26: OSCO
A27: 26 | B27: 14 | C27: 17 | D27: 24 | E27: 26 | F27: VSSPST | G27: VSS
A28: 27 | B28: 15 | C28: 18 | D28: 25 | E28: 27 | F28: VPP | G28: VPP
A29: 28 | B29: 16 | C29: 19 | D29: 26 | E29: 28 | F29: VDDPST | G29: VOUT12
A30: 29 | B30: 17 | C30: 20 | D30: 27 | E30: 29 | F30: NDMOD | G30: NDMOD
A31: 30 | B31: 18 | C31: 21 | D31: 28 | E31: 30 | F31: VDDPST | G31: VOUT30
A32: 31 | B32: 19 | C32: 22 | D32: 29 | E32: 31 | F32: GPA[0] | G32: PA.0 | H32: GPWM6_GPWMH60 | I32: GPWM6_GPWM60 | AZ32: IOPAMD[3] | BA32: IOPAMD[2] | BB32: IOPAMD[1] | BC32: IOPAMD[0]
A33: 32 | B33: 20 | C33: 23 | D33: 30 | E33: 32 | F33: GPA[1] | G33: PA.1 | H33: GPWM6_GPWMH61 | I33: GPWM6_GPWM61 | AZ33: IOPAMD[7] | BA33: IOPAMD[6] | BB33: IOPAMD[5] | BC33: IOPAMD[4]
A34: 33 | C34: 24 | D34: 31 | E34: 33 | F34: GPA[2] | G34: PA.2 | H34: GPWM7_GPWMH70 | I34: GPWM7_GPWM70 | AZ34: IOPAMD[11] | BA34: IOPAMD[10] | BB34: IOPAMD[9] | BC34: IOPAMD[8]
A35: 34 | C35: 25 | D35: 32 | E35: 34 | F35: GPA[3] | G35: PA.3 | H35: GPWM7_GPWMH71 | I35: GPWM7_GPWM71 | AZ35: IOPAMD[15] | BA35: IOPAMD[14] | BB35: IOPAMD[13] | BC35: IOPAMD[12]
A36: 35 | E36: 35 | F36: GP6[6] | G36: P6.6 | AZ36: IOP6MD[27] | BA36: IOP6MD[26] | BB36: IOP6MD[25] | BC36: IOP6MD[24]
A37: 36 | E37: 36 | F37: GP6[7] | G37: P6.7 | AZ37: IOP6MD[31] | BA37: IOP6MD[30] | BB37: IOP6MD[29] | BC37: IOP6MD[28]
A38: 37 | C38: 26 | D38: 33 | E38: 37 | F38: GPA[4] | G38: PA.4 | H38: GPWM8_GPWMH80 | I38: GPWM8_GPWM80 | AZ38: IOPAMD[19] | BA38: IOPAMD[18] | BB38: IOPAMD[17] | BC38: IOPAMD[16]
A39: 38 | C39: 27 | D39: 34 | E39: 38 | F39: GPA[5] | G39: PA.5 | H39: GPWM8_GPWMH81 | I39: GPWM8_GPWM81 | AZ39: IOPAMD[23] | BA39: IOPAMD[22] | BB39: IOPAMD[21] | BC39: IOPAMD[20]
A40: 39 | E40: 39 | F40: GPA[6] | G40: PA.6 | AZ40: IOPAMD[27] | BA40: IOPAMD[26] | BB40: IOPAMD[25] | BC40: IOPAMD[24]
...

Sheet Package Type
B3: Part No. | C3: HQFP 80 (14x14) | E3: HQFP100 (14x14) | G3: HQFP 128 (18x18) | I3: HQFP144 (20x20)
B4: KM1M7AF0 | C4: KM1M7AF03N/M/K | D4: HQFP80 | E4: KM1M7AF02N/M/K | F4: HQFP100 | G4: KM1M7AF01N/M/K | H4: HQFP128 | I4: KM1M7AF00N/M/K | J4: HQFP144
B5: KM1M7AF1 | C5: KM1M7AF13N/M/K | D5: HQFP80 | E5: KM1M7AF12N/M/K | F5: HQFP100 | G5: KM1M7AF11N/M/K | H5: HQFP128 | I5: KM1M7AF10N/M/K | J5: HQFP144
B6: KM1M7AF5 | C6: KM1M7AF53N/M/K | D6: HQFP80 | E6: KM1M7AF52N/M/K | F6: HQFP100 | G6: KM1M7AF51N/M/K | H6: HQFP128 | I6: KM1M7AF50N/M/K | J6: HQFP144
B7: KM1M7AF6 | C7: KM1M7AF63N/M/K | D7: HQFP80 | E7: KM1M7AF62N/M/K | F7: HQFP100 | G7: KM1M7AF61N/M/K | H7: HQFP128 | I7: KM1M7AF60N/M/K | J7: HQFP144
B12: HQFP80 (14*14) | C12: HQFP100 (14*14) | D12: HQFP128 (18*18) | E12: HQFP144 (20*20)
B13: HQFP80 | C13: HQFP100 | D13: HQFP128 | E13: HQFP144
B15: VDD50 | C15: no specific power domin
B17: AVDD50 | C17: no specific power domin
B19: VOUT30 | C19: no specific power domin
B21: VOUT12 | C21: no specific power domin

Sheet Unused IP
B1: MFP | C1: MFP | D1: MFP | E1: MFP | F1: MFP | G1: MFP | H1: MFP | I1: MFP | J1: MFP | K1: MFP | L1: MFP | M1: MFP | N1: MFP | O1: MFP | P1: MFP | Q1: MFP
B2: KM1M7AF03N/M/K | C2: KM1M7AF13N/M/K | D2: KM1M7AF53N/M/K | E2: KM1M7AF63N/M/K | F2: KM1M7AF02N/M/K | G2: KM1M7AF12N/M/K | H2: KM1M7AF52N/M/K | I2: KM1M7AF62N/M/K | J2: KM1M7AF01N/M/K | K2: KM1M7AF11N/M/K | L2: KM1M7AF51N/M/K | M2: KM1M7AF61N/M/K | N2: KM1M7AF00N/M/K | O2: KM1M7AF10N/M/K | P2: KM1M7AF50N/M/K | Q2: KM1M7AF60N/M/K
A3: All | B3: HQFP80 (14*14) | C3: HQFP80 (14*14) | D3: HQFP80 (14*14) | E3: HQFP80 (14*14) | F3: HQFP100 (14*14) | G3: HQFP100 (14*14) | H3: HQFP100 (14*14) | I3: HQFP100 (14*14) | J3: HQFP128 (18*18) | K3: HQFP128 (18*18) | L3: HQFP128 (18*18) | M3: HQFP128 (18*18) | N3: HQFP144 (20*20) | O3: HQFP144 (20*20) | P3: HQFP144 (20*20) | Q3: HQFP144 (20*20)
A4: Timer | B4: TM22 | C4: TM22 | D4: TM22 | E4: TM22
A5: Power Control PWM | B5: GPWM7 | C5: GPWM7 | D5: GPWM7 | E5: GPWM7
B6: GPWM8 | C6: GPWM8 | D6: GPWM8 | E6: GPWM8
B7: GPWMA | C7: GPWMA | D7: GPWMA | E7: GPWMA | F7: GPWMA | G7: GPWMA | H7: GPWMA | I7: GPWMA
B8: GPWMB | C8: GPWMB | D8: GPWMB | E8: GPWMB | F8: GPWMB | G8: GPWMB | H8: GPWMB | I8: GPWMB
A9: Serial Interface | B9: SPI2 | C9: SPI2 | D9: SPI2 | E9: SPI2 | F9: SPI2 | G9: SPI2 | H9: SPI2 | I9: SPI2
B10: SPI3 | C10: SPI3 | D10: SPI3 | E10: SPI3
B11: UART2 | C11: UART2 | D11: UART2 | E11: UART2 | F11: UART2 | G11: UART2 | H11: UART2 | I11: UART2
B12: UART3 | C12: UART3 | D12: UART3 | E12: UART3
A13: CAN | B13: CAN0 | C13: CAN0 | F13: CAN0 | G13: CAN0 | J13: CAN0 | K13: CAN0 | N13: CAN0 | O13: CAN0
B14: CAN1 | C14: CAN1 | F14: CAN1 | G14: CAN1 | J14: CAN1 | K14: CAN1 | N14: CAN1 | O14: CAN1
A15: SMBUS | B15: SMBUS | C15: SMBUS | D15: SMBUS | E15: SMBUS | F15: SMBUS | G15: SMBUS | H15: SMBUS | I15: SMBUS
A16: VGA | C16: VGA0 | E16: VGA0 | G16: VGA0 | I16: VGA0 | K16: VGA0 | M16: VGA0 | O16: VGA0 | Q16: VGA0
C17: VGA1 | E17: VGA1 | G17: VGA1 | I17: VGA1 | K17: VGA1 | M17: VGA1 | O17: VGA1 | Q17: VGA1
C18: VGA2 | E18: VGA2 | G18: VGA2 | I18: VGA2 | K18: VGA2 | M18: VGA2 | O18: VGA2 | Q18: VGA2

Sheet Special Group Name
A1: Group Name | B1: MFP Function
A2: IRQ | B2: IRQ00
A3: IRQ | B3: IRQ01
A4: IRQ | B4: IRQ02
A5: IRQ | B5: IRQ03
A6: IRQ | B6: IRQ04
A7: IRQ | B7: IRQ05
A8: IRQ | B8: IRQ06
A9: IRQ | B9: IRQ07
A10: IRQ | B10: IRQ08
A11: IRQ | B11: IRQ09
A12: IRQ | B12: IRQ10
... A96: AD | B96: ADTRG2

Sheet Port Control Register
A1: Port Control Register | B1: Define in code | C1: Address | D1: Default value
A2: IOP0MD | B2: GPIO->IOP0MD | C2: 0x40100080 | D2: 0x00000000
A3: IOP1MD | B3: GPIO->IOP1MD | C3: 0x40100084 | D3: 0x00000000
A4: IOP2MD | B4: GPIO->IOP2MD | C4: 0x40100088 | D4: 0x00000000
A5: IOP3MD | B5: GPIO->IOP3MD | C5: 0x4010008C | D5: 0x00000000
A6: IOP4MD | B6: GPIO->IOP4MD | C6: 0x40100090 | D6: 0x00000000
A7: IOP5MD | B7: GPIO->IOP5MD | C7: 0x40100194 | D7: 0x00000000
A8: IOP6MD | B8: GPIO->IOP6MD | C8: 0x40100198 | D8: 0x00000000
A9: IOP7MD | B9: GPIO->IOP7MD | C9: 0x4010019C | D9: 0x00000000
A10: IOP8MD | B10: GPIO->IOP8MD | C10: 0x401001A0 | D10: 0x00000000
A11: IOP9MD | B11: GPIO->IOP9MD | C11: 0x401001A4 | D11: 0x00000000
A12: IOPAMD | B12: GPIO->IOPAMD | C12: 0x401001A8 | D12: 0x00000000
... A17: IOPFMD | B17: GPIO->IOPFMD | C17: 0x401001BC | D17: 0x00000000

Sheet ＠グループ、表示名
B2: 機能 | C2: グループ案 | D2: 端子設定 | G2: 1：XXX_AAA形式 | H2: 表示名案
D3: 端子機能名 | E3: 共通名 | G3: 2：Special Group Name | H3: グループ名 | I3: 端子機能名
B4: デバッガ | C4: DBG | D4: TRCCLK | G4: 1 | H4: =C4 -> DBG | I4: =IF(G4=1,C4&"_"&IF(E4<>"",E4,D4),IF(E4<>"",E4,D4)) -> DBG_TRCCLK
C5: DBG | D5: TRCSWO | G5: 1 | H5: =C5 -> DBG | I5: =IF(G5=1,C5&"_"&IF(E5<>"",E5,D5),IF(E5<>"",E5,D5)) -> DBG_TRCSWO
C6: DBG | D6: TRCD0 | G6: 1 | H6: =C6 -> DBG | I6: =IF(G6=1,C6&"_"&IF(E6<>"",E6,D6),IF(E6<>"",E6,D6)) -> DBG_TRCD0
C7: DBG | D7: TRCD1 | G7: 1 | H7: =C7 -> DBG | I7: =IF(G7=1,C7&"_"&IF(E7<>"",E7,D7),IF(E7<>"",E7,D7)) -> DBG_TRCD1
C8: DBG | D8: TRCD2 | G8: 1 | H8: =C8 -> DBG | I8: =IF(G8=1,C8&"_"&IF(E8<>"",E8,D8),IF(E8<>"",E8,D8)) -> DBG_TRCD2
C9: DBG | D9: TRCD3 | G9: 1 | H9: =C9 -> DBG | I9: =IF(G9=1,C9&"_"&IF(E9<>"",E9,D9),IF(E9<>"",E9,D9)) -> DBG_TRCD3
B10: 外部割込み | C10: IRQ | D10: IRQ00 | G10: 2 | H10: =C10 -> IRQ | I10: =IF(G10=1,C10&"_"&IF(E10<>"",E10,D10),IF(E10<>"",E10,D10)) -> IRQ00
C11: IRQ | D11: IRQ01 | G11: 2 | H11: =C11 -> IRQ | I11: =IF(G11=1,C11&"_"&IF(E11<>"",E11,D11),IF(E11<>"",E11,D11)) -> IRQ01
C12: IRQ | D12: IRQ02 | G12: 2 | H12: =C12 -> IRQ | I12: =IF(G12=1,C12&"_"&IF(E12<>"",E12,D12),IF(E12<>"",E12,D12)) -> IRQ02
C13: IRQ | D13: IRQ03 | G13: 2 | H13: =C13 -> IRQ | I13: =IF(G13=1,C13&"_"&IF(E13<>"",E13,D13),IF(E13<>"",E13,D13)) -> IRQ03
C14: IRQ | D14: IRQ04 | G14: 2 | H14: =C14 -> IRQ | I14: =IF(G14=1,C14&"_"&IF(E14<>"",E14,D14),IF(E14<>"",E14,D14)) -> IRQ04
C15: IRQ | D15: IRQ05 | G15: 2 | H15: =C15 -> IRQ | I15: =IF(G15=1,C15&"_"&IF(E15<>"",E15,D15),IF(E15<>"",E15,D15)) -> IRQ05
C16: IRQ | D16: IRQ06 | G16: 2 | H16: =C16 -> IRQ | I16: =IF(G16=1,C16&"_"&IF(E16<>"",E16,D16),IF(E16<>"",E16,D16)) -> IRQ06
C17: IRQ | D17: IRQ07 | G17: 2 | H17: =C17 -> IRQ | I17: =IF(G17=1,C17&"_"&IF(E17<>"",E17,D17),IF(E17<>"",E17,D17)) -> IRQ07
C18: IRQ | D18: IRQ08 | G18: 2 | H18: =C18 -> IRQ | I18: =IF(G18=1,C18&"_"&IF(E18<>"",E18,D18),IF(E18<>"",E18,D18)) -> IRQ08
C19: IRQ | D19: IRQ09 | G19: 2 | H19: =C19 -> IRQ | I19: =IF(G19=1,C19&"_"&IF(E19<>"",E19,D19),IF(E19<>"",E19,D19)) -> IRQ09
C20: IRQ | D20: IRQ10 | G20: 2 | H20: =C20 -> IRQ | I20: =IF(G20=1,C20&"_"&IF(E20<>"",E20,D20),IF(E20<>"",E20,D20)) -> IRQ10
C21: IRQ | D21: IRQ11 | G21: 2 | H21: =C21 -> IRQ | I21: =IF(G21=1,C21&"_"&IF(E21<>"",E21,D21),IF(E21<>"",E21,D21)) -> IRQ11
C22: IRQ | D22: IRQ12 | G22: 2 | H22: =C22 -> IRQ | I22: =IF(G22=1,C22&"_"&IF(E22<>"",E22,D22),IF(E22<>"",E22,D22)) -> IRQ12
... C29: IRQ | D29: IRQ19 | G29: 2 | H29: =C29 -> IRQ | I29: =IF(G29=1,C29&"_"&IF(E29<>"",E29,D29),IF(E29<>"",E29,D29)) -> IRQ19
B30: 16 ビットタイマ | C30: TM00 | D30: TM00A | G30: 2 | H30: =C30 -> TM00 | I30: =IF(G30=1,C30&"_"&IF(E30<>"",E30,D30),IF(E30<>"",E30,D30)) -> TM00A
C31: TM00 | D31: TM00B | G31: 2 | H31: =C31 -> TM00 | I31: =IF(G31=1,C31&"_"&IF(E31<>"",E31,D31),IF(E31<>"",E31,D31)) -> TM00B
C32: TM01 | D32: TM01A | G32: 2 | H32: =C32 -> TM01 | I32: =IF(G32=1,C32&"_"&IF(E32<>"",E32,D32),IF(E32<>"",E32,D32)) -> TM01A
C33: TM01 | D33: TM01B | G33: 2 | H33: =C33 -> TM01 | I33: =IF(G33=1,C33&"_"&IF(E33<>"",E33,D33),IF(E33<>"",E33,D33)) -> TM01B
C34: TM02 | D34: TM02A | G34: 2 | H34: =C34 -> TM02 | I34: =IF(G34=1,C34&"_"&IF(E34<>"",E34,D34),IF(E34<>"",E34,D34)) -> TM02A
C35: TM02 | D35: TM02B | G35: 2 | H35: =C35 -> TM02 | I35: =IF(G35=1,C35&"_"&IF(E35<>"",E35,D35),IF(E35<>"",E35,D35)) -> TM02B
C36: TM03 | D36: TM03A | G36: 2 | H36: =C36 -> TM03 | I36: =IF(G36=1,C36&"_"&IF(E36<>"",E36,D36),IF(E36<>"",E36,D36)) -> TM03A
C37: TM03 | D37: TM03B | G37: 2 | H37: =C37 -> TM03 | I37: =IF(G37=1,C37&"_"&IF(E37<>"",E37,D37),IF(E37<>"",E37,D37)) -> TM03B
C38: TM04 | D38: TM04A | G38: 2 | H38: =C38 -> TM04 | I38: =IF(G38=1,C38&"_"&IF(E38<>"",E38,D38),IF(E38<>"",E38,D38)) -> TM04A
C39: TM04 | D39: TM04B | G39: 2 | H39: =C39 -> TM04 | I39: =IF(G39=1,C39&"_"&IF(E39<>"",E39,D39),IF(E39<>"",E39,D39)) -> TM04B
C40: TM05 | D40: TM05A | G40: 2 | H40: =C40 -> TM05 | I40: =IF(G40=1,C40&"_"&IF(E40<>"",E40,D40),IF(E40<>"",E40,D40)) -> TM05A
C41: TM05 | D41: TM05B | G41: 2 | H41: =C41 -> TM05 | I41: =IF(G41=1,C41&"_"&IF(E41<>"",E41,D41),IF(E41<>"",E41,D41)) -> TM05B
C42: TM06 | D42: TM06A | G42: 2 | H42: =C42 -> TM06 | I42: =IF(G42=1,C42&"_"&IF(E42<>"",E42,D42),IF(E42<>"",E42,D42)) -> TM06A
... C69: TM25 | D69: TM25B | G69: 2 | H69: =C69 -> TM25 | I69: =IF(G69=1,C69&"_"&IF(E69<>"",E69,D69),IF(E69<>"",E69,D69)) -> TM25B
B70: パワー制御用PWM | C70: GPWM0 | D70: GPWM00 | G70: 1 | H70: =C70 -> GPWM0 | I70: =IF(G70=1,C70&"_"&IF(E70<>"",E70,D70),IF(E70<>"",E70,D70)) -> GPWM0_GPWM00
C71: GPWM0 | D71: GPWMH00 | G71: 1 | H71: =C71 -> GPWM0 | I71: =IF(G71=1,C71&"_"&IF(E71<>"",E71,D71),IF(E71<>"",E71,D71)) -> GPWM0_GPWMH00
C72: GPWM0 | D72: GPWM01 | G72: 1 | H72: =C72 -> GPWM0 | I72: =IF(G72=1,C72&"_"&IF(E72<>"",E72,D72),IF(E72<>"",E72,D72)) -> GPWM0_GPWM01
C73: GPWM0 | D73: GPWMH01 | G73: 1 | H73: =C73 -> GPWM0 | I73: =IF(G73=1,C73&"_"&IF(E73<>"",E73,D73),IF(E73<>"",E73,D73)) -> GPWM0_GPWMH01
...

Sheet @Pin Component List記載
B2: 表示名案 | D2: 説明文案 | H2: Pin Component List記載
B3: グループ名 | C3: 端子機能名 | D3: 説明(L説) | E3: 参考箇所 | F3: 入出力 | G3: 説明形式(pinconfig) | H3: Pin Name | I3: Description ( '*', '$' are wildcard characters) | J3: Type
B4: ='＠グループ、表示名'!H4 -> DBG | C4: ='＠グループ、表示名'!I4 -> DBG_TRCCLK | D4: Trace clock pin | E4: Table 30.1-2 List of Debug Interface Pins | F4: O | G4: Trace clock output pin | H4: DBG_TRCCLK | I4: Trace clock output pin | J4: =F4 -> O
B5: ='＠グループ、表示名'!H5 -> DBG | C5: ='＠グループ、表示名'!I5 -> DBG_TRCSWO | D5: Serial wire output pin | E5: Table 30.1-2 List of Debug Interface Pins | F5: O | G5: Serial wire output pin | H5: DBG_TRCSWO | I5: Serial wire output pin | J5: =F5 -> O
B6: ='＠グループ、表示名'!H6 -> DBG | C6: ='＠グループ、表示名'!I6 -> DBG_TRCD0 | D6: Trace data 0 pin | E6: Table 30.1-2 List of Debug Interface Pins | F6: O | G6: Trace data 0 output pin | H6: DBG_TRCD* | I6: Trace data * output pin | J6: =F6 -> O
B7: ='＠グループ、表示名'!H7 -> DBG | C7: ='＠グループ、表示名'!I7 -> DBG_TRCD1 | D7: Trace data 1 pin | E7: Table 30.1-2 List of Debug Interface Pins | F7: O | G7: Trace data 1 output pin | H7: DBG_TRCD* | I7: Trace data * output pin | J7: =F7 -> O
B8: ='＠グループ、表示名'!H8 -> DBG | C8: ='＠グループ、表示名'!I8 -> DBG_TRCD2 | D8: Trace data 2 pin | E8: Table 30.1-2 List of Debug Interface Pins | F8: O | G8: Trace data 2 output pin | H8: DBG_TRCD* | I8: Trace data * output pin | J8: =F8 -> O
B9: ='＠グループ、表示名'!H9 -> DBG | C9: ='＠グループ、表示名'!I9 -> DBG_TRCD3 | D9: Trace data 3 pin | E9: Table 30.1-2 List of Debug Interface Pins | F9: O | G9: Trace data 3 output pin | H9: DBG_TRCD* | I9: Trace data * output pin | J9: =F9 -> O
B10: ='＠グループ、表示名'!H10 -> IRQ | C10: ='＠グループ、表示名'!I10 -> IRQ00 | D10: External interrupt 0 | E10: Table 7.4-1 The List of the Interrupt Factors | F10: I | G10: External interrupt 0 input pin | H10: IRQ00 | I10: External interrupt 0 input pin | J10: =F10 -> I
B11: ='＠グループ、表示名'!H11 -> IRQ | C11: ='＠グループ、表示名'!I11 -> IRQ01 | D11: External interrupt 1 | E11: Table 7.4-1 The List of the Interrupt Factors | F11: I | G11: External interrupt 1 input pin | H11: IRQ01 | I11: External interrupt 1 input pin | J11: =F11 -> I
B12: ='＠グループ、表示名'!H12 -> IRQ | C12: ='＠グループ、表示名'!I12 -> IRQ02 | D12: External interrupt 2 | E12: Table 7.4-1 The List of the Interrupt Factors | F12: I | G12: External interrupt 2 input pin | H12: IRQ02 | I12: External interrupt 2 input pin | J12: =F12 -> I
B13: ='＠グループ、表示名'!H13 -> IRQ | C13: ='＠グループ、表示名'!I13 -> IRQ03 | D13: External interrupt 3 | E13: Table 7.4-1 The List of the Interrupt Factors | F13: I | G13: External interrupt 3 input pin | H13: IRQ03 | I13: External interrupt 3 input pin | J13: =F13 -> I
B14: ='＠グループ、表示名'!H14 -> IRQ | C14: ='＠グループ、表示名'!I14 -> IRQ04 | D14: External interrupt 4 | E14: Table 7.4-1 The List of the Interrupt Factors | F14: I | G14: External interrupt 4 input pin | H14: IRQ04 | I14: External interrupt 4 input pin | J14: =F14 -> I
B15: ='＠グループ、表示名'!H15 -> IRQ | C15: ='＠グループ、表示名'!I15 -> IRQ05 | D15: External interrupt 5 | E15: Table 7.4-1 The List of the Interrupt Factors | F15: I | G15: External interrupt 5 input pin | H15: IRQ05 | I15: External interrupt 5 input pin | J15: =F15 -> I
... B297: ='＠グループ、表示名'!H297 -> P0 | C297: ='＠グループ、表示名'!I297 -> P0.6 | D297: General-Purpose I/O Port | E297: Table 9.1-1 The List of Ports in Each Series | F297: I/O | G297: General-purpose input/output pin | H297: P0.* | I297: General-purpose input/output pin | J297: =F297 -> I/O
B298: ='＠グループ、表示名'!H298 -> P0 | C298: ='＠グループ、表示名'!I298 -> P0.7 | D298: General-Purpose I/O Port | E298: Table 9.1-1 The List of Ports in Each Series | F298: I/O | G298: General-purpose input/output pin | H298: P0.* | I298: General-purpose input/output pin | J298: I/O
B299: ='＠グループ、表示名'!H299 -> P1 | C299: ='＠グループ、表示名'!I299 -> P1.0 | D299: General-Purpose I/O Port | E299: Table 9.1-1 The List of Ports in Each Series | F299: I/O | G299: General-purpose input/output pin | H299: P1.* | I299: General-purpose input/output pin | J299: I/O
B300: ='＠グループ、表示名'!H300 -> P1 | C300: ='＠グループ、表示名'!I300 -> P1.1 | D300: General-Purpose I/O Port | E300: Table 9.1-1 The List of Ports in Each Series | F300: I/O | G300: General-purpose input/output pin | H300: P1.* | I300: General-purpose input/output pin | J300: I/O
B301: ='＠グループ、表示名'!H301 -> P1 | C301: ='＠グループ、表示名'!I301 -> P1.2 | D301: General-Purpose I/O Port | E301: Table 9.1-1 The List of Ports in Each Series | F301: I/O | G301: General-purpose input/output pin | H301: P1.* | I301: General-purpose input/output pin | J301: I/O
B302: ='＠グループ、表示名'!H302 -> P1 | C302: ='＠グループ、表示名'!I302 -> P1.3 | D302: General-Purpose I/O Port | E302: Table 9.1-1 The List of Ports in Each Series | F302: I/O | G302: General-purpose input/output pin | H302: P1.* | I302: General-purpose input/output pin | J302: I/O
B303: ='＠グループ、表示名'!H303 -> P1 | C303: ='＠グループ、表示名'!I303 -> P1.4 | D303: General-Purpose I/O Port | E303: Table 9.1-1 The List of Ports in Each Series | F303: I/O | G303: General-purpose input/output pin | H303: P1.* | I303: General-purpose input/output pin | J303: I/O
B304: ='＠グループ、表示名'!H304 -> P1 | C304: ='＠グループ、表示名'!I304 -> P1.5 | D304: General-Purpose I/O Port | E304: Table 9.1-1 The List of Ports in Each Series | F304: I/O | G304: General-purpose input/output pin | H304: P1.* | I304: General-purpose input/output pin | J304: I/O
B305: ='＠グループ、表示名'!H305 -> P1 | C305: ='＠グループ、表示名'!I305 -> P1.6 | D305: General-Purpose I/O Port | E305: Table 9.1-1 The List of Ports in Each Series | F305: I/O | G305: General-purpose input/output pin | H305: P1.* | I305: General-purpose input/output pin | J305: I/O
B306: ='＠グループ、表示名'!H306 -> P1 | C306: ='＠グループ、表示名'!I306 -> P1.7 | D306: General-Purpose I/O Port | E306: Table 9.1-1 The List of Ports in Each Series | F306: I/O | G306: General-purpose input/output pin | H306: P1.* | I306: General-purpose input/output pin | J306: I/O
B307: ='＠グループ、表示名'!H307 -> P2 | C307: ='＠グループ、表示名'!I307 -> P2.0 | D307: General-Purpose I/O Port | E307: Table 9.1-1 The List of Ports in Each Series | F307: I/O | G307: General-purpose input/output pin | H307: P2.* | I307: General-purpose input/output pin | J307: I/O
B308: ='＠グループ、表示名'!H308 -> P2 | C308: ='＠グループ、表示名'!I308 -> P2.1 | D308: General-Purpose I/O Port | E308: Table 9.1-1 The List of Ports in Each Series | F308: I/O | G308: General-purpose input/output pin | H308: P2.* | I308: General-purpose input/output pin | J308: I/O
B309: ='＠グループ、表示名'!H309 -> P2 | C309: ='＠グループ、表示名'!I309 -> P2.2 | D309: General-Purpose I/O Port | E309: Table 9.1-1 The List of Ports in Each Series | F309: I/O | G309: General-purpose input/output pin | H309: P2.* | I309: General-purpose input/output pin | J309: I/O
... B413: ='＠グループ、表示名'!H413 -> PF | C413: ='＠グループ、表示名'!I413 -> PF.7 | D413: General-Purpose I/O Port | E413: Table 9.1-1 The List of Ports in Each Series | F413: I/O | G413: General-purpose input/output pin | H413: PF.* | I413: General-purpose input/output pin | J413: I/O
